{"timestamp": "2025-10-05T16:33:47.374205", "container": "gitea", "language": "python", "error": "2025/09/28 11:32:41 routers/common/db.go:36:InitDBEngine() [E] ORM engine initialization attempt #1/10 failed. Error: pq: the database system is starting up", "solution": "Errore AI: <!DOCTYPE html>\n<html lang=\"en\">\n<head>\n<meta charset=\"utf-8\">\n<title>Error</title>\n</head>\n<body>\n<pre>Internal Server Error</pre>\n</body>\n</html>"}
{"timestamp": "2025-10-05T16:33:48.740593", "container": "gitea-db-1", "language": "generic", "error": "2025-09-28 09:32:41.137 UTC [28] FATAL:  the database system is starting up", "solution": "Errore AI: <!DOCTYPE html>\n<html lang=\"en\">\n<head>\n<meta charset=\"utf-8\">\n<title>Error</title>\n</head>\n<body>\n<pre>Internal Server Error</pre>\n</body>\n</html>"}
{"timestamp": "2025-10-05T16:33:50.066884", "container": "couchdb1", "language": "generic", "error": "[error] 2025-09-26T00:34:02.116105Z couchdb@couchdb1 <0.467.0> -------- ** System running to use fully qualified hostnames **", "solution": "Errore AI: <!DOCTYPE html>\n<html lang=\"en\">\n<head>\n<meta charset=\"utf-8\">\n<title>Error</title>\n</head>\n<body>\n<pre>Internal Server Error</pre>\n</body>\n</html>"}
{"timestamp": "2025-10-05T16:33:51.509895", "container": "frontend", "language": "generic", "error": "2025/09/28 09:32:18 [error] 42#42: *1 connect() failed (111: Connection refused) while connecting to upstream, client: 172.21.0.1, server: 192.168.1.10, request: \"GET /api/agents HTTP/1.1\", upstream: \"http://172.21.0.3:8003/agents\", host: \"peschiera3.ddns.net\", referrer: \"https://peschiera3.ddns.net/dossier/\"", "solution": "Errore AI: <!DOCTYPE html>\n<html lang=\"en\">\n<head>\n<meta charset=\"utf-8\">\n<title>Error</title>\n</head>\n<body>\n<pre>Internal Server Error</pre>\n</body>\n</html>"}
{"timestamp": "2025-10-05T16:33:52.805184", "container": "dossier-backend", "language": "generic", "error": "\u001b[32m2025-09-27 03:12:45\u001b[0m | \u001b[31m\u001b[1mERROR   \u001b[0m | \u001b[31m\u001b[1m[FETCH] Errore fetch GNews: 'NoneType' object is not iterable\u001b[0m", "solution": "Errore AI: <!DOCTYPE html>\n<html lang=\"en\">\n<head>\n<meta charset=\"utf-8\">\n<title>Error</title>\n</head>\n<body>\n<pre>Internal Server Error</pre>\n</body>\n</html>"}
{"timestamp": "2025-10-05T16:33:54.301659", "container": "proxy", "language": "generic", "error": "2025/09/25 23:21:07 [error] 27#27: *134 connect() failed (111: Connection refused) while connecting to upstream, client: 172.17.0.1, server: localhost, request: \"GET /v1 HTTP/1.1\", upstream: \"http://172.17.0.1:1234/v1\", host: \"peschiera3.ddns.net\", referrer: \"https://peschiera3.ddns.net/api\"", "solution": "Errore AI: <!DOCTYPE html>\n<html lang=\"en\">\n<head>\n<meta charset=\"utf-8\">\n<title>Error</title>\n</head>\n<body>\n<pre>Internal Server Error</pre>\n</body>\n</html>"}
{"timestamp": "2025-10-05T16:33:55.660834", "container": "proxy", "language": "generic", "error": "2025/09/25 23:21:07 [error] 27#27: *138 connect() failed (111: Connection refused) while connecting to upstream, client: 172.17.0.1, server: localhost, request: \"GET /v2 HTTP/1.1\", upstream: \"http://172.17.0.1:4891/\", host: \"peschiera3.ddns.net\", referrer: \"https://peschiera3.ddns.net/api\"", "solution": "Errore AI: <!DOCTYPE html>\n<html lang=\"en\">\n<head>\n<meta charset=\"utf-8\">\n<title>Error</title>\n</head>\n<body>\n<pre>Internal Server Error</pre>\n</body>\n</html>"}
{"timestamp": "2025-10-05T16:33:56.994549", "container": "proxy", "language": "generic", "error": "2025/09/25 23:21:09 [error] 25#25: *155 connect() failed (111: Connection refused) while connecting to upstream, client: 172.17.0.1, server: localhost, request: \"GET /rea HTTP/1.1\", upstream: \"http://172.17.0.1:8000/\", host: \"peschiera3.ddns.net\", referrer: \"https://peschiera3.ddns.net/api\"", "solution": "Errore AI: <!DOCTYPE html>\n<html lang=\"en\">\n<head>\n<meta charset=\"utf-8\">\n<title>Error</title>\n</head>\n<body>\n<pre>Internal Server Error</pre>\n</body>\n</html>"}
{"timestamp": "2025-10-05T16:33:58.255887", "container": "privoxy-updater", "language": "python", "error": "Traceback (most recent call last):", "solution": "Errore AI: <!DOCTYPE html>\n<html lang=\"en\">\n<head>\n<meta charset=\"utf-8\">\n<title>Error</title>\n</head>\n<body>\n<pre>Internal Server Error</pre>\n</body>\n</html>"}
{"timestamp": "2025-10-05T16:33:59.688058", "container": "privoxy-updater", "language": "python", "error": "  File \"/usr/local/lib/python3.11/site-packages/urllib3/connection.py\", line 198, in _new_conn", "solution": "Errore AI: <!DOCTYPE html>\n<html lang=\"en\">\n<head>\n<meta charset=\"utf-8\">\n<title>Error</title>\n</head>\n<body>\n<pre>Internal Server Error</pre>\n</body>\n</html>"}
{"timestamp": "2025-10-05T16:34:00.885479", "container": "privoxy", "language": "python", "error": "2025-08-21 09:18:16.458 7c3e34d33b38 Error: write to client failed: Invalid argument", "solution": "Errore AI: <!DOCTYPE html>\n<html lang=\"en\">\n<head>\n<meta charset=\"utf-8\">\n<title>Error</title>\n</head>\n<body>\n<pre>Internal Server Error</pre>\n</body>\n</html>"}
{"timestamp": "2025-10-05T17:56:52.580451", "container": "gitea", "language": "python", "error": "2025/09/28 11:32:41 routers/common/db.go:36:InitDBEngine() [E] ORM engine initialization attempt #1/10 failed. Error: pq: the database system is starting up", "solution": "Il bug è che il codice non gestisce correttamente l'errore quando il database si sta avviando.\n\nLa soluzione è aggiungere un ritardo di alcuni secondi prima di riprovare l'inizializzazione dell'ORM engine, in modo da lasciare tempo al database di completare la sua inizializzazione. \n\nEsempio di codice corretto:\n```go\nfunc InitDBEngine() {\n    defer func() {\n        if r := recovery(); r != nil {\n            log.Println(\"recovery:\", r)\n        }\n    }()\n    // Aggiungi un ritardo di 5 secondi prima di riprovare l'inizializzazione\n    time.Sleep(5 * time.Second)\n    \n    // Prova a riprovare l'inizializzazione dell'ORM engine\n    if err := db"}
{"timestamp": "2025-10-05T17:56:53.557345", "container": "frontend", "language": "generic", "error": "2025/09/28 09:32:18 [error] 42#42: *1 connect() failed (111: Connection refused) while connecting to upstream, client: 172.21.0.1, server: 192.168.1.10, request: \"GET /api/agents HTTP/1.1\", upstream: \"http://172.21.0.3:8003/agents\", host: \"peschiera3.ddns.net\", referrer: \"https://peschiera3.ddns.net/dossier/\"", "solution": "Il bug è che il server non sta ascoltando sulla porta 8003.\n\n**Soluzione:** assicurarsi di avviare correttamente l'applicazione e che la porta 8003 sia effettivamente ascoltata. Ad esempio, se si utilizza un framework come Express.js, assicurarsi di aver configurato correttamente il server:\n\n```javascript\nconst express = require('express');\nconst app = express();\n\napp.listen(8003, () => {\n  console.log('Server in ascolto sulla porta 8003');\n});\n```\n\nNota che la soluzione dipenderà dal framework e dalla tecnologia utilizzata per l'applicazione."}
{"timestamp": "2025-10-05T17:56:54.242371", "container": "proxy", "language": "generic", "error": "2025/09/25 23:21:07 [error] 27#27: *134 connect() failed (111: Connection refused) while connecting to upstream, client: 172.17.0.1, server: localhost, request: \"GET /v1 HTTP/1.1\", upstream: \"http://172.17.0.1:1234/v1\", host: \"peschiera3.ddns.net\", referrer: \"https://peschiera3.ddns.net/api\"", "solution": "Il bug è che il server locale (localhost) non è in ascolto sul porto 1234, ma il client tenta di connettersi a quel porto.\n\n**Soluzione:** assicurarsi che il servizio che si vuole eseguire sul localhost sia in esecuzione e che stia ascoltando sulla porta corretta. Ad esempio:\n\n```bash\npython -m http.server 1234\n```\n\nQuesto comando avvia un server HTTP di base sul porto 1234, consentendo al client di connettersi correttamente."}
{"timestamp": "2025-10-05T17:56:54.821501", "container": "proxy", "language": "generic", "error": "2025/09/25 23:21:07 [error] 27#27: *138 connect() failed (111: Connection refused) while connecting to upstream, client: 172.17.0.1, server: localhost, request: \"GET /v2 HTTP/1.1\", upstream: \"http://172.17.0.1:4891/\", host: \"peschiera3.ddns.net\", referrer: \"https://peschiera3.ddns.net/api\"", "solution": "Il bug è che il server non sta ascoltando sulla porta 4891.\n\n**Soluzione:** assicurarsi di avviare correttamente l'applicazione o servizio che si trova sulla porta 4891. Ad esempio, se si tratta di un servizio Node.js, assicurarsi di aver utilizzato la funzione `app.listen(4891)` per ascoltare su quella porta.\n\n**Esempio di codice (Node.js):**\n```javascript\nconst express = require('express');\nconst app = express();\n\napp.get('/v2', (req, res) => {\n  // gestione della richiesta\n});\n\napp.listen(4891, () => {\n  console.log('Servizio ascoltando su porta 4891');\n});\n```\nNota che questo è solo un esemp"}
{"timestamp": "2025-10-05T17:56:55.626770", "container": "proxy", "language": "generic", "error": "2025/09/25 23:21:09 [error] 25#25: *155 connect() failed (111: Connection refused) while connecting to upstream, client: 172.17.0.1, server: localhost, request: \"GET /rea HTTP/1.1\", upstream: \"http://172.17.0.1:8000/\", host: \"peschiera3.ddns.net\", referrer: \"https://peschiera3.ddns.net/api\"", "solution": "Il bug è che il server non sta ascoltando su port 8000.\n\nLa soluzione potrebbe essere di verificare se il servizio che sta cercando di connettersi (Apache, Nginx, ecc.) stia correttamente ascoltando su quel porto. Ad esempio, per Apache, potresti controllare la configurazione del file `/etc/apache2/httpd.conf` o `/etc/apache2/sites-available/default-ssl.conf`.\n\nEsempio di codice non errato (configurazione di Apache per ascoltare su port 8000):\n```bash\n<VirtualHost *:80>\n    ServerName peschiera3.ddns.net\n\n    ProxyPass /rea http://172.17.0.1:8000/\n    ProxyPassReverse /rea http://172."}
{"timestamp": "2025-10-05T17:56:56.433010", "container": "gitea-db-1", "language": "generic", "error": "2025-09-28 09:32:41.137 UTC [28] FATAL:  the database system is starting up", "solution": "Il bug sembra essere una semplice sintassi errata.\n\nLa soluzione potrebbe essere di aggiungere i parametri necessari per avviare il database, ad esempio:\n\n```bash\ngitea -d /var/lib/gitea -c /etc/gitea/gitea.ini\n```\n\nNota che la soluzione specifica dipenderà dal sistema operativo e dalle impostazioni del database utilizzato."}
{"timestamp": "2025-10-05T17:56:56.851291", "container": "dossier-backend", "language": "generic", "error": "\u001b[32m2025-09-27 03:12:45\u001b[0m | \u001b[31m\u001b[1mERROR   \u001b[0m | \u001b[31m\u001b[1m[FETCH] Errore fetch GNews: 'NoneType' object is not iterable\u001b[0m", "solution": "Il bug è che il codice cerca di iterare su un oggetto `None`, ovvero nulla. Ciò succede perché la variabile che contiene i dati da recuperare non è stata caricata correttamente.\n\n**Soluzione:**\nVerifica se la variabile `GNews` è stata caricata correttamente prima di cercare di iterarla.\n\nEsempio di codice corretto:\n```python\nimport requests\n\n# Carica i dati da GNews\nresponse = requests.get('https://api.gnews.io/v3/search?q=python')\nif response.status_code == 200:\n    GNews = response.json()\nelse:\n    print(f\"Errore di rete: {response.status_code}\")\n```\nIn questo esempio, si verifica un'eccezione se la richiesta al servizio di GNews fall"}
{"timestamp": "2025-10-05T17:56:57.646430", "container": "couchdb1", "language": "generic", "error": "[error] 2025-09-26T00:34:02.116105Z couchdb@couchdb1 <0.467.0> -------- ** System running to use fully qualified hostnames **", "solution": "Il bug è che il sistema richiede utilizzo di nomi completi di host, ma non è specificato se il server CouchDB sia disponibile in modo pubblico o privato.\n\nLa soluzione è quella di utilizzare un nome completo di host come `localhost` o `127.0.0.1` per accedere al server CouchDB.\n\nEsempio di codice (non errato):\n```javascript\nvar db = require('coouchdb').db('http://localhost:5984');\n```\nNota che in questo esempio, il nome completo del host è `localhost`, ma potrebbe essere necessario utilizzare `127.0.0.1` se si sta accedendo al server da un'interfaccia locale."}
{"timestamp": "2025-10-05T17:56:58.377384", "container": "privoxy-updater", "language": "python", "error": "Traceback (most recent call last):", "solution": "Il bug è probabilmente una connessione fallita al server di aggiornamento del Privoxy-Updater.\n\nLa soluzione potrebbe essere quella di controllare la connessione a Internet e assicurarsi che il server di aggiornamento sia raggiungibile. \n\nEsempio di codice non errato:\n```python\nimport requests\n\ntry:\n    response = requests.get('https://privoxy-updater.org/latest')\n    if response.status_code == 200:\n        print(\"Aggiornamento disponibile\")\n    else:\n        print(\"Errore di connessione al server di aggiornamento\")\nexcept requests.ConnectionError as e:\n    print(f\"Errore di connessione: {e}\")\n```"}
{"timestamp": "2025-10-05T17:56:59.053020", "container": "privoxy-updater", "language": "python", "error": "  File \"/usr/local/lib/python3.11/site-packages/urllib3/connection.py\", line 198, in _new_conn", "solution": "Il bug è che il file `/usr/local/lib/python3.11/site-packages/urllib3/connection.py` non esiste più.\n\n**Soluzione:**\nAggiornare le dipendenze del progetto Privoxy-Updater per utilizzare la versione più recente di urllib3.\n\nEsempio di codice:\n```python\nimport setuptools\n\nsetuptools.setup(\n    name='privoxy-updater',\n    packages=setuptools.find_packages(),\n    install_requires=['urllib3==2.1.26']\n)\n```\nNota: La versione specifica di urllib3 utilizzata nel codice è 2.1.26, che potrebbe essere la versione più recente disponibile al momento della compilazione del progetto."}
{"timestamp": "2025-10-05T17:56:59.748329", "container": "privoxy", "language": "python", "error": "2025-08-21 09:18:16.458 7c3e34d33b38 Error: write to client failed: Invalid argument", "solution": "Il bug è che il codice non controlla se la connessione al server è stata stabilita correttamente prima di tentare di scrivere dati al client.\n\n**Esempio di codice errato:**\n```c\n// senza controllo sulla connessione\nif (connessione != NULL) {\n    scrittura = connessione->write(data, 10);\n}\n```\n**Soluzione corretta:**\n```c\n// con controllo sulla connessione\nif (connessione != NULL && connessione->isConnected()) {\n    scrittura = connessione->write(data, 10);\n} else {\n    // gestione dell'errore\n}\n```\nIn questo modo si assicura che la connessione al server sia stata stabilita correttamente prima di"}
{"timestamp": "2025-10-05T17:58:53.996778", "container": "dossier-backend", "language": "generic", "error": "\u001b[32m2025-09-27 03:12:45\u001b[0m | \u001b[31m\u001b[1mERROR   \u001b[0m | \u001b[31m\u001b[1m[FETCH] Errore fetch GNews: 'NoneType' object is not iterable\u001b[0m", "solution": "Il bug è che il codice cerca di iterare su un oggetto None, ovvero un valore nullo. Questo può accadere se la chiave \"GNews\" non esiste nel dizionario o nella struttura dati utilizzata.\n\n**Soluzione concisa:**\nVerifica che la chiave \"GNews\" sia presente e non nulla prima di cercare di iterarla. Ad esempio:\n\n```python\ndata = {'key1': 'value1', 'key2': None, 'GNews': 'news'}\nif 'GNews' in data:\n    for news in data['GNews']:\n        print(news)\nelse:\n    print(\"La chiave GNews non esiste\")\n```\n\nIn questo esempio, il codice verifica se la chiave \"GNews\" è presente nel dizionario prima di"}
{"timestamp": "2025-10-05T17:58:54.968921", "container": "gitea-db-1", "language": "generic", "error": "2025-09-28 09:32:41.137 UTC [28] FATAL:  the database system is starting up", "solution": "Il bug è probabilmente legato alla configurazione del database. La frase \"the database system is starting up\" suggerisce che il sistema di database non sia stato correttamente configurato.\n\n**Soluzione concisa:** Verifica la configurazione del file `my.cnf` (o equivalente) per assicurarti che le impostazioni di base siano corrette, come ad esempio la connessione alla rete e le impostazioni di sicurezza."}
{"timestamp": "2025-10-05T17:58:55.431203", "container": "gitea", "language": "python", "error": "2025/09/28 11:32:41 routers/common/db.go:36:InitDBEngine() [E] ORM engine initialization attempt #1/10 failed. Error: pq: the database system is starting up", "solution": "Il bug è che il codice non attende prima che la base di dati sia stata avviata prima di tentare di inizializzarla.\n\n**Soluzione concisa:** Aggiungere un tempo di attesa prima dell'inizializzazione della base di dati.\n\nEsempio di codice corretto:\n```go\nfunc InitDBEngine() {\n    // attendi 2 secondi prima di tentare di inizializzare la base di dati\n    time.Sleep(2 * time.Second)\n    \n    // restante codice...\n}\n```\nNota: il tempo di attesa può variare a seconda delle esigenze specifiche del sistema."}
{"timestamp": "2025-10-05T17:58:56.090891", "container": "proxy", "language": "generic", "error": "2025/09/25 23:21:07 [error] 27#27: *134 connect() failed (111: Connection refused) while connecting to upstream, client: 172.17.0.1, server: localhost, request: \"GET /v1 HTTP/1.1\", upstream: \"http://172.17.0.1:1234/v1\", host: \"peschiera3.ddns.net\", referrer: \"https://peschiera3.ddns.net/api\"", "solution": "Il bug è che il client (il server proxy) non riesce a connettersi al server upstream (l'host 172.17.0.1) perché il port 1234 non esiste.\n\n**Soluzione concisa:**\n\nVerifica che il servizio che si sta cercando di connettere sia avviato e ascolti sul port 1234. Ad esempio, se si tratta di un servizio scritto in Python:\n```python\nimport http.server\n\nhttpd = http.server.HTTPServer(('172.17.0.1', 1234), http.server.SimpleHTTPRequestHandler)\nhttpd.serve_forever()\n```\nNota che questo è solo un esempio e potrebbe non essere la soluzione finale, ma rappresenta il concetto di base."}
{"timestamp": "2025-10-05T17:58:56.874024", "container": "proxy", "language": "generic", "error": "2025/09/25 23:21:07 [error] 27#27: *138 connect() failed (111: Connection refused) while connecting to upstream, client: 172.17.0.1, server: localhost, request: \"GET /v2 HTTP/1.1\", upstream: \"http://172.17.0.1:4891/\", host: \"peschiera3.ddns.net\", referrer: \"https://peschiera3.ddns.net/api\"", "solution": "Il bug è che il server non sta ascoltando sulla porta 4891.\n\n**Soluzione:** Assicurarsi di avere un servizio web o un'applicazione eseguente sul porto 4891 e che sia in ascolto quando il proxy tenta di connettersi."}
{"timestamp": "2025-10-05T17:58:57.177698", "container": "proxy", "language": "generic", "error": "2025/09/25 23:21:09 [error] 25#25: *155 connect() failed (111: Connection refused) while connecting to upstream, client: 172.17.0.1, server: localhost, request: \"GET /rea HTTP/1.1\", upstream: \"http://172.17.0.1:8000/\", host: \"peschiera3.ddns.net\", referrer: \"https://peschiera3.ddns.net/api\"", "solution": "Il bug è che il server non sta ascoltando sulla porta 8000.\n\nSoluzione:\n- Assicurarsi di avere un servizio web eseguibile su `localhost` e che stia ascoltando sulla porta corretta (in questo caso, 8000).\n\nEsempio di codice (non errato):\n```python\nfrom http.server import BaseHTTPRequestHandler, HTTPServer\n\nclass MyRequestHandler(BaseHTTPRequestHandler):\n    def do_GET(self):\n        self.send_response(200)\n        self.end_headers()\n        self.wfile.write(b\"Hello World!\")\n\ndef run_server():\n    server_address = ('', 8000)\n    httpd = HTTPServer(server_address, MyRequestHandler)\n    print(\"Servizio web in esecuzione...\")\n    httpd.serve_forever()\n\nif __name__ == \"__main__\":"}
{"timestamp": "2025-10-05T17:58:57.983429", "container": "frontend", "language": "generic", "error": "2025/09/28 09:32:18 [error] 42#42: *1 connect() failed (111: Connection refused) while connecting to upstream, client: 172.21.0.1, server: 192.168.1.10, request: \"GET /api/agents HTTP/1.1\", upstream: \"http://172.21.0.3:8003/agents\", host: \"peschiera3.ddns.net\", referrer: \"https://peschiera3.ddns.net/dossier/\"", "solution": "Il bug è che il server non sta ascoltando su l'indirizzo IP specificato (`172.21.0.1`) in cui si cerca di connettersi.\n\n**Soluzione concisa:** Assicurarsi che il servizio web sia configurato per ascoltare su un indirizzo IP specifico e che quel indirizzo sia disponibile sulla rete."}
{"timestamp": "2025-10-05T17:58:58.379967", "container": "couchdb1", "language": "generic", "error": "[error] 2025-09-26T00:34:02.116105Z couchdb@couchdb1 <0.467.0> -------- ** System running to use fully qualified hostnames **", "solution": "Il bug è che il sistema richiede l'uso di nomi completi dei host (FQDN) invece di nomi di dominio relativi (DNS).\n\n**Soluzione:** assicurarsi di utilizzare FQDN in tutti i parametri di configurazione.\n\nEsempio di codice non errato:\n```javascript\n// Configura il server con un FQDN\nvar server = {\n  \"httpd\": {\n    // ...\n    \"bind_to\": \"couchdb1.example.com\"\n  }\n};\n```\nIn questo esempio, il server è configurato per leggersi su `couchdb1.example.com` anziché solo `couchdb1`."}
{"timestamp": "2025-10-05T17:58:59.057365", "container": "privoxy-updater", "language": "python", "error": "Traceback (most recent call last):", "solution": "Il bug è che il codice non include l'importazione della libreria `logging` necessaria per gestire gli errori.\n\nSoluzione: aggiungere la linea `import logging` all'inizio del file di codice. \n\nEsempio di codice corretto:\n```python\nimport logging\nimport requests\n\n# ...\n```\nNota: il codice completo non è fornito, quindi si assume che l'errore sia legato alla gestione degli errori."}
{"timestamp": "2025-10-05T17:58:59.517649", "container": "privoxy-updater", "language": "python", "error": "  File \"/usr/local/lib/python3.11/site-packages/urllib3/connection.py\", line 198, in _new_conn", "solution": "Il bug è che il file `/usr/local/lib/python3.11/site-packages/urllib3/connection.py` non esiste più.\n\nSoluzione: controlla se il pacchetto `urllib3` è aggiornato e installa la versione più recente utilizzando pip:\n```bash\npip install --upgrade urllib3\n```\nQuesto dovrebbe risolvere il problema."}
{"timestamp": "2025-10-05T17:58:59.903060", "container": "privoxy", "language": "python", "error": "2025-08-21 09:18:16.458 7c3e34d33b38 Error: write to client failed: Invalid argument", "solution": "Il bug è probabilmente legato alla gestione delle connessioni TCP. Il problema potrebbe essere causato da un'errore nella chiusura della connessione o in una mossa di timeout.\n\nSoluzione consigliata:\nVerifica che la classe `Connection` stia chiudendo correttamente le connessioni TCP e che non ci siano timeout configurati troppo bassi. Ad esempio, il codice seguente mostra come gestire correttamente le connessioni TCP:\n\n```java\n// Gestione della connessione\npublic class PrivoxyConnection {\n    // ...\n    \n    public void close() throws IOException {\n        if (connection != null) {\n            connection.close();\n        }\n    }\n}\n```\n\nNota che il codice originale non è stato fornito, quindi questa soluzione è solo una ipotes"}
{"timestamp": "2025-10-05T17:59:29.227081", "container": "gitea", "language": "python", "error": "2025/09/28 11:32:41 routers/common/db.go:36:InitDBEngine() [E] ORM engine initialization attempt #1/10 failed. Error: pq: the database system is starting up", "solution": "Il bug è che il codice tenta di inizializzare l'ORM engine prima che il database sia completamente avviato.\n\n**Soluzione concisa:** Utilizza un meccanismo di ritardo per attendere che il database sia pronto prima di iniziare l'ORM engine. Ad esempio, si può utilizzare la funzione `time.Sleep()` con un tempo di attesa sufficiente.\n\nEsempio di codice corretto:\n```go\nfunc InitDBEngine() {\n    // Attendi 5 secondi per garantire che il database sia pronto\n    time.Sleep(5 * time.Second)\n    \n    // Inizializza l'ORM engine\n    db, err := sql.Open(\"postgres\", \"user:password@localhost/dbname\")\n    if err != nil {\n        log.Fatal(err)\n    }\n    //"}
{"timestamp": "2025-10-05T17:59:30.189744", "container": "frontend", "language": "generic", "error": "2025/09/28 09:32:18 [error] 42#42: *1 connect() failed (111: Connection refused) while connecting to upstream, client: 172.21.0.1, server: 192.168.1.10, request: \"GET /api/agents HTTP/1.1\", upstream: \"http://172.21.0.3:8003/agents\", host: \"peschiera3.ddns.net\", referrer: \"https://peschiera3.ddns.net/dossier/\"", "solution": "Il bug è che il server non sta ascoltando sulla porta 8003.\n\nSoluzione: assicurarsi di avere un servizio web eseguibile sulla porta 8003. Ad esempio, nel caso di Node.js:\n\n```javascript\nconst http = require('http');\n\nconst server = http.createServer((req, res) => {\n    res.writeHead(200, {'Content-Type': 'text/plain'});\n    res.end('Hello World\\n');\n});\n\nserver.listen(8003, () => {\n    console.log('Server in ascolto sulla porta 8003');\n});\n```\n\nNota che la soluzione dipende dal linguaggio di programmazione e dalla tecnologia utilizzata per creare il servizio web."}
{"timestamp": "2025-10-05T17:59:30.903452", "container": "dossier-backend", "language": "generic", "error": "\u001b[32m2025-09-27 03:12:45\u001b[0m | \u001b[31m\u001b[1mERROR   \u001b[0m | \u001b[31m\u001b[1m[FETCH] Errore fetch GNews: 'NoneType' object is not iterable\u001b[0m", "solution": "Il bug è che il codice cerca di iterare su un oggetto `None`, ovvero un valore nullo. Questo potrebbe succedere se la chiave del dizionario non esiste.\n\n**Soluzione concisa:** Verificare se la chiave del dizionario esiste prima di cercarla.\n\nEsempio di codice corretto:\n```python\nimport requests\n\n# caricamento dei dati da GNews\nresponse = requests.get('https://gnews.org/api/v3/topstories')\ndata = response.json()\n\nif 'topstories' in data and data['topstories']:\n    # il dizionario contiene la chiave 'topstories'\nelse:\n    print(\"Errore: non esistono topstories\")\n```"}
{"timestamp": "2025-10-05T17:59:31.588942", "container": "couchdb1", "language": "generic", "error": "[error] 2025-09-26T00:34:02.116105Z couchdb@couchdb1 <0.467.0> -------- ** System running to use fully qualified hostnames **", "solution": "Il bug è che il server CouchDB richiede un hostnome completo (FQDN) per funzionare correttamente, ma non è stato specificato.\n\n**Soluzione:** Assicurarsi di utilizzare un hostnome completo nel file di configurazione del server CouchDB. Ad esempio:\n\n```bash\n# /etc/couchdb/local.ini\n[server]\nhost = 'couchdb1.example.com'\n```\n\nIn questo modo, il server CouchDB sarà in grado di funzionare correttamente utilizzando un hostnome completo."}
{"timestamp": "2025-10-05T17:59:32.126877", "container": "gitea-db-1", "language": "generic", "error": "2025-09-28 09:32:41.137 UTC [28] FATAL:  the database system is starting up", "solution": "Il bug è che il messaggio di errore non fornisce informazioni specifiche sul problema, ma solo un messaggio generico \"FATAL\". \n\nLa soluzione potrebbe essere di aumentare la livello di dettaglio del log, ad esempio utilizzando `log_level = debug` per vedere i dettagli dell'errore.\n\nEsempio di codice:\n```c\n#include <gitea.h>\n\nint main() {\n    gitea_db_open(\"nome_database\", \"nome_user\", \"password\");\n    return 0;\n}\n```\nNota: il codice è un esempio semplice e non risolve il problema specifico del messaggio di errore."}
{"timestamp": "2025-10-05T17:59:32.795692", "container": "proxy", "language": "generic", "error": "2025/09/25 23:21:07 [error] 27#27: *134 connect() failed (111: Connection refused) while connecting to upstream, client: 172.17.0.1, server: localhost, request: \"GET /v1 HTTP/1.1\", upstream: \"http://172.17.0.1:1234/v1\", host: \"peschiera3.ddns.net\", referrer: \"https://peschiera3.ddns.net/api\"", "solution": "Il bug è che il server non sta ascoltando sulla porta 1234.\n\n**Soluzione:** Assicurarsi di eseguire il servizio web o l'applicazione che ascolta su quella porta. Ad esempio, se si utilizza Node.js e Express, assicurarsi di eseguire `node app.js` per avviare l'applicazione.\n\n**Esempio di codice (Node.js + Express):**\n```javascript\nconst express = require('express');\nconst app = express();\n\napp.get('/v1', (req, res) => {\n  res.send('OK');\n});\n\napp.listen(1234, () => {\n  console.log('Ascolto sulla porta 1234');\n});\n```\nNota che in questo esempio si utilizza la porta 1234 come punto di ascolto"}
{"timestamp": "2025-10-05T17:59:33.600033", "container": "proxy", "language": "generic", "error": "2025/09/25 23:21:07 [error] 27#27: *138 connect() failed (111: Connection refused) while connecting to upstream, client: 172.17.0.1, server: localhost, request: \"GET /v2 HTTP/1.1\", upstream: \"http://172.17.0.1:4891/\", host: \"peschiera3.ddns.net\", referrer: \"https://peschiera3.ddns.net/api\"", "solution": "Il bug è che il client (in questo caso, un'applicazione web) sta cercando di connettersi al server localhost sulla porta 4891, ma il server non è configurato per ascoltare su questa porta.\n\n**Soluzione:** assicurarsi che il server sia configurato per ascoltare su una porta specifica e che la porta sia aperta nel firewall. Ad esempio:\n\n```php\n$server = new Server('localhost', 8080); // ascolta sulla porta 8080\n```\n\nNota: in questo esempio, il server ascolta sulla porta 8080 invece di 4891."}
{"timestamp": "2025-10-05T17:59:34.239445", "container": "proxy", "language": "generic", "error": "2025/09/25 23:21:09 [error] 25#25: *155 connect() failed (111: Connection refused) while connecting to upstream, client: 172.17.0.1, server: localhost, request: \"GET /rea HTTP/1.1\", upstream: \"http://172.17.0.1:8000/\", host: \"peschiera3.ddns.net\", referrer: \"https://peschiera3.ddns.net/api\"", "solution": "Il bug è che il server non sta ascoltando su port 80 (il porto predefinito per HTTP) e quindi il client non riesce a stabilire una connessione.\n\n**Soluzione:** assicurarsi di avviare il servizio web con l'opzione `-p` o `--port` per specificare il porto ascoltato, ad esempio:\n\n```bash\npython -m http.server -p 8000\n```\n\nIn questo modo, il server ascolterà su port 8000 e non sulla porta predefinita."}
{"timestamp": "2025-10-05T17:59:34.850921", "container": "privoxy-updater", "language": "python", "error": "Traceback (most recent call last):", "solution": "Il bug è probabilmente legato alla mancanza di una dipendenza corretta per la libreria `pysocks`.\n\nSoluzione: aggiungere la dipendenza `pysocks` al file `setup.py`:\n```python\nfrom setuptools import setup, find_packages\n\nsetup(\n    name='privoxy-updater',\n    version='1.0',\n    install_requires=['pysocks'],\n    # altre impostazioni...\n)\n```\nNota: il codice esatto dipenderà dalle specifiche richieste del progetto `privoxy-updater`."}
{"timestamp": "2025-10-05T17:59:35.388826", "container": "privoxy-updater", "language": "python", "error": "  File \"/usr/local/lib/python3.11/site-packages/urllib3/connection.py\", line 198, in _new_conn", "solution": "Il bug è che il file `urllib3` non è stato installato correttamente.\n\n**Soluzione:**\n\nInstalla i pacchetti necessari con pip:\n```bash\npip3 install --upgrade urllib3\n```\nQuesto dovrebbe risolvere il problema e consentire di aggiornare Privoxy."}
{"timestamp": "2025-10-05T17:59:35.708863", "container": "privoxy", "language": "python", "error": "2025-08-21 09:18:16.458 7c3e34d33b38 Error: write to client failed: Invalid argument", "solution": "Il bug è probabilmente legato alla configurazione del protocollo HTTP/2, poiché il messaggio di errore indica \"Invalid argument\", che potrebbe essere dovuto a un problema con la chiave o il valore della proprietà `max_pump_size` nella configurazione del proxy.\n\n**Soluzione:** assicurarsi che la proprietà `max_pump_size` sia impostata su un valore ragionevole, ad esempio:\n\n```java\nmaxPumpSize = 1048576; // 1MB\n```\n\nQuesto può aiutare a risolvere il problema di scrittura fallita al client."}
{"timestamp": "2025-10-07T15:50:29.794655", "container": "gitea", "language": "python", "error": "2025/09/28 11:32:41 routers/common/db.go:36:InitDBEngine() [E] ORM engine initialization attempt #1/10 failed. Error: pq: the database system is starting up", "solution": "Il bug è che il codice non attende la fine dell'avvio del database prima di tentare di inizializzarlo.\n\nSoluzione:\nIncludi un tempo di attesa prima di tentare di inizializzare l'ORM engine. Ad esempio:\n\n```go\nfunc InitDBEngine() {\n    time.Sleep(5 * time.Second) // attendere 5 secondi prima di iniziare\n    // codice per inizializzare l'ORM engine\n}\n```\n\nQuesto ti permetterà di evitare errori dovuti a un database che non è ancora pronto."}
{"timestamp": "2025-10-07T15:50:31.875244", "container": "dossier-backend", "language": "generic", "error": "\u001b[32m2025-09-27 03:12:45\u001b[0m | \u001b[31m\u001b[1mERROR   \u001b[0m | \u001b[31m\u001b[1m[FETCH] Errore fetch GNews: 'NoneType' object is not iterable\u001b[0m", "solution": "Il bug è che il codice cerca di iterare su un oggetto None, che non può essere trattato come una sequenza.\n\nSoluzione:\nVerifica se l'oggetto è None prima di cercare di iterarlo. Ad esempio:\n\n```python\ngnews = fetch_gnews()  # supponiamo che fetch_gnews restituisca None\nif gnews is not None:\n    for news in gnews:\n        # codice qui\nelse:\n    print(\"Errore: GNews è None\")\n```\n\nIn questo modo, eviti di cercare di iterare su un oggetto None e eviti l'errore \"NoneType\" object is not iterable."}
{"timestamp": "2025-10-07T15:50:32.556060", "container": "proxy", "language": "generic", "error": "2025/09/25 23:21:07 [error] 27#27: *134 connect() failed (111: Connection refused) while connecting to upstream, client: 172.17.0.1, server: localhost, request: \"GET /v1 HTTP/1.1\", upstream: \"http://172.17.0.1:1234/v1\", host: \"peschiera3.ddns.net\", referrer: \"https://peschiera3.ddns.net/api\"", "solution": "Il bug è che il client tenta di connettersi al server localhost, ma il server non è disponibile.\n\n**Soluzione concisa:** assicurarsi che il server sia avviato e ascolti sulla porta corretta (in questo caso 1234).\n\n**Esempio di codice (Apache HTTP Server):**\n\n```bash\n<VirtualHost *:80>\n    ServerName peschiera3.ddns.net\n\n    ProxyPass /v1 http://172.17.0.1:1234/v1\n    ProxyPassReverse /v1 http://172.17.0.1:1234/v1\n</VirtualHost>\n```\n\nNota che in questo esempio, il server Apache è configurato per proxyare le richieste a `http://172.17.0.1:1234/v"}
{"timestamp": "2025-10-07T15:50:33.373298", "container": "proxy", "language": "generic", "error": "2025/09/25 23:21:07 [error] 27#27: *138 connect() failed (111: Connection refused) while connecting to upstream, client: 172.17.0.1, server: localhost, request: \"GET /v2 HTTP/1.1\", upstream: \"http://172.17.0.1:4891/\", host: \"peschiera3.ddns.net\", referrer: \"https://peschiera3.ddns.net/api\"", "solution": "Il bug è che il server non sta ascoltando sulla porta 4891.\n\n**Soluzione concisa:** assicurarsi di avviare correttamente l'applicazione o servizio che si trova su `localhost:4891`. Ad esempio, se si utilizza Node.js e Express:\n\n```javascript\nconst express = require('express');\nconst app = express();\napp.listen(4891, () => {\n  console.log('Servizio ascoltato sulla porta 4891');\n});\n```\n\nIn questo caso, il bug è che l'applicazione non sta ascoltando sulla porta 4891."}
{"timestamp": "2025-10-07T15:50:33.983337", "container": "proxy", "language": "generic", "error": "2025/09/25 23:21:09 [error] 25#25: *155 connect() failed (111: Connection refused) while connecting to upstream, client: 172.17.0.1, server: localhost, request: \"GET /rea HTTP/1.1\", upstream: \"http://172.17.0.1:8000/\", host: \"peschiera3.ddns.net\", referrer: \"https://peschiera3.ddns.net/api\"", "solution": "Il bug è che il server non sta ascoltando su port 8000.\n\nSoluzione: assicurarsi di avere un servizio web eseguente all'interno del container (ad esempio, Apache o Nginx) e di aver configurato correttamente l'accesso al port 8000. \n\nEsempio di codice non errato (Apache):\n```bash\n<VirtualHost *:80>\n    ServerName peschiera3.ddns.net\n    DocumentRoot /var/www/html\n\n    <Directory /var/www/html>\n        Options Indexes FollowSymLinks MultiViews\n        AllowOverride All\n        Require all granted\n    </Directory>\n\n    ProxyPass / http://172.17.0.1:8000/\n    ProxyPassReverse / http://172.17.0.1:8000"}
{"timestamp": "2025-10-07T15:50:34.790143", "container": "gitea-db-1", "language": "generic", "error": "2025-09-28 09:32:41.137 UTC [28] FATAL:  the database system is starting up", "solution": "Il bug è probabilmente legato alla mancanza di una connessione al database. La soluzione potrebbe essere:\n\n* Verificare che il file di configurazione del database sia presente e corretto.\n* Assicurarsi che il servizio di database sia stato avviato correttamente.\n\nEsempio di codice non errato:\n```bash\n# File di configurazione del database\nDB_HOST=\"localhost\"\nDB_USER=\"root\"\nDB_PASSWORD=\"password\"\nDB_NAME=\"gitea_db\"\n\n# Avvio del servizio di database\ndocker run -d --name gitea-db \\\n  -p 5432:5432 \\\n  -e DB_HOST=$DB_HOST \\\n  -e DB_USER=$DB_USER \\\n  -e DB_PASSWORD=$DB_PASSWORD \\\n  -e DB_NAME=$DB_NAME \\\n  gite"}
{"timestamp": "2025-10-07T15:50:35.600766", "container": "couchdb1", "language": "generic", "error": "[error] 2025-09-26T00:34:02.116105Z couchdb@couchdb1 <0.467.0> -------- ** System running to use fully qualified hostnames **", "solution": "Il bug è che il sistema non sta utilizzando i nomi completi dei host in modo corretto.\n\nLa soluzione è quella di configurare correttamente le variabili `hosts` e `port` nel file di configurazione del CouchDB. Ad esempio:\n\n```bash\n[local]\n hosts = \"localhost:5985\"\n```\n\nIn questo esempio, il sistema utilizza il nome host completo (`localhost`) con il porto specificato (`5985`)."}
{"timestamp": "2025-10-07T15:50:36.065765", "container": "frontend", "language": "generic", "error": "2025/09/28 09:32:18 [error] 42#42: *1 connect() failed (111: Connection refused) while connecting to upstream, client: 172.21.0.1, server: 192.168.1.10, request: \"GET /api/agents HTTP/1.1\", upstream: \"http://172.21.0.3:8003/agents\", host: \"peschiera3.ddns.net\", referrer: \"https://peschiera3.ddns.net/dossier/\"", "solution": "Il bug è che il server non sta ascoltando sulla porta 8003.\n\nSoluzione:\n- Assicurarsi di avviare correttamente l'application server (ad esempio, Node.js o Python) e di configurarlo per ascoltare sulla porta 8003."}
{"timestamp": "2025-10-07T15:50:36.374600", "container": "privoxy-updater", "language": "python", "error": "Traceback (most recent call last):", "solution": "Il bug potrebbe essere che il file di configurazione `config.txt` non è stato trovato. La soluzione potrebbe essere aggiungere la seguente riga di codice per specificare il percorso del file:\n\n```python\nimport os\nconfig_file = 'path/alla/config.txt'\n```\n\nIn questo modo, Privoxy-Updater saprà trovare automaticamente il file di configurazione."}
{"timestamp": "2025-10-07T15:50:36.767083", "container": "privoxy-updater", "language": "python", "error": "  File \"/usr/local/lib/python3.11/site-packages/urllib3/connection.py\", line 198, in _new_conn", "solution": "Il bug è che il file `urllib3.connection.py` è stato modificato e ora non è compatibile con la versione di Python installata.\n\n**Soluzione:**\n\nAggiornare le dipendenze del progetto per utilizzare una versione compatibile di `urllib3`.\n\nEsempio di codice (non errato):\n```python\nimport requests\n\nresponse = requests.get('https://www.example.com')\nprint(response.status_code)\n```\nNota: in questo esempio, non c'è un bug specifico che richieda una soluzione, ma è importante assicurarsi di utilizzare le dipendenze più recenti per evitare problemi di compatibilità."}
{"timestamp": "2025-10-07T15:50:37.432248", "container": "privoxy", "language": "python", "error": "2025-08-21 09:18:16.458 7c3e34d33b38 Error: write to client failed: Invalid argument", "solution": "Il bug è che il problema \"Invalid argument\" potrebbe essere causato da un'errata configurazione della porta di rete o dell'indirizzo IP del server proxy.\n\n**Soluzione concisa:** Verifica la configurazione della porta di rete e dell'indirizzo IP del server proxy per assicurarti che sia corretta. Ad esempio, assicurati che la porta 80 (per HTTP) o 443 (per HTTPS) sia configurata correttamente nel file di configurazione del Privoxy.\n\n**Esempio di codice non errato:**\n```python\n# Configurazione del Privoxy per il protocollo HTTP\nhttp_port = 80\nhttp_server = \"localhost\"\n\n# Configurazione del Privoxy per il protocollo HTTPS\nhttps_port = 443\nhttps_server ="}
{"timestamp": "2025-10-07T15:51:35.784658", "container": "gitea-db-1", "language": "generic", "error": "2025-09-28 09:32:41.137 UTC [28] FATAL:  the database system is starting up", "solution": "Il bug è che il log di errore non fornisce informazioni dettagliate sul problema specifico.\n\n**Soluzione:** Aggiungere la opzione `-v` al comando `gitea` per aumentare il livello di logs e ottenere informazioni più dettagliate.\n\nEsempio di codice:\n```bash\ngitea -v\n```\nQuesto comando aumenterà il livello di logs, consentendo di ottenere informazioni più dettagliate sul problema specifico."}
{"timestamp": "2025-10-07T15:51:36.474957", "container": "gitea", "language": "python", "error": "2025/09/28 11:32:41 routers/common/db.go:36:InitDBEngine() [E] ORM engine initialization attempt #1/10 failed. Error: pq: the database system is starting up", "solution": "Il bug è che il codice non attende che il database sia pronto prima di iniziare l'initializzazione dell'engine.\n\nSoluzione:\nUtilizzare un meccanismo di ritardo per attendere che il database sia pronto, ad esempio utilizzando `time.Sleep()` con una durata ragionevole (ad esempio 5 secondi).\n\nEsempio di codice corretto:\n```go\nfunc InitDBEngine() {\n    // Attendi che il database sia pronto\n    time.Sleep(5 * time.Second)\n    \n    // Inizializza l'engine del database\n    // ...\n}\n```\nNota: la soluzione esposta è solo un esempio e potrebbe non essere adatta a tutti i casi, ma rappresenta una possibile soluzione per il problema specifico."}
{"timestamp": "2025-10-07T15:51:37.252140", "container": "dossier-backend", "language": "generic", "error": "\u001b[32m2025-09-27 03:12:45\u001b[0m | \u001b[31m\u001b[1mERROR   \u001b[0m | \u001b[31m\u001b[1m[FETCH] Errore fetch GNews: 'NoneType' object is not iterable\u001b[0m", "solution": "Il bug è che il codice cerca di iterare su un oggetto None, ovvero nulla. Questo può accadere se la variabile che si aspetta di trovare un valore non è stata inizializzata correttamente.\n\n**Soluzione:**\nIn questo caso, potrebbe essere necessario verificare se la variabile `GNews` è stata inizializzata correttamente e se il suo valore è effettivamente None. Se è così, bisogna assicurarsi di inizializzare correttamente la variabile o di gestire l'errore in modo appropriato.\n\n**Esempio di codice:**\n```python\nimport requests\n\nGNews = None  # inizializzazione della variabile GNews\n\nif GNews is not None:\n    response = requests.get('https"}
{"timestamp": "2025-10-07T15:51:38.044145", "container": "frontend", "language": "generic", "error": "2025/09/28 09:32:18 [error] 42#42: *1 connect() failed (111: Connection refused) while connecting to upstream, client: 172.21.0.1, server: 192.168.1.10, request: \"GET /api/agents HTTP/1.1\", upstream: \"http://172.21.0.3:8003/agents\", host: \"peschiera3.ddns.net\", referrer: \"https://peschiera3.ddns.net/dossier/\"", "solution": "Il bug è che il server non sta ascoltando sulla porta 8003.\n\n**Soluzione:** Assicurarsi di avviare correttamente l'applicazione e che la porta 8003 sia effettivamente utilizzata. Ad esempio, se l'applicazione è scritta in Python, assicurarsi di utilizzare la libreria `http.server` con la porta 8003.\n\n**Esempio di codice (Python):**\n```python\nfrom http.server import BaseHTTPRequestHandler, HTTPServer\n\nclass MyRequestHandler(BaseHTTPRequestHandler):\n    def do_GET(self):\n        self.send_response(200)\n        self.end_headers()\n        self.wfile.write(b\"OK\")\n\ndef run_server():\n    server_address = ('', 8003)\n    httpd = HTTPServer(server_address, MyRequestHandler)"}
{"timestamp": "2025-10-07T15:51:38.868666", "container": "proxy", "language": "generic", "error": "2025/09/25 23:21:07 [error] 27#27: *134 connect() failed (111: Connection refused) while connecting to upstream, client: 172.17.0.1, server: localhost, request: \"GET /v1 HTTP/1.1\", upstream: \"http://172.17.0.1:1234/v1\", host: \"peschiera3.ddns.net\", referrer: \"https://peschiera3.ddns.net/api\"", "solution": "Il bug è che il server non sta ascoltando su porto 1234.\n\nSoluzione:\n- Assicurarsi di avere il servizio che gestisce l'applicazione esposto sulla porta desiderata (in questo caso, 1234).\n- Verificare che il file di configurazione del servizio sia corretto e che il servizio stia ascoltando su quella porta.\n\nEsempio di codice non errato (utilizzando Node.js e Express):\n```javascript\nconst express = require('express');\nconst app = express();\n\napp.get('/v1', (req, res) => {\n  // gestione della richiesta\n});\n\napp.listen(1234, () => {\n  console.log('Servizio ascoltante su porto 1234');\n});\n```\nNota: in questo esemp"}
{"timestamp": "2025-10-07T15:51:39.678647", "container": "proxy", "language": "generic", "error": "2025/09/25 23:21:07 [error] 27#27: *138 connect() failed (111: Connection refused) while connecting to upstream, client: 172.17.0.1, server: localhost, request: \"GET /v2 HTTP/1.1\", upstream: \"http://172.17.0.1:4891/\", host: \"peschiera3.ddns.net\", referrer: \"https://peschiera3.ddns.net/api\"", "solution": "Il bug è che il server non sta ascoltando su porto 4891.\n\nLa soluzione è quella di assicurarsi che il servizio sia in esecuzione e stia ascoltando correttamente sul porto 4891. Ad esempio, se si utilizza un container Docker, assicurarsi che il servizio sia stato avviato correttamente:\n\n```bash\ndocker run -p 4891:4891 <immagine-docker>\n```\n\nIn questo modo, il servizio sarà ascoltante sul porto 4891 e la connessione con il client sarà possibile."}
{"timestamp": "2025-10-07T15:51:40.309518", "container": "proxy", "language": "generic", "error": "2025/09/25 23:21:09 [error] 25#25: *155 connect() failed (111: Connection refused) while connecting to upstream, client: 172.17.0.1, server: localhost, request: \"GET /rea HTTP/1.1\", upstream: \"http://172.17.0.1:8000/\", host: \"peschiera3.ddns.net\", referrer: \"https://peschiera3.ddns.net/api\"", "solution": "Il bug è che il server non sta ascoltando sulla porta 8000.\n\nSoluzione:\n* Assicurarsi di avere un servizio web eseguibile sulla porta 8000.\n* Verificare che il file di configurazione del proxy (ad esempio `nginx.conf`) abbia la riga `listen 8000;` per specificare la porta ascoltata.\n\nEsempio di codice non errato:\n```nginx\nhttp {\n    server {\n        listen 80;\n        server_name peschiera3.ddns.net;\n\n        location / {\n            proxy_pass http://172.17.0.1:8000/;\n            proxy_set_header Host $host;\n            proxy_set_header X-Real-IP $remote_addr;\n        }\n    }\n}\n```\nNota che in questo esempio, il server N"}
{"timestamp": "2025-10-07T15:51:41.144675", "container": "couchdb1", "language": "generic", "error": "[error] 2025-09-26T00:34:02.116105Z couchdb@couchdb1 <0.467.0> -------- ** System running to use fully qualified hostnames **", "solution": "Il bug è che il messaggio di errore non fornisce informazioni utili sul problema specifico.\n\n**Soluzione:** Aggiungere ulteriori dettagli al messaggio di errore, come ad esempio l'ID del documento o la chiave di accesso che sta causando il problema. Ad esempio:\n\n```javascript\n[error] 2025-09-26T00:34:02.116105Z couchdb@couchdb1 <0.467.0> -------- \nSystem running to use fully qualified hostnames, but no hostnames were specified.\n```\n\nIn questo caso, il messaggio di errore fornisce una spiegazione più dettagliata del problema e aiuta a identificare la causa dell'errore."}
{"timestamp": "2025-10-07T15:51:41.917044", "container": "privoxy-updater", "language": "python", "error": "Traceback (most recent call last):", "solution": "Il bug è che il codice non include l'importazione della libreria `logging` necessaria per gestire i log dei segnali di errore.\n\nSoluzione: aggiungi l'importazione di `logging` al principio del file, ad esempio:\n```python\nimport logging\n```\nQuesto permetterà di gestire correttamente gli errori e di visualizzare i dettagli dei segnali di errore."}
{"timestamp": "2025-10-07T15:51:42.344591", "container": "privoxy-updater", "language": "python", "error": "  File \"/usr/local/lib/python3.11/site-packages/urllib3/connection.py\", line 198, in _new_conn", "solution": "Il bug è che il file `/usr/local/lib/python3.11/site-packages/urllib3/connection.py` non esiste nel sistema operativo Linux.\n\nLa soluzione è: controllare la presenza e l'installazione dei pacchetti `liburllib3`, `libssl-dev` e `python3-urllib3` per garantire che siano installati correttamente."}
{"timestamp": "2025-10-07T15:51:42.759382", "container": "privoxy", "language": "python", "error": "2025-08-21 09:18:16.458 7c3e34d33b38 Error: write to client failed: Invalid argument", "solution": "Il bug è che il problema \"Invalid argument\" si verifica quando Proxycache non riesce a scrivere i dati sul client, probabilmente a causa di un problema con la connessione.\n\nLa soluzione potrebbe essere:\n\n* Verificare se la porta del server è correttamente impostata\n* Controllare se il client è disponibile e in ascolto sulla porta specificata\n\nEsempio di codice per verificare la porta:\n```python\nimport socket\n\ndef verifica_porta(porta):\n    try:\n        s = socket.socket(socket.AF_INET, socket.SOCK_STREAM)\n        s.connect((\"localhost\", porta))\n        return True\n    except socket.error as e:\n        print(f\"Errore: {e}\")\n        return False\n\nporta = 8080\nse non si può connettere al porto,"}
{"timestamp": "2025-10-07T15:53:04.449559", "container": "gitea", "language": "python", "error": "2025/09/28 11:32:41 routers/common/db.go:36:InitDBEngine() [E] ORM engine initialization attempt #1/10 failed. Error: pq: the database system is starting up", "solution": "Il bug è che il codice non controlla bene l'esito dell'inizializzazione della base di dati, quindi se la base di dati è ancora in fase di avvio, l'errore viene ignorato e si tenta nuovamente.\n\n**Soluzione:**\n\nAggiungere un tempo di attesa prima di tentare nuovamente l'inizializzazione della base di dati per evitare di bloccare il sistema. Ad esempio:\n\n```go\nfunc InitDBEngine() {\n    // ...\n    for i := 0; i < maxAttempts; i++ {\n        if err := db.Open(); err == nil {\n            return\n        }\n        time.Sleep(100 * time.Millisecond)\n    }\n    // gestione dell'errore, ad esempio:\n    log.Printf(\"Errore durante l'inizial"}
{"timestamp": "2025-10-07T15:53:05.420545", "container": "frontend", "language": "generic", "error": "2025/09/28 09:32:18 [error] 42#42: *1 connect() failed (111: Connection refused) while connecting to upstream, client: 172.21.0.1, server: 192.168.1.10, request: \"GET /api/agents HTTP/1.1\", upstream: \"http://172.21.0.3:8003/agents\", host: \"peschiera3.ddns.net\", referrer: \"https://peschiera3.ddns.net/dossier/\"", "solution": "Il bug è che il server non sta ascoltando sulla porta 8003.\n\n**Soluzione concisa:** Assicurarsi di avviare correttamente l'applicazione web e che la porta 8003 sia stata configurata correttamente nel file di configurazione del servizio."}
{"timestamp": "2025-10-07T15:53:05.747524", "container": "dossier-backend", "language": "generic", "error": "\u001b[32m2025-09-27 03:12:45\u001b[0m | \u001b[31m\u001b[1mERROR   \u001b[0m | \u001b[31m\u001b[1m[FETCH] Errore fetch GNews: 'NoneType' object is not iterable\u001b[0m", "solution": "Il bug è che il codice cerca di iterare su un oggetto `None`, che non può essere trattato come una sequenza.\n\nSoluzione:\nVerifica se l'oggetto è stato caricato correttamente e, se no, gestisci l'errore in modo appropriato. Ad esempio:\n\n```python\nimport logging\n\n# ...\n\ntry:\n    data = fetch_gnews()\nexcept TypeError as e:\n    logging.error(f\"Errore fetch GNews: {e}\")\nelse:\n    # dati caricati correttamente\n    pass\n```\n\nIn questo esempio, se il codice cerca di iterare su un oggetto `None`, si verificherà un errore di tipo `TypeError` e verrà gestito in modo appropriato."}
{"timestamp": "2025-10-07T15:53:06.477624", "container": "gitea-db-1", "language": "generic", "error": "2025-09-28 09:32:41.137 UTC [28] FATAL:  the database system is starting up", "solution": "Il bug è probabilmente legato alla configurazione della base di dati. La frase \"the database system is starting up\" suggerisce che il sistema di database non riesce a iniziare correttamente.\n\n**Soluzione concisa:** Verifica la connessione al database e assicurati che i parametri di connessione siano corretti.\n\nEsempio di codice (in Python):\n```python\nimport psycopg2\n\ntry:\n    conn = psycopg2.connect(\n        host=\"localhost\",\n        database=\"gitea_db\",\n        user=\"username\",\n        password=\"password\"\n    )\n    print(\"Connesso al database\")\nexcept psycopg2.Error as e:\n    print(f\"Errore di connessione: {e}\")\n```\nIn questo esempio, il codice prova a connettersi alla base di"}
{"timestamp": "2025-10-07T15:53:07.289434", "container": "proxy", "language": "generic", "error": "2025/09/25 23:21:07 [error] 27#27: *134 connect() failed (111: Connection refused) while connecting to upstream, client: 172.17.0.1, server: localhost, request: \"GET /v1 HTTP/1.1\", upstream: \"http://172.17.0.1:1234/v1\", host: \"peschiera3.ddns.net\", referrer: \"https://peschiera3.ddns.net/api\"", "solution": "Il bug è che il client (in questo caso, un'applicazione di backend) sta tentando di connettersi a se stesso, anziché al server esterno. Ciò succede perché la porta 1234 non è quella corretta per l'accesso al server esterno.\n\nSoluzione:\n- Verificare che la porta 1234 sia effettivamente la porta corretta per l'accesso al server esterno e che il server esterno sia configurato per ascoltare su questa porta.\n- Se necessario, modificare la porta di accesso nel codice dell'applicazione backend."}
{"timestamp": "2025-10-07T15:53:07.898999", "container": "proxy", "language": "generic", "error": "2025/09/25 23:21:07 [error] 27#27: *138 connect() failed (111: Connection refused) while connecting to upstream, client: 172.17.0.1, server: localhost, request: \"GET /v2 HTTP/1.1\", upstream: \"http://172.17.0.1:4891/\", host: \"peschiera3.ddns.net\", referrer: \"https://peschiera3.ddns.net/api\"", "solution": "Il bug è che il server non sta ascoltando su l'indirizzo IP specificato (`http://172.17.0.1:4891/`) che è diverso dallo indirizzo IP del client (`172.17.0.1`).\n\n**Soluzione:** assicurarsi di configurare correttamente il server a utilizzare lo stesso indirizzo IP e porta per l'accesso ai servizi.\n\n**Esempio di codice (Apache):**\n```bash\n<VirtualHost *:4891>\n    ServerName peschiera3.ddns.net\n    DocumentRoot /var/www/html\n\n    # Configurazione per il proxy passante\n    ProxyPass /v2 http://localhost:8080/\n    ProxyPassReverse /v2 http://localhost:8080/\n\n    # Configurazione per la gest"}
{"timestamp": "2025-10-07T15:53:08.716637", "container": "proxy", "language": "generic", "error": "2025/09/25 23:21:09 [error] 25#25: *155 connect() failed (111: Connection refused) while connecting to upstream, client: 172.17.0.1, server: localhost, request: \"GET /rea HTTP/1.1\", upstream: \"http://172.17.0.1:8000/\", host: \"peschiera3.ddns.net\", referrer: \"https://peschiera3.ddns.net/api\"", "solution": "Il bug è che il server non sta ascoltando sulla porta 8000.\n\nSoluzione:\n- Assicurarsi di avere un servizio web correttamente configurato e eseguibile sulla porta 8000."}
{"timestamp": "2025-10-07T15:53:08.959820", "container": "couchdb1", "language": "generic", "error": "[error] 2025-09-26T00:34:02.116105Z couchdb@couchdb1 <0.467.0> -------- ** System running to use fully qualified hostnames **", "solution": "Il bug è che il messaggio di errore non contiene informazioni dettagliate sul problema specifico.\n\n**Soluzione:** Aggiungere ulteriori informazioni al messaggio di errore, ad esempio l'ID dell'errore o la causa specifica del problema.\n\nEsempio di codice:\n```javascript\nconsole.error(`Errore ${err.id}: ${err.reason}`);\n```\nIn questo modo, il messaggio di errore diventa più utile e facile da comprendere."}
{"timestamp": "2025-10-07T15:53:09.444765", "container": "privoxy-updater", "language": "python", "error": "Traceback (most recent call last):", "solution": "Il bug è probabilmente una connessione non stabile con il server di aggiornamento di Privoxy.\n\nLa soluzione potrebbe essere quella di controllare la connessione e di attendere che si stabilisca correttamente prima di procedere con l'aggiornamento. \n\nEsempio di codice (Python):\n```python\nimport requests\n\ndef update_privoxy():\n    try:\n        response = requests.get('https://example.com/privoxy-updater')\n        if response.status_code == 200:\n            # Procedi con l'aggiornamento\n            print(\"Connessione stabile, procedo con l'aggiornamento\")\n        else:\n            print(\"Connessione non stabile, attendi un attimo...\")\n            update_privoxy()\n    except requests.ConnectionError as e:\n        print(f"}
{"timestamp": "2025-10-07T15:53:10.227265", "container": "privoxy-updater", "language": "python", "error": "  File \"/usr/local/lib/python3.11/site-packages/urllib3/connection.py\", line 198, in _new_conn", "solution": "Il bug è che il file `/usr/local/lib/python3.11/site-packages/urllib3/connection.py` non esiste nel sistema operativo Ubuntu.\n\nLa soluzione è:\n\n*   Verifica la presenza del pacchetto `liburllib3-dev` installato sul sistema operativo: `sudo apt-get update && sudo apt-get install -y liburllib3-dev`\n*   Se il pacchetto non è stato trovato, aggiorna l'elenco dei pacchetti disponibili con `sudo apt-get update`.\n*   Installa il pacchetto `liburllib3-dev` se necessario.\n\nEsempio di codice Python che potrebbe causare questo errore:\n```python\nimport urllib3\n\n# Codice non errato\nhttp = urllib3.PoolManager()\n```\nNota: il codice fornito è"}
{"timestamp": "2025-10-07T15:53:11.019193", "container": "privoxy", "language": "python", "error": "2025-08-21 09:18:16.458 7c3e34d33b38 Error: write to client failed: Invalid argument", "solution": "Il bug è che il problema \"Invalid argument\" potrebbe essere causato da un'opzione di configurazione errata o da un problema con la connessione al server.\n\n**Soluzione concisa:**\n\nVerifica le opzioni di configurazione del privoxy e assicurati che l'opzione corretta sia stata impostata. Ad esempio, se il problema è dovuto a una configurazione errata dell'opzione `max-connections`, assicurati di aver impostato un valore positivo.\n\n**Esempio di codice (non errato):**\n```python\nimport privoxy\n\n# Imposta la configurazione corretta per max-connections\nprivoxy.max_connections = 1000\n```\nNota: il codice fornito è solo un esempio e non dovrebbe essere"}
{"timestamp": "2025-10-07T15:58:45.843654", "container": "dossier-backend", "language": "generic", "error": "\u001b[32m2025-09-27 03:12:45\u001b[0m | \u001b[31m\u001b[1mERROR   \u001b[0m | \u001b[31m\u001b[1m[FETCH] Errore fetch GNews: 'NoneType' object is not iterable\u001b[0m", "solution": "Il bug è che il codice cerca di iterare su un oggetto `None` (cioè, nulla) quando si tenta di eseguire una query su una tabella o un database.\n\n**Soluzione concisa:** Verifica che il campo corrispondente non sia impostato su null e controlla la struttura dei dati per assicurarti che non ci siano valori None. Ad esempio:\n\n```python\nimport sqlite3\n\n# Connessione al database\nconn = sqlite3.connect('dossier-backend.db')\nc = conn.cursor()\n\n# Controllo se il campo 'GNews' è impostato su null\nc.execute(\"SELECT * FROM table_name\")\nrows = c.fetchall()\nif rows:\n    for row in rows:\n        if row[0] is None:  # Controlla se il valore è"}
{"timestamp": "2025-10-07T15:58:47.931266", "container": "gitea-db-1", "language": "generic", "error": "2025-09-28 09:32:41.137 UTC [28] FATAL:  the database system is starting up", "solution": "Il bug sembra essere una semplice inizializzazione del database che non riesce a avviarsi correttamente.\n\n**Soluzione:** Verifica se il file di configurazione `/etc/gitea/gitea.ini` è completo e corretto, in particolare controlla la sezione `[database]` e assicurati che il valore di `SQLALCHEMY_DATABASE_URI` sia corretto. Ad esempio:\n\n```ini\n[database]\ntype = sqlite\nhost = /var/lib/gitea/database.db\nuser = gitea\npassword =\n```\n\nSe il file è completo, prova a riavviare il servizio Gitea per verificare se il problema si risolve."}
{"timestamp": "2025-10-07T15:58:48.631742", "container": "proxy", "language": "generic", "error": "2025/09/25 23:21:07 [error] 27#27: *134 connect() failed (111: Connection refused) while connecting to upstream, client: 172.17.0.1, server: localhost, request: \"GET /v1 HTTP/1.1\", upstream: \"http://172.17.0.1:1234/v1\", host: \"peschiera3.ddns.net\", referrer: \"https://peschiera3.ddns.net/api\"", "solution": "Il bug è che il server non sta ascoltando su porto 1234.\n\nSoluzione:\nAssicurarsi di avviare il servizio del server web (ad esempio, Nginx) e che stia ascoltando su porto 1234. Ad esempio:\n\n```bash\nsudo nginx -g 'daemon on; include /etc/nginx/conf.d/*.conf;' -c /etc/nginx/nginx.conf\n```\n\nNota: la soluzione dipenderà dal sistema operativo e dalla configurazione del servizio web."}
{"timestamp": "2025-10-07T15:58:49.167316", "container": "proxy", "language": "generic", "error": "2025/09/25 23:21:07 [error] 27#27: *138 connect() failed (111: Connection refused) while connecting to upstream, client: 172.17.0.1, server: localhost, request: \"GET /v2 HTTP/1.1\", upstream: \"http://172.17.0.1:4891/\", host: \"peschiera3.ddns.net\", referrer: \"https://peschiera3.ddns.net/api\"", "solution": "Il bug è che il server non sta ascoltando su port 4891.\n\nLa soluzione è di assicurarsi che il server stia eseguendo l'applicazione e che sia in grado di ascoltare su quel port. Ad esempio, se si utilizza un container Docker, assicurarsi che il file di configurazione `docker-compose.yml` abbia la riga `ports: - 4891: 4891`.\n\nEsempio di codice:\n```yml\nversion: '3'\nservices:\n  peschiera3:\n    build: .\n    ports:\n      - \"4891: 4891\"\n```\nNota che questo è solo un esempio e potrebbe richiedere ulteriori configurazioni."}
{"timestamp": "2025-10-07T15:58:49.905467", "container": "proxy", "language": "generic", "error": "2025/09/25 23:21:09 [error] 25#25: *155 connect() failed (111: Connection refused) while connecting to upstream, client: 172.17.0.1, server: localhost, request: \"GET /rea HTTP/1.1\", upstream: \"http://172.17.0.1:8000/\", host: \"peschiera3.ddns.net\", referrer: \"https://peschiera3.ddns.net/api\"", "solution": "Il bug è che il server non sta ascoltando su port 8000.\n\n**Soluzione concisa:** assicurarsi di eseguire l'applicazione con il comando `python -m http.server` o `gunicorn` in modo da avviare lo server HTTP correttamente."}
{"timestamp": "2025-10-07T15:58:50.208051", "container": "couchdb1", "language": "generic", "error": "[error] 2025-09-26T00:34:02.116105Z couchdb@couchdb1 <0.467.0> -------- ** System running to use fully qualified hostnames **", "solution": "Il bug è che la configurazione di CouchDB non utilizza i nomi host completi.\n\nSoluzione:\nAggiungere l'opzione `host` nella configurazione di CouchDB, ad esempio:\n\n```javascript\n{\n  \"include_files\": true,\n  \"hosts\": [\"couchdb1:5985\"],\n  \"httpd\": {\n    \"port\": 5986,\n    \"bind_address\": \"0.0.0.0\"\n  }\n}\n```\n\nIn questo esempio, il nome host completo è `couchdb1:5985`."}
{"timestamp": "2025-10-07T15:58:50.755543", "container": "gitea", "language": "python", "error": "2025/09/28 11:32:41 routers/common/db.go:36:InitDBEngine() [E] ORM engine initialization attempt #1/10 failed. Error: pq: the database system is starting up", "solution": "Il bug è che il codice tenta di inizializzare l'ORM engine prima che il database sia pronto.\n\n**Soluzione concisa:** Verifica se il database è stato avviato correttamente e attendi alcuni secondi prima di provare a inizializzarlo.\n\nEsempio di codice non errato:\n```go\nfunc InitDBEngine() {\n    // Attendere 2 secondi per verificare se il database è pronto\n    time.Sleep(2 * time.Second)\n    \n    // Tentare l'inizializzazione dell'ORM engine\n    db, err := pgx.Connect(\"user=postgres password=password host=localhost port=5432 dbname=mydb\")\n    if err != nil {\n        log.Println(err)\n        return\n    }\n    // ...\n}\n```"}
{"timestamp": "2025-10-07T15:58:51.494736", "container": "frontend", "language": "generic", "error": "2025/09/28 09:32:18 [error] 42#42: *1 connect() failed (111: Connection refused) while connecting to upstream, client: 172.21.0.1, server: 192.168.1.10, request: \"GET /api/agents HTTP/1.1\", upstream: \"http://172.21.0.3:8003/agents\", host: \"peschiera3.ddns.net\", referrer: \"https://peschiera3.ddns.net/dossier/\"", "solution": "Il bug è che il server non sta ascoltando sulla porta 8003.\n\n**Soluzione:** assicurarsi di avviare correttamente l'applicazione e che la porta 8003 sia stata effettivamente assegnata all'applicazione. Ad esempio, in Python con Flask:\n```python\nfrom flask import Flask\n\napp = Flask(__name__)\napp.run(host='172.21.0.1', port=8003)\n```\nIn questo caso, il server dovrebbe ascoltare sulla porta 8003 e non rifiutare la connessione."}
{"timestamp": "2025-10-07T15:58:52.106950", "container": "privoxy-updater", "language": "python", "error": "Traceback (most recent call last):", "solution": "Il bug è probabilmente una connessione non stabile con il server Privoxy. La soluzione potrebbe essere quella di controllare la configurazione del server e assicurarsi che sia disponibile e funzionante correttamente.\n\nEsempio di codice (non errato):\n```python\nimport requests\n\ndef connettersi_al_server():\n    url = \"http://localhost:8113\"\n    try:\n        risposta = requests.get(url)\n        return risposta.status_code == 200\n    except requests.ConnectionError as e:\n        print(f\"Errore di connessione: {e}\")\n        return False\n\nif __name__ == \"__main__\":\n    se_connetto = connettersi_al_server()\n    if not se_connetto:\n        print(\"Non riesco a connettermi al server\")\n```"}
{"timestamp": "2025-10-07T15:58:52.889476", "container": "privoxy-updater", "language": "python", "error": "  File \"/usr/local/lib/python3.11/site-packages/urllib3/connection.py\", line 198, in _new_conn", "solution": "Il bug è che il file `/usr/local/lib/python3.11/site-packages/urllib3/connection.py` non esiste più.\n\nSoluzione: assicurarsi di utilizzare la versione più recente del pacchetto `privoxy-updater`. Ad esempio, installare `privoxy-updater` con pip:\n\n```bash\npip3 install --upgrade privoxy-updater\n```\n\nNota: la soluzione dipenderà dal sistema operativo e dalle dipendenze specifiche."}
{"timestamp": "2025-10-07T15:58:53.370814", "container": "privoxy", "language": "python", "error": "2025-08-21 09:18:16.458 7c3e34d33b38 Error: write to client failed: Invalid argument", "solution": "Il bug è probabilmente legato alla gestione delle connessioni con il server proxy.\n\nLa soluzione potrebbe essere di controllare che la chiave del certificato SSL utilizzata per la comunicazione con il server proxy sia correttamente configurata e aggiornata.\n\nEsempio di codice non errato:\n```python\nimport ssl\n\n# Configurazione della chiave del certificato SSL\ncontext = ssl.create_default_context()\ncontext.load_cert_chain('path/to/cert', 'path/to/key')\n\n# Utilizzo del contesto per la comunicazione con il server proxy\nwith privoxy.connect(context) as conn:\n    # Codice di esempio per l'accesso al server proxy\n    conn.write(b'Hello, world!')\n```\nNota che è importante sostituire `'path/to/cert'`"}
{"timestamp": "2025-10-07T15:59:08.284081", "container": "gitea", "language": "python", "error": "2025/09/28 11:32:41 routers/common/db.go:36:InitDBEngine() [E] ORM engine initialization attempt #1/10 failed. Error: pq: the database system is starting up", "solution": "Il bug è che l'applicazione sta tentando di inizializzare il motore DB prima che il sistema di database sia completamente pronto.\n\n**Soluzione concisa:** Aggiungere un timeout per il tentativo di inizializzazione del motore DB, in modo da non bloccare l'applicazione se il sistema di database richiede più tempo per completarsi.\n\nEsempio di codice (non errato):\n```go\nfunc InitDBEngine() {\n    // Aggiungere un timeout di 5 secondi\n    time.Sleep(5 * time.Second)\n    \n    // Tentativo di inizializzazione del motore DB\n    db, err := sql.Open(\"postgres\", \"user:password@localhost/dbname\")\n    if err != nil {\n        log.Println(err)\n        return\n    }\n    // ...\n}"}
{"timestamp": "2025-10-07T15:59:09.271198", "container": "frontend", "language": "generic", "error": "2025/09/28 09:32:18 [error] 42#42: *1 connect() failed (111: Connection refused) while connecting to upstream, client: 172.21.0.1, server: 192.168.1.10, request: \"GET /api/agents HTTP/1.1\", upstream: \"http://172.21.0.3:8003/agents\", host: \"peschiera3.ddns.net\", referrer: \"https://peschiera3.ddns.net/dossier/\"", "solution": "Il bug è che il server non sta ascoltando su port 8003.\n\nSoluzione:\nVerifica che il servizio di backend (ad esempio Nginx o Apache) stia effettivamente ascoltando su quel porto e che la configurazione sia corretta."}
{"timestamp": "2025-10-07T15:59:09.589179", "container": "gitea-db-1", "language": "generic", "error": "2025-09-28 09:32:41.137 UTC [28] FATAL:  the database system is starting up", "solution": "Il bug è che il messaggio di errore non fornisce informazioni dettagliate sul problema specifico.\n\n**Soluzione:** Aggiungere ulteriori log per raccogliere informazioni più dettagliate. Ad esempio, potrebbe essere utile visualizzare i log del database per determinare la causa effettiva dell'errore.\n\n**Esempio di codice (Gitea):**\n```bash\n# Aggiungere il seguente comando al file di configurazione (gitea.ini) per visualizzare i log del database\nlog_level = debug\n\n# Aggiungere il seguente comando al file di configurazione (gitea.ini) per visualizzare i log del database\nlog_file = /var/log/gitea.log\n```\nQueste modifiche consentiranno di"}
{"timestamp": "2025-10-07T15:59:10.390687", "container": "privoxy-updater", "language": "python", "error": "Traceback (most recent call last):", "solution": "Il bug è probabilmente legato alla mancata gestione degli errori durante l'aggiornamento del proxy. \n\nLa soluzione potrebbe essere implementare un meccanismo di gestione degli errori più robusto, ad esempio utilizzando try-except per catturare e gestire le eccezioni che possono verificarsi durante l'aggiornamento.\n\nEsempio di codice corretto:\n```python\ntry:\n    # Codice dell'aggiornamento del proxy\nexcept Exception as e:\n    print(f\"Errore durante l'aggiornamento del proxy: {e}\")\n```\nNota che questo è solo un esempio generico e potrebbe essere necessario implementare una soluzione più complessa in base alle specifiche esigenze dell'applicazione."}
{"timestamp": "2025-10-07T15:59:11.153872", "container": "privoxy-updater", "language": "python", "error": "  File \"/usr/local/lib/python3.11/site-packages/urllib3/connection.py\", line 198, in _new_conn", "solution": "Il bug è che il modulo `urllib3` sta utilizzando una versione non aggiornata del protocollo TLS.\n\n**Soluzione:**\n\nAggiorna il modulo `urllib3` a una versione più recente utilizzando pip:\n```bash\npip install --upgrade urllib3\n```\nQuesto dovrebbe risolvere il problema e consentire di connettersi correttamente ai server."}
{"timestamp": "2025-10-07T15:59:11.554537", "container": "dossier-backend", "language": "generic", "error": "\u001b[32m2025-09-27 03:12:45\u001b[0m | \u001b[31m\u001b[1mERROR   \u001b[0m | \u001b[31m\u001b[1m[FETCH] Errore fetch GNews: 'NoneType' object is not iterable\u001b[0m", "solution": "Il bug è che il codice sta cercando di iterare su un oggetto None, che non può essere trattato come una sequenza.\n\nSoluzione:\nInvece di cercare di iterare direttamente su `None`, dovresti verificare perché l'oggetto è null. Ad esempio:\n\n```python\nif gnews is not None and hasattr(gnews, '__iter__'):\n    # codice per elaborare la sequenza\nelse:\n    print(\"Errore: oggetto None non iterabile\")\n```\n\nIn questo modo, si verifica un controllo più preciso e si evitano errori inutili."}
{"timestamp": "2025-10-07T15:59:12.176933", "container": "proxy", "language": "generic", "error": "2025/09/25 23:21:07 [error] 27#27: *134 connect() failed (111: Connection refused) while connecting to upstream, client: 172.17.0.1, server: localhost, request: \"GET /v1 HTTP/1.1\", upstream: \"http://172.17.0.1:1234/v1\", host: \"peschiera3.ddns.net\", referrer: \"https://peschiera3.ddns.net/api\"", "solution": "Il bug è che il server non sta ascoltando sulla porta 1234.\n\n**Soluzione concisa:** Assicurarsi di avviare il servizio di Apache o Nginx correttamente, ad esempio con la riga `sudo service apache2 start` (su Ubuntu/Debian) o `sudo systemctl start nginx` (su CentOS/RHEL).\n\nEsempio di codice non errato:\n```bash\n# avvio del servizio Apache\nsudo service apache2 start\n```\nNota: il codice è solo un esempio e potrebbe variare in base alla distribuzione Linux utilizzata."}
{"timestamp": "2025-10-07T15:59:12.795240", "container": "proxy", "language": "generic", "error": "2025/09/25 23:21:07 [error] 27#27: *138 connect() failed (111: Connection refused) while connecting to upstream, client: 172.17.0.1, server: localhost, request: \"GET /v2 HTTP/1.1\", upstream: \"http://172.17.0.1:4891/\", host: \"peschiera3.ddns.net\", referrer: \"https://peschiera3.ddns.net/api\"", "solution": "Il bug è che il server non sta ascoltando su porto 4891, ma il client cerca di connettersi a questo porto.\n\n**Soluzione concisa:** assicurarsi che il servizio che sta cercando di raggiungere sia in esecuzione e stia ascoltando sul corretto porto."}
{"timestamp": "2025-10-07T15:59:13.144595", "container": "proxy", "language": "generic", "error": "2025/09/25 23:21:09 [error] 25#25: *155 connect() failed (111: Connection refused) while connecting to upstream, client: 172.17.0.1, server: localhost, request: \"GET /rea HTTP/1.1\", upstream: \"http://172.17.0.1:8000/\", host: \"peschiera3.ddns.net\", referrer: \"https://peschiera3.ddns.net/api\"", "solution": "Il bug è che il server non sta ascoltando su l'indirizzo IP specificato (`http://172.17.0.1:8000/`) e invece deve ascoltare sulla porta 80 (il porto predefinito per HTTPS).\n\n**Soluzione:** assicurarsi di utilizzare la porta corretta nel file di configurazione del server, ad esempio:\n\n```bash\nsudo nano /etc/nginx/sites-available/peschiera3\n```\n\nE aggiungere il seguente codice:\n```nginx\nserver {\n    listen 80;\n    server_name peschiera3.ddns.net;\n\n    location /rea {\n        proxy_pass http://172.17.0.1:8000/;\n        proxy_http_version 1.1;\n        proxy_set_header Upgrade $http_upgrade;\n        proxy_set_header Connection"}
{"timestamp": "2025-10-07T15:59:13.956978", "container": "couchdb1", "language": "generic", "error": "[error] 2025-09-26T00:34:02.116105Z couchdb@couchdb1 <0.467.0> -------- ** System running to use fully qualified hostnames **", "solution": "Il bug è che il server CouchDB non sta utilizzando i nomi completi dei host (FQDN) per le connessioni.\n\n**Soluzione:** assicurarsi di configurare correttamente il file `/etc/hosts` o l'interfaccia utente del sistema operativo per includere gli indirizzi IP e i nomi FQDN dei server.\n\n**Esempio di codice (non errato):**\n```javascript\nconst couchdb = require('couchdb');\n\n// connettersi al server CouchDB utilizzando il nome completo del host\nconst db = new couchdb('http://couchdb1.example.com:5985');\n```\nNota che in questo esempio, `couchdb1` è il nome FQDN del server CouchDB."}
{"timestamp": "2025-10-07T15:59:14.730910", "container": "privoxy", "language": "python", "error": "2025-08-21 09:18:16.458 7c3e34d33b38 Error: write to client failed: Invalid argument", "solution": "Il bug è probabilmente dovuto a un problema di configurazione del protocollo HTTP/2.\n\nLa soluzione potrebbe essere:\n\n* Verificare che il file `privoxy.conf` sia correttamente configurato per l'uso di HTTPS (ad esempio, utilizzare la chiave certificata `certfile` e il file di configurazione `server-cert`) \n* Assicurarsi che la porta 443 sia aperta sul server.\n\nEsempio di codice non errato:\n```bash\n# privoxy.conf\nhttp2 {\n    server-cert = \"/path/to/server-cert\"\n    certfile = \"/path/to/certfile\"\n}\n\nserver {\n    listen 443 ssl;\n}\n```\nNota: questo è solo un esempio e potrebbe richiedere modifiche specifiche in base alle tue esigen"}
{"timestamp": "2025-10-07T16:04:39.388082", "container": "gitea", "language": "python", "error": "2025/09/28 11:32:41 routers/common/db.go:36:InitDBEngine() [E] ORM engine initialization attempt #1/10 failed. Error: pq: the database system is starting up", "solution": "Il bug è che il codice tenta di inizializzare l'orm engine prima che il database sia completamente avviato.\n\n**Soluzione concisa:** Utilizza un meccanismo di ritardo per attendere che il database sia pronto prima di provare a inizializzarlo.\n\nEsempio di codice:\n```go\nimport (\n\t\"time\"\n\n\t\"gitea/routers/common/db\"\n)\n\nfunc InitDBEngine() {\n\tdefer func() {\n\t\tif err := recover(); err != nil {\n\t\t\tdb.Close()\n\t\t\tlog.Println(err)\n\t\t}\n\t}()\n\n\ttime.Sleep(time.Second * 5) // attendi 5 secondi prima di provare a inizializzare l'orm engine\n\tif err := db.InitDBEngine(); err != nil {\n\t\tlog.Println(err)\n\t\treturn\n\t}\n\n\t// il database è"}
{"timestamp": "2025-10-07T16:04:41.480362", "container": "frontend", "language": "generic", "error": "2025/09/28 09:32:18 [error] 42#42: *1 connect() failed (111: Connection refused) while connecting to upstream, client: 172.21.0.1, server: 192.168.1.10, request: \"GET /api/agents HTTP/1.1\", upstream: \"http://172.21.0.3:8003/agents\", host: \"peschiera3.ddns.net\", referrer: \"https://peschiera3.ddns.net/dossier/\"", "solution": "Il bug è che il server non sta ascoltando sulla porta 8003.\n\n**Soluzione**: assicurarsi di avere un servizio Nginx o altri server web configurati per ascoltare su quella porta. Ad esempio, l'errore potrebbe essere risolto aggiungendo la seguente riga al file di configurazione del servizio:\n\n```nginx\nserver {\n    listen 8003;\n    # altre configurazioni...\n}\n```\n\nNota: questo è solo un esempio e potrebbero esserci altre cause dell'errore."}
{"timestamp": "2025-10-07T16:04:42.075269", "container": "privoxy-updater", "language": "python", "error": "Traceback (most recent call last):", "solution": "Il bug è che il codice non include l'importazione della libreria `logging` necessaria per gestire i log degli errori.\n\nSoluzione:\n```python\nimport logging\n```\nNota: in un esempio di codice non errato, la funzione principale potrebbe essere chiamata con successo senza alcun errore. Ad esempio:\n\n```python\nimport logging\n\ndef aggiornaPrivoxy():\n    # codice di aggiornamento Privoxy\n    pass\n\nlogging.basicConfig(level=logging.INFO)\naggiornaPrivoxy()\n```\nIn questo esempio, il codice funziona correttamente e non genera alcun errore."}
{"timestamp": "2025-10-07T16:04:42.723105", "container": "privoxy-updater", "language": "python", "error": "  File \"/usr/local/lib/python3.11/site-packages/urllib3/connection.py\", line 198, in _new_conn", "solution": "Il bug è che il file `/usr/local/lib/python3.11/site-packages/urllib3/connection.py` non esiste più.\n\nSoluzione: assicurarsi di avere l'ultima versione del pacchetto `urllib3` installato, ad esempio:\n\n```bash\npip3 install --upgrade urllib3\n```\n\nNota: il file `/usr/local/lib/python3.11/site-packages/urllib3/connection.py` è solo un esempio di file che potrebbe essere presente in una versione precedente del pacchetto `urllib3`."}
{"timestamp": "2025-10-07T16:04:43.282069", "container": "dossier-backend", "language": "generic", "error": "\u001b[32m2025-09-27 03:12:45\u001b[0m | \u001b[31m\u001b[1mERROR   \u001b[0m | \u001b[31m\u001b[1m[FETCH] Errore fetch GNews: 'NoneType' object is not iterable\u001b[0m", "solution": "Il bug è che il codice cerca di iterare su un oggetto None, che non può essere trattato come una sequenza.\n\nSoluzione:\nInvece di cercare di iterare direttamente su `None`, dovresti verificare perché l'oggetto è None e quindi non contiene dati da elaborare.\n\nEsempio di codice corretto:\n\n```python\nimport requests\n\n# Cerca di caricare i dati del GNews\nresponse = requests.get('https://gnews.io/api/v3/top-headlines')\nif response.status_code == 200:\n    data = response.json()\n    # Verifica se la chiave 'sources' esiste e non è None\n    if 'sources' in data and data['sources'] is not None:\n        for source in data['sources']:\n            print(source)\n    else:"}
{"timestamp": "2025-10-07T16:04:44.073527", "container": "proxy", "language": "generic", "error": "2025/09/25 23:21:07 [error] 27#27: *134 connect() failed (111: Connection refused) while connecting to upstream, client: 172.17.0.1, server: localhost, request: \"GET /v1 HTTP/1.1\", upstream: \"http://172.17.0.1:1234/v1\", host: \"peschiera3.ddns.net\", referrer: \"https://peschiera3.ddns.net/api\"", "solution": "Il bug è che il server non sta ascoltando su port 1234.\n\nLa soluzione è quella di eseguire il comando `systemctl restart nginx` (o il comando corrispondente per il sistema operativo utilizzato) per riavviare il servizio Nginx, che gestisce la connessione al server."}
{"timestamp": "2025-10-07T16:04:44.418853", "container": "proxy", "language": "generic", "error": "2025/09/25 23:21:07 [error] 27#27: *138 connect() failed (111: Connection refused) while connecting to upstream, client: 172.17.0.1, server: localhost, request: \"GET /v2 HTTP/1.1\", upstream: \"http://172.17.0.1:4891/\", host: \"peschiera3.ddns.net\", referrer: \"https://peschiera3.ddns.net/api\"", "solution": "Il bug è che il server non sta ascoltando su port 4891.\n\n**Soluzione concisa:** Assicurarsi di avviare correttamente l'ascolto del server su quel port. Ad esempio, utilizzare un comando come `nginx -g \"daemon on; listen 4891;` per avviare l'ascolto del server Nginx.\n\n**Esempio di codice non errato:**\n```bash\n# file: /etc/nginx/conf.d/peschiera3.conf\nserver {\n    listen 4891;\n    server_name peschiera3.ddns.net;\n\n    location /v2 {\n        proxy_pass http://172.17.0.1:4891/;\n        proxy_set_header Host $host;\n        proxy_set_header X-Real-IP $remote_addr;\n    }"}
{"timestamp": "2025-10-07T16:04:45.224397", "container": "proxy", "language": "generic", "error": "2025/09/25 23:21:09 [error] 25#25: *155 connect() failed (111: Connection refused) while connecting to upstream, client: 172.17.0.1, server: localhost, request: \"GET /rea HTTP/1.1\", upstream: \"http://172.17.0.1:8000/\", host: \"peschiera3.ddns.net\", referrer: \"https://peschiera3.ddns.net/api\"", "solution": "Il bug è che il server non sta ascoltando su port 80 (l'indizio predefinito per HTTP) e quindi il client non riesce a stabilire una connessione.\n\nLa soluzione è di eseguire il comando `systemctl restart nginx` (se si utilizza Nginx come server web) o `sudo service apache2 restart` (se si utilizza Apache come server web), in modo da riavviare i servizi e farli ascoltare su port 80."}
{"timestamp": "2025-10-07T16:04:45.733227", "container": "gitea-db-1", "language": "generic", "error": "2025-09-28 09:32:41.137 UTC [28] FATAL:  the database system is starting up", "solution": "Il bug è probabilmente legato alla configurazione del file di configurazione (`/etc/gitea/gitea.ini`).\n\nLa soluzione potrebbe essere di verificare che il file di configurazione sia correttamente impostato, in particolare la sezione `database` e l'opzione `driver`.\n\nEsempio di codice non errato:\n```ini\n[database]\ntype = sqlite3\npath = /var/lib/gitea/database.db\n```\nAssicurarsi che il percorso del file di database sia corretto e che il sistema abbia i permessi necessari per accedere al file."}
{"timestamp": "2025-10-07T16:04:46.380786", "container": "couchdb1", "language": "generic", "error": "[error] 2025-09-26T00:34:02.116105Z couchdb@couchdb1 <0.467.0> -------- ** System running to use fully qualified hostnames **", "solution": "Il bug è che il sistema non utilizza i nomi completi dei host, ma solo i nomi di dominio (FQDN). Ciò può causare problemi quando si cerca di connettersi al database da un'altra macchina.\n\n**Soluzione:** assicurarsi di utilizzare i nomi completi dei host in modo corretto. Ad esempio, invece di utilizzare \"localhost\", utilizzare \"127.0.0.1\" o il nome FQDN del computer che esegue CouchDB.\n\nEsempio di codice non errato:\n```javascript\nvar db = new CouchDB('http://127.0.0.1:5984');\n```\nInvece, l'esempio seguente contiene il bug:\n```javascript\nvar db = new CouchDB('localhost');"}
{"timestamp": "2025-10-07T16:04:47.178518", "container": "privoxy", "language": "python", "error": "2025-08-21 09:18:16.458 7c3e34d33b38 Error: write to client failed: Invalid argument", "solution": "Il bug è che il problema \"Invalid argument\" può essere causato da un'eccezione che si verifica quando il codice prova a scrivere dati al client, ma non fornisce sufficienti informazioni per determinare l'errore.\n\n**Soluzione:** Verifica se la variabile `client` è stata impostata correttamente e se i dati che vengono scritti sono validi. Ad esempio:\n\n```python\n# Non errore, poiché il problema non è nel codice\ndef write_to_client(client, data):\n    client.write(data)\n```\n\nIn questo esempio, il problema \"Invalid argument\" potrebbe essere causato da un'eccezione che si verifica quando `client` è null o vuoto."}
{"timestamp": "2025-10-07T16:07:39.096965", "container": "gitea", "language": "python", "error": "2025/09/28 11:32:41 routers/common/db.go:36:InitDBEngine() [E] ORM engine initialization attempt #1/10 failed. Error: pq: the database system is starting up", "solution": "Il bug è che il codice non attende la fine dell'avvio del sistema di database prima di tentare di inizializzarlo.\n\nSoluzione:\nUtilizzare un meccanismo di ritardo per attendere l'avvio del sistema di database, ad esempio utilizzando `time.Sleep()` con un tempo di attesa ragionevole.\n\nEsempio di codice corretto (in Go):\n```go\nimport (\n    \"context\"\n    \"fmt\"\n    \"time\"\n)\n\nfunc InitDBEngine(ctx context.Context) error {\n    // attendere 2 secondi per garantire che il sistema di database sia pronto\n    time.Sleep(2 * time.Second)\n    \n    // inizializzare l'engine del database\n    // ...\n}\n```"}
{"timestamp": "2025-10-07T16:07:40.012447", "container": "dossier-backend", "language": "generic", "error": "\u001b[32m2025-09-27 03:12:45\u001b[0m | \u001b[31m\u001b[1mERROR   \u001b[0m | \u001b[31m\u001b[1m[FETCH] Errore fetch GNews: 'NoneType' object is not iterable\u001b[0m", "solution": "Il bug è che il codice cerca di iterare su un oggetto `None`, ovvero nulla. Questo può accadere se la variabile che si aspetta di trovare un oggetto non presente.\n\nSoluzione:\nVerifica che la variabile in questione sia stata correttamente inizializzata e che il codice non stia cercando di iterare su una variabile che è stata impostata a `None`.\n\nEsempio di codice errato:\n```python\ngnews = None\nfor articolo in gnews:\n    print(articolo)\n```\nSoluzione corretta:\n```python\ngnews = ['Articolo 1', 'Articolo 2']  # assicurati che gnews sia stata inizializzata con un oggetto iterabile\nfor articolo in"}
{"timestamp": "2025-10-07T16:07:40.803994", "container": "couchdb1", "language": "generic", "error": "[error] 2025-09-26T00:34:02.116105Z couchdb@couchdb1 <0.467.0> -------- ** System running to use fully qualified hostnames **", "solution": "Il bug è che il server CouchDB richiede di utilizzare nomi completi di host (FQDN) per le connessioni, ma non è stato specificato se il nome del server sia un FQDN o un indirizzo IP.\n\n**Soluzione:**\n\nUtilizza il comando `--hostname` o `-H` per specificare il nome completo del server. Ad esempio:\n\n```bash\ncouchdb -H \"localhost:5984\"\n```\n\nIn questo modo, il server CouchDB saprà utilizzare il nome completo del server per le connessioni."}
{"timestamp": "2025-10-07T16:07:41.352363", "container": "gitea-db-1", "language": "generic", "error": "2025-09-28 09:32:41.137 UTC [28] FATAL:  the database system is starting up", "solution": "Il bug è che il messaggio di errore non fornisce informazioni dettagliate sul problema specifico.\n\n**Soluzione:** Aggiungere ulteriori log per identificare l'errore.\n\nEsempio di codice (in Python):\n```python\nimport logging\n\nlogging.basicConfig(level=logging.INFO)\n\ntry:\n    # codice che potrebbe generare un errore\n    conn = connect_to_db()\nexcept Exception as e:\n    logging.error(f\"Errore durante la connessione al database: {str(e)}\")\n```\nIn questo esempio, aggiungendo il log di errore possiamo identificare l'errore specifico e prendere misure correttive."}
{"timestamp": "2025-10-07T16:07:42.043616", "container": "proxy", "language": "generic", "error": "2025/09/25 23:21:07 [error] 27#27: *134 connect() failed (111: Connection refused) while connecting to upstream, client: 172.17.0.1, server: localhost, request: \"GET /v1 HTTP/1.1\", upstream: \"http://172.17.0.1:1234/v1\", host: \"peschiera3.ddns.net\", referrer: \"https://peschiera3.ddns.net/api\"", "solution": "Il bug è che il server non sta ascoltando sulla porta 1234.\n\nSoluzione: assicurarsi di avere un servizio di ascolto correttamente configurato e avviato su quella porta. Ad esempio, in Node.js, potresti utilizzare l'espressione `app.listen(1234)` per ascoltare sulla porta 1234.\n\nEsempio di codice (Node.js):\n```javascript\nconst app = require('express')();\nconst http = require('http').createServer(app);\n\nhttp.listen(1234, () => {\n  console.log('Servizio ascolta sulla porta 1234');\n});\n```\nNota che il codice è solo un esempio e potrebbe richiedere modifiche per adattarsi al tuo progetto specifico."}
{"timestamp": "2025-10-07T16:07:42.822770", "container": "proxy", "language": "generic", "error": "2025/09/25 23:21:07 [error] 27#27: *138 connect() failed (111: Connection refused) while connecting to upstream, client: 172.17.0.1, server: localhost, request: \"GET /v2 HTTP/1.1\", upstream: \"http://172.17.0.1:4891/\", host: \"peschiera3.ddns.net\", referrer: \"https://peschiera3.ddns.net/api\"", "solution": "Il bug è che il server non sta ascoltando su port 4891, ma il client tenta di connettersi a questo porto.\n\n**Soluzione concisa:** assicurarsi che il server stia eseguendo un servizio web e che sia configurato per ascoltare su port 4891."}
{"timestamp": "2025-10-07T16:07:43.157278", "container": "proxy", "language": "generic", "error": "2025/09/25 23:21:09 [error] 25#25: *155 connect() failed (111: Connection refused) while connecting to upstream, client: 172.17.0.1, server: localhost, request: \"GET /rea HTTP/1.1\", upstream: \"http://172.17.0.1:8000/\", host: \"peschiera3.ddns.net\", referrer: \"https://peschiera3.ddns.net/api\"", "solution": "Il bug è che il server non risponde al client.\n\nLa soluzione è di assicurarsi che il servizio sia avviato e ascolti sulla porta 8000. \n\nEsempio di codice per verificare se un servizio Python sta correttamente ascoltando la porta:\n\n```python\nimport socket\n\ndef controlla_ascolto(porta):\n    try:\n        with socket.socket(socket.AF_INET, socket.SOCK_STREAM) as s:\n            s.bind((\"0.0.0.0\", porta))\n            s.listen(1)\n            print(f\"Servizio in ascolto sulla porta {porta}\")\n    except socket.error as e:\n        print(f\"Il servizio non sta correttamente ascoltando la porta {porta}: {e}\")\n\ncontrolla_ascolto(8000)"}
{"timestamp": "2025-10-07T16:07:43.994246", "container": "frontend", "language": "generic", "error": "2025/09/28 09:32:18 [error] 42#42: *1 connect() failed (111: Connection refused) while connecting to upstream, client: 172.21.0.1, server: 192.168.1.10, request: \"GET /api/agents HTTP/1.1\", upstream: \"http://172.21.0.3:8003/agents\", host: \"peschiera3.ddns.net\", referrer: \"https://peschiera3.ddns.net/dossier/\"", "solution": "Il bug è che il server non sta ascoltando sulla porta 8003.\n\n**Soluzione:** assicurarsi di avviare correttamente l'applicazione e che la porta 8003 sia stata configurata correttamente nel file di configurazione del servizio.\n\nEsempio di codice (non errato):\n```php\n// server.php\n$server = new Swoole\\Http\\Server('0.0.0.0', 8003, $config);\n$server->on('start', function ($server) {\n    echo \"Server avviato\\n\";\n});\n$server->listen();\n```\nNota: il codice sopra è un esempio di base in PHP con Swoole e potrebbe non essere completo o corretto."}
{"timestamp": "2025-10-07T16:07:44.739427", "container": "privoxy-updater", "language": "python", "error": "Traceback (most recent call last):", "solution": "Il bug è probabilmente legato alla mancanza di una dipendenza necessaria per il modulo Privoxy-Updater. \n\nSoluzione: assicurarsi di installare tutte le dipendenze necessarie prima di eseguire l'aggiornamento.\n\nEsempio di codice (non errato):\n```bash\npip install -r requirements.txt\npython setup.py upgrade\n```\nNota: il codice è un esempio generico e potrebbe non essere applicabile al software Privoxy-Updater specifico."}
{"timestamp": "2025-10-07T16:07:45.242694", "container": "privoxy-updater", "language": "python", "error": "  File \"/usr/local/lib/python3.11/site-packages/urllib3/connection.py\", line 198, in _new_conn", "solution": "Il bug è che il file di configurazione `/etc/privoxy.conf` non esiste o non è leggibile.\n\n**Soluzione concisa:**\n\nAssicurati di avere un file `/etc/privoxy.conf` con la configurazione corretta e che i permessi di accesso siano adeguati. Ad esempio, potresti aggiungere il seguente codice in `/etc/privoxy.conf` per consentire l'accesso al file:\n\n```bash\nset log-file = /var/log/privoxy.log\n```\n\nQuesto assicura che Privoxy possa leggere e scrivere nel file di configurazione."}
{"timestamp": "2025-10-07T16:07:45.882220", "container": "privoxy", "language": "python", "error": "2025-08-21 09:18:16.458 7c3e34d33b38 Error: write to client failed: Invalid argument", "solution": "Il bug è che il problema \"Invalid argument\" potrebbe essere causato da un'opzione di configurazione non correttamente impostata.\n\n**Soluzione concisa:** Verifica le opzioni di configurazione del proxy e assicurati che l'opzione `write_large_requests` sia impostata su `true`.\n\n**Esempio di codice (non errato):**\n```python\nfrom privoxy import Privoxy\n\nprivoxy = Privoxy()\nprivoxy.set_option('write_large_requests', True)\n```\nNota: il codice esempio è scritto in Python, ma la soluzione si applica a qualsiasi linguaggio di programmazione che utilizza la libreria Privoxy."}
{"timestamp": "2025-10-07T16:13:08.665978", "container": "gitea", "language": "python", "error": "2025/09/28 11:32:41 routers/common/db.go:36:InitDBEngine() [E] ORM engine initialization attempt #1/10 failed. Error: pq: the database system is starting up", "solution": "Il bug è che il codice non attende che la connessione al database sia stabile prima di tentare l'initializzazione dell'engine.\n\n**Soluzione concisa:**\n\nAggiungere un tempo di attesa prima di riconnettersi al database in caso di errore. Ad esempio:\n\n```go\nfunc InitDBEngine() {\n    // ...\n    for attempt := 0; attempt < maxAttempts; attempt++ {\n        if err := db.Connect(); err != nil {\n            if err == sql.ErrConnDone {\n                // connessione al database è stata stabilita, attendi un po' prima di riconnettersi\n                time.Sleep(500 * time.Millisecond)\n                continue\n            }\n            return\n        }\n        break\n    }\n    // ...\n}\n```\n\nIn questo esempio, il cod"}
{"timestamp": "2025-10-07T16:13:10.780994", "container": "frontend", "language": "generic", "error": "2025/09/28 09:32:18 [error] 42#42: *1 connect() failed (111: Connection refused) while connecting to upstream, client: 172.21.0.1, server: 192.168.1.10, request: \"GET /api/agents HTTP/1.1\", upstream: \"http://172.21.0.3:8003/agents\", host: \"peschiera3.ddns.net\", referrer: \"https://peschiera3.ddns.net/dossier/\"", "solution": "Il bug è che il server non sta ascoltando sulla porta 8003.\n\nSoluzione:\n- Verifica che il servizio di Apache o Nginx (se utilizzato) stia eseguendo correttamente e ascoltando sulla porta 8003.\n- Se necessario, aggiorna le configurazioni del server per correggere l'errore.\n\nEsempio di codice non errato:\n```bash\n# file /etc/apache2/sites-available/agents.conf\n\n<VirtualHost *:80>\n    ServerName peschiera3.ddns.net\n    DocumentRoot /var/www/html\n\n    # Configurazione per la porta 8003\n    ProxyPass /api/agents http://172.21.0.3:8003/\n    ProxyPassReverse /api/agents http://172.21.0"}
{"timestamp": "2025-10-07T16:13:11.635863", "container": "gitea-db-1", "language": "generic", "error": "2025-09-28 09:32:41.137 UTC [28] FATAL:  the database system is starting up", "solution": "Il bug è che il messaggio di errore indica che il sistema di database sta iniziando, ma non fornisce alcun dettaglio sul problema specifico.\n\nSoluzione:\nInvece di un messaggio generico, dovrebbe essere fornito un codice di stato più specifico o ulteriori informazioni per aiutare a diagnosticare il problema. Ad esempio:\n\n```sql\n2025-09-28 09:32:41.137 UTC [28] FATAL:  database system is starting up, but failed to connect to the primary database server.\n```\n\nIn questo modo, si può capire se il problema è legato alla connessione al database o a un altro aspetto."}
{"timestamp": "2025-10-07T16:13:12.319393", "container": "proxy", "language": "generic", "error": "2025/09/25 23:21:07 [error] 27#27: *134 connect() failed (111: Connection refused) while connecting to upstream, client: 172.17.0.1, server: localhost, request: \"GET /v1 HTTP/1.1\", upstream: \"http://172.17.0.1:1234/v1\", host: \"peschiera3.ddns.net\", referrer: \"https://peschiera3.ddns.net/api\"", "solution": "Il bug è che il server non sta ascoltando su porto 1234.\n\n**Soluzione concisa:** Assicurarsi di avviare il servizio del server web e di impostare correttamente la configurazione del socket per ascoltare su porto 1234."}
{"timestamp": "2025-10-07T16:13:12.620217", "container": "proxy", "language": "generic", "error": "2025/09/25 23:21:07 [error] 27#27: *138 connect() failed (111: Connection refused) while connecting to upstream, client: 172.17.0.1, server: localhost, request: \"GET /v2 HTTP/1.1\", upstream: \"http://172.17.0.1:4891/\", host: \"peschiera3.ddns.net\", referrer: \"https://peschiera3.ddns.net/api\"", "solution": "Il bug è che il server locale (localhost) non sta ascoltando su porta 4891.\n\n**Soluzione:** Assicurarsi di avviare il servizio di Apache o altro server web correttamente e di ascoltare sulla porta corretta. Ad esempio, se si utilizza Apache, potrebbe essere necessario aggiungere la seguente riga al file di configurazione `/etc/apache2/sites-available/000-default.conf`:\n\n```bash\n<VirtualHost *:4891>\n    ServerName peschiera3.ddns.net\n    DocumentRoot /var/www/html\n</VirtualHost>\n```\n\nAssicurarsi di sostituire `/var/www/html` con la cartella corretta dove si desidera eseguire il servizio web."}
{"timestamp": "2025-10-07T16:13:13.380720", "container": "proxy", "language": "generic", "error": "2025/09/25 23:21:09 [error] 25#25: *155 connect() failed (111: Connection refused) while connecting to upstream, client: 172.17.0.1, server: localhost, request: \"GET /rea HTTP/1.1\", upstream: \"http://172.17.0.1:8000/\", host: \"peschiera3.ddns.net\", referrer: \"https://peschiera3.ddns.net/api\"", "solution": "Il bug è che il server non sta ascoltando sulla porta 8000.\n\nLa soluzione è di assicurarsi che il servizio che ascolta su quella porta sia in esecuzione e che la porta sia aperta nel file di configurazione del servizio. Ad esempio, se si utilizza Nginx:\n\n```nginx\nhttp {\n    ...\n    upstream peschiera3 {\n        server localhost:8000;\n    }\n    ...\n}\n```\n\nIn questo caso, il bug è che il file di configurazione non specifica la porta 8000, quindi il server cerca di connettersi alla porta 80 (standard per HTTP) anziché 8000."}
{"timestamp": "2025-10-07T16:13:14.075852", "container": "privoxy-updater", "language": "python", "error": "Traceback (most recent call last):", "solution": "Il bug è probabilmente una connessione non stabile con il repository GitHub, che impedisce l'aggiornamento del software Privoxy-Updater.\n\nLa soluzione potrebbe essere quella di controllare la connessione con il repository e di attendere alcuni minuti prima di provare nuovamente l'aggiornamento. \n\nEsempio di codice (non errato):\n```python\nimport requests\n\ndef controlla_connessione():\n    try:\n        response = requests.get('https://api.github.com')\n        if response.status_code == 200:\n            print(\"Connessione stabile\")\n        else:\n            print(\"Connessione instabile\")\n            time.sleep(60)  # attendere 1 minuto\n            controlla_connessione()\n    except Exception as e:\n        print(f\"Errore"}
{"timestamp": "2025-10-07T16:13:14.856295", "container": "privoxy-updater", "language": "python", "error": "  File \"/usr/local/lib/python3.11/site-packages/urllib3/connection.py\", line 198, in _new_conn", "solution": "Il bug è che il file `/usr/local/lib/python3.11/site-packages/urllib3/connection.py` non esiste. Probabilmente è stato sostituito da una versione più recente.\n\nLa soluzione potrebbe essere:\n\n- Verificare la presenza e l'ultima versione del pacchetto `libcurl4`.\n- Installare il pacchetto `libcurl4` se non è già installato.\n- Aggiornare Privoxy-Updater per utilizzare la versione più recente.\n\nEsempio di codice (non errato):\n```python\nimport os\n\ndef main():\n    print(\"Primo esempio di codice\")\n\nif __name__ == \"__main__\":\n    main()\n```\nNota: il codice fornito non contiene errori, ma è solo un esempio per dim"}
{"timestamp": "2025-10-07T16:13:15.642218", "container": "dossier-backend", "language": "generic", "error": "\u001b[32m2025-09-27 03:12:45\u001b[0m | \u001b[31m\u001b[1mERROR   \u001b[0m | \u001b[31m\u001b[1m[FETCH] Errore fetch GNews: 'NoneType' object is not iterable\u001b[0m", "solution": "Il bug è che il codice cerca di iterare su un oggetto None, che non può essere trattato come una sequenza.\n\nSoluzione:\nVerifica se il valore restituito dal database è effettivamente None prima di cercare di iterarlo. Ad esempio:\n\n```python\ngnews = db.session.query(GNews).first()\nif gnews is not None:\n    # procedi con la lettura del GNews\nelse:\n    print(\"Non si è trovato alcun GNews\")\n```\n\nIn questo modo, eviti l'errore e gestisci il caso in cui non si trova alcun GNews."}
{"timestamp": "2025-10-07T16:13:16.241669", "container": "couchdb1", "language": "generic", "error": "[error] 2025-09-26T00:34:02.116105Z couchdb@couchdb1 <0.467.0> -------- ** System running to use fully qualified hostnames **", "solution": "Il bug è che il sistema richiede utilizzare nomi completi di host, ma il server CouchDB non lo fa.\n\n**Soluzione:** assicurarsi che il nome del server sia risolto correttamente e sia utilizzato con la sua parte completa (es. `couchdb1` invece di solo `couchdb`)."}
{"timestamp": "2025-10-07T16:13:16.584682", "container": "privoxy", "language": "python", "error": "2025-08-21 09:18:16.458 7c3e34d33b38 Error: write to client failed: Invalid argument", "solution": "Il bug è che il valore dell'identificatore del pacchetto (in questo caso `7c3e34d33b38`) non è stato inserito correttamente nella chiamata al metodo `write` di Privoxy.\n\nLa soluzione è quella di utilizzare il formato corretto per l'identificatore del pacchetto, ad esempio:\n\n```python\nimport socket\n\n# Creare un nuovo socket\ns = socket.socket(socket.AF_INET, socket.SOCK_STREAM)\n\n# Impostare la direzione del socket\ns.bind(('127.0.0.1', 8080))\n\n# Ascoltare sulla porta 8080\ns.listen(5)\n```\n\nIn questo esempio, il valore dell'identificatore del pacchetto non è necessario perché Privoxy utilizza un identific"}
{"timestamp": "2025-10-07T16:29:43.667861", "container": "gitea-db-1", "language": "generic", "error": "2025-09-28 09:32:41.137 UTC [28] FATAL:  the database system is starting up", "solution": "Il bug è probabilmente legato alla mancanza di una connessione al database.\n\nLa soluzione potrebbe essere quella di assicurarsi che il file di configurazione del database sia presente e corretto, ad esempio:\n\n```bash\n# Esempio di file di configurazione per PostgreSQL\ncat > /etc/postgresql/13/main/postgresql.conf << EOF\ndata_directory = '/var/lib/postgresql/13/main'\nlisten_addresses = 'localhost'\nEOF\n```\n\nIn questo esempio, il file di configurazione `postgresql.conf` è stato creato e contiene le impostazioni standard per PostgreSQL. Assicurarsi che il file sia presente e corretto può aiutare a risolvere l'errore \"database system is starting up\"."}
{"timestamp": "2025-10-07T16:29:45.768705", "container": "dossier-backend", "language": "generic", "error": "\u001b[32m2025-09-27 03:12:45\u001b[0m | \u001b[31m\u001b[1mERROR   \u001b[0m | \u001b[31m\u001b[1m[FETCH] Errore fetch GNews: 'NoneType' object is not iterable\u001b[0m", "solution": "Il bug è che il codice cerca di iterare su un oggetto `None` quando si tenta di caricare i dati da una fonte (in questo caso, GNews).\n\nLa soluzione potrebbe essere:\n```python\n# Cerca di caricare i dati da GNews\ntry:\n    data = fetch_gnews()\nexcept TypeError as e:\n    # Se l'errore è dovuto a un oggetto None, cerca di caricare i dati manualmente\n    if data is None:\n        data = fetch_gnews_manual()\n```\nIn questo esempio, si verifica un tentativo di caricamento dei dati da GNews. Se l'errore è dovuto a un oggetto `None`, si cerca di caricare i dati manualmente utilizzando una funzione alternativa (`fetch_gnews_manual`)."}
{"timestamp": "2025-10-07T16:29:46.543830", "container": "gitea", "language": "python", "error": "2025/09/28 11:32:41 routers/common/db.go:36:InitDBEngine() [E] ORM engine initialization attempt #1/10 failed. Error: pq: the database system is starting up", "solution": "Il bug è che il codice non attende la fine dell'avvio del database prima di tentare di inizializzarlo.\n\n**Soluzione concisa:**\n\nAggiungere un'attesa per garantire che il database sia pronto:\n\n```go\nfunc InitDBEngine() {\n    // ...\n    for {\n        if err := db.Ping(); err == nil {\n            break\n        }\n        time.Sleep(100 * time.Millisecond)\n    }\n    // ...\n}\n```\n\nIn questo esempio, il codice attende 100 millisecondi tra ogni tentativo di inizializzazione del database fino a quando non riesce a connettersi."}
{"timestamp": "2025-10-07T16:29:47.171811", "container": "couchdb1", "language": "generic", "error": "[error] 2025-09-26T00:34:02.116105Z couchdb@couchdb1 <0.467.0> -------- ** System running to use fully qualified hostnames **", "solution": "Il bug è che il nome del server CouchDB non è stato specificato correttamente.\n\nLa soluzione è quella di utilizzare un nome di host completo, ad esempio `localhost` o `127.0.0.1`, invece di solo l'indirizzo IP.\n\nEsempio di codice:\n```javascript\nvar db = require('couchdb').createDatabase({\n  name: 'mydatabase',\n  host: 'localhost'\n});\n```\nNota che in questo esempio, `localhost` è utilizzato come nome del server CouchDB."}
{"timestamp": "2025-10-07T16:29:47.702295", "container": "frontend", "language": "generic", "error": "2025/09/28 09:32:18 [error] 42#42: *1 connect() failed (111: Connection refused) while connecting to upstream, client: 172.21.0.1, server: 192.168.1.10, request: \"GET /api/agents HTTP/1.1\", upstream: \"http://172.21.0.3:8003/agents\", host: \"peschiera3.ddns.net\", referrer: \"https://peschiera3.ddns.net/dossier/\"", "solution": "Il bug è che il server non sta ascoltando sulla porta 8003.\n\n**Soluzione concisa:** Assicurarsi di avviare correttamente l'applicazione e di avere acceso alla porta 8003. \n\nEsempio di codice (Nginx):\n```nginx\nhttp {\n    ...\n    upstream agents {\n        server localhost:8003;\n    }\n    ...\n}\n```\nNota: il codice è un esempio di configurazione Nginx per l'upstream, potrebbe variare a seconda della struttura del progetto."}
{"timestamp": "2025-10-07T16:29:48.287654", "container": "privoxy-updater", "language": "python", "error": "Traceback (most recent call last):", "solution": "Il bug è probabilmente legato alla mancanza di una dipendenza necessaria per il modulo Privoxy-Updater. \n\nLa soluzione potrebbe essere aggiungere la dipendenza `python-privoxy` al file `requirements.txt`.\n\nEsempio di codice corretto:\n```bash\npip install -r requirements.txt\n```\nNota: è importante verificare se il modulo Privoxy-Updater richiede altre dipendenze specifiche."}
{"timestamp": "2025-10-07T16:29:48.738290", "container": "privoxy-updater", "language": "python", "error": "  File \"/usr/local/lib/python3.11/site-packages/urllib3/connection.py\", line 198, in _new_conn", "solution": "Il bug è che il file `urllib3` si trova nella directory `/usr/local/lib/python3.11/site-packages`, ma la variabile `PYTHONPATH` non è aggiornata per includere questa directory.\n\n**Soluzione:**\n\nAggiorna la variabile `PYTHONPATH` per includere la directory corretta:\n\n```bash\nexport PYTHONPATH=$PYTHONPATH:/usr/local/lib/python3.11/site-packages\n```\n\nQuesto ti permetterà di utilizzare il file `urllib3` senza problemi."}
{"timestamp": "2025-10-07T16:29:49.242744", "container": "privoxy", "language": "python", "error": "2025-08-21 09:18:16.458 7c3e34d33b38 Error: write to client failed: Invalid argument", "solution": "Il bug è che il problema \"Invalid argument\" potrebbe essere causato da un problema con la configurazione del proxy o della connessione al client.\n\n**Soluzione concisa:** Verifica che le impostazioni di configurazione del proxy siano corrette e che la connessione al client sia stabile.\n\n**Esempio di codice (non errato):**\n```python\nimport socket\n\n# Configurazione del proxy\nproxy_host = '127.0.0.1'\nproxy_port = 8080\n\n# Creazione della connessione\nsock = socket.socket(socket.AF_INET, socket.SOCK_STREAM)\nsock.connect((proxy_host, proxy_port))\n```\nIn questo esempio, il codice crea una connessione al proxy utilizzando le impostazioni specificate. Se il problema è causato da un problema con la configur"}
{"timestamp": "2025-10-07T16:29:50.044365", "container": "proxy", "language": "generic", "error": "2025/09/25 23:21:07 [error] 27#27: *134 connect() failed (111: Connection refused) while connecting to upstream, client: 172.17.0.1, server: localhost, request: \"GET /v1 HTTP/1.1\", upstream: \"http://172.17.0.1:1234/v1\", host: \"peschiera3.ddns.net\", referrer: \"https://peschiera3.ddns.net/api\"", "solution": "Il bug è che il client (localhost) non sta ascoltando sulla porta 1234.\n\n**Soluzione:** Assicurarsi di avviare l'applicazione o il servizio che si trova su localhost sulla porta corretta. Ad esempio, se si utilizza un server web come Apache o Nginx, bisogna configurare la porta di ascolto correttamente.\n\n**Esempio di codice (Nginx):**\n```nginx\nserver {\n    listen 1234;\n    server_name peschiera3.ddns.net;\n\n    location /v1 {\n        proxy_pass http://172.17.0.1:1234/v1;\n        proxy_set_header Host $host;\n        proxy_set_header X-Real-IP $remote_addr;\n    }\n}\n```\nNota che questo è solo un"}
{"timestamp": "2025-10-07T16:29:50.852736", "container": "proxy", "language": "generic", "error": "2025/09/25 23:21:07 [error] 27#27: *138 connect() failed (111: Connection refused) while connecting to upstream, client: 172.17.0.1, server: localhost, request: \"GET /v2 HTTP/1.1\", upstream: \"http://172.17.0.1:4891/\", host: \"peschiera3.ddns.net\", referrer: \"https://peschiera3.ddns.net/api\"", "solution": "Il bug è che il server non sta ascoltando sulla porta 4891.\n\nLa soluzione potrebbe essere di controllare se il servizio che sta tentando di connettersi (probabilmente un container Docker) sta eseguendo correttamente e ascoltando sulla porta corretta. Ad esempio, se si utilizza Docker, verificare che il comando `docker run` o `docker-compose up` stia eseguendo correttamente.\n\nEsempio di codice non errato:\n```bash\ndocker run -p 4891:4891 my-image\n```\nNota: il numero di porta nella parte destra del `-p` è la porta ascoltata dal container."}
{"timestamp": "2025-10-07T16:29:51.563936", "container": "proxy", "language": "generic", "error": "2025/09/25 23:21:09 [error] 25#25: *155 connect() failed (111: Connection refused) while connecting to upstream, client: 172.17.0.1, server: localhost, request: \"GET /rea HTTP/1.1\", upstream: \"http://172.17.0.1:8000/\", host: \"peschiera3.ddns.net\", referrer: \"https://peschiera3.ddns.net/api\"", "solution": "Il bug è che il server non sta ascoltando su tutti i porti (specificamente, il porto 80 per HTTP). Il problema è che la richiesta viene inviata al porto 443 (HTTPS) anziché al porto 80.\n\n**Soluzione:** assicurarsi di ascoltare su tutti i porti, ad esempio utilizzando `listen 0.0.0.0:80` in lugar di `listen 0.0.0.0:443`.\n\nEsempio di codice (Apache HTTP Server):\n```bash\n<VirtualHost *:80>\n    ServerName peschiera3.ddns.net\n    DocumentRoot /var/www/peschiera3\n\n    <Directory /var/www/peschiera3>\n        Options Indexes FollowSymLinks MultiViews\n        Allow"}
{"timestamp": "2025-10-08T02:07:32.452803", "container": "couchdb1", "language": "generic", "error": "[error] 2025-09-26T00:34:02.116105Z couchdb@couchdb1 <0.467.0> -------- ** System running to use fully qualified hostnames **", "solution": "Il bug è che il sistema non sta utilizzando i nomi di host pieni (FQDN) per le connessioni.\n\n**Soluzione:** assicurarsi di utilizzare FQDN corretti nel file `/etc/hosts` e nella configurazione del database CouchDB.\n\nEsempio di codice (non errato):\n```javascript\n// Configurazione del database CouchDB con host completo\nvar db = require('coouchdb').db('https://couchdb1:5984');\n```\nNota che in questo esempio, `couchdb1` è il nome FQDN completo del server CouchDB."}
{"timestamp": "2025-10-08T02:07:34.417466", "container": "gitea", "language": "python", "error": "2025/09/28 11:32:41 routers/common/db.go:36:InitDBEngine() [E] ORM engine initialization attempt #1/10 failed. Error: pq: the database system is starting up", "solution": "Il bug è che il codice tenta di inizializzare l'ORM engine prima che il database sia stato effettivamente avviato.\n\n**Soluzione concisa:** Aggiungere un tempo di attesa prima dell'inizializzazione dell'ORM engine, ad esempio:\n\n```go\nfunc InitDBEngine() {\n    // Attendi fino a quando il database non è pronto\n    time.Sleep(2 * time.Second)\n    \n    // Inizializza l'ORM engine\n    // ...\n}\n```\n\nQuesto permette al codice di attendere che il database sia stato avviato prima di tentare di inizializzarlo."}
{"timestamp": "2025-10-08T02:07:35.054300", "container": "frontend", "language": "generic", "error": "2025/09/28 09:32:18 [error] 42#42: *1 connect() failed (111: Connection refused) while connecting to upstream, client: 172.21.0.1, server: 192.168.1.10, request: \"GET /api/agents HTTP/1.1\", upstream: \"http://172.21.0.3:8003/agents\", host: \"peschiera3.ddns.net\", referrer: \"https://peschiera3.ddns.net/dossier/\"", "solution": "Il bug è la presenza di un indirizzo IP non esistente (`172.21.0.1`) nel client, che non corrisponde all'indirizzo IP del server (`192.168.1.10`).\n\nSoluzione: assicurarsi che l'indirizzo IP del client sia corretto e corrisponda all'indirizzo IP del server.\n\nEsempio di codice (in PHP) per verificare l'esistenza dell'indirizzo IP:\n```php\n$ipClient = '172.21.0.1';\nif (!filter_var($ipClient, FILTER_VALIDATE_IP)) {\n    // gestione errore\n}\n```\nNota: in questo esempio, utilizziamo la funzione `filter_var` per verificare l'esistenza dell'indirizzo IP. Se il"}
{"timestamp": "2025-10-08T02:07:35.891080", "container": "dossier-backend", "language": "generic", "error": "\u001b[32m2025-09-27 03:12:45\u001b[0m | \u001b[31m\u001b[1mERROR   \u001b[0m | \u001b[31m\u001b[1m[FETCH] Errore fetch GNews: 'NoneType' object is not iterable\u001b[0m", "solution": "Il bug è che il codice non controlla se la variabile `GNews` è `None` prima di tentare di iterarla. Ciò può causare un errore.\n\nSoluzione:\n```python\nif GNews is not None:\n    for news in GNews:\n        # codice qui\nelse:\n    print(\"Errore: GNews non disponibile\")\n```\nIn questo esempio, si controlla se `GNews` è `None` e solo se no, si procede a iterare su di esso."}
{"timestamp": "2025-10-08T02:07:36.415084", "container": "gitea-db-1", "language": "generic", "error": "2025-09-28 09:32:41.137 UTC [28] FATAL:  the database system is starting up", "solution": "Il bug è che il messaggio di errore contiene informazioni sulla data e l'ora della richiesta, ma non sul codice di errore specifico.\n\n**Soluzione:** Utilizzare un logging più dettagliato per raccogliere le informazioni di errore in modo più preciso. Ad esempio:\n\n```java\nimport org.gitea.db.GiteaDB;\nimport org.gitea.db.exceptions.DatabaseException;\n\npublic class Main {\n    public static void main(String[] args) {\n        try {\n            GiteaDB db = new GiteaDB();\n            // codice di esecuzione\n        } catch (DatabaseException e) {\n            System.err.println(\"Errore database: \" + e.getMessage());\n            System.exit(1);\n        }\n    }\n}\n```\n\nIn questo modo, il messaggio di errore"}
{"timestamp": "2025-10-08T02:07:37.229063", "container": "privoxy-updater", "language": "python", "error": "Traceback (most recent call last):", "solution": "Il bug è probabilmente legato alla mancanza di una dipendenza necessaria per il modulo Privoxy-Updater. \n\nSoluzione: assicurarsi di installare tutte le dipendenze richieste, ad esempio `python3-setuptools` e `python3-wheel`, aggiungendo queste linee al file `setup.py`:\n\n```python\nfrom setuptools import setup\n\nsetup(\n    name='Privoxy-Updater',\n    version='1.0',\n    install_requires=['setuptools', 'wheel']\n)\n```\n\nNota: la soluzione potrebbe variare in base alle specifiche richieste del modulo Privoxy-Updater."}
{"timestamp": "2025-10-08T02:07:37.845870", "container": "privoxy-updater", "language": "python", "error": "  File \"/usr/local/lib/python3.11/site-packages/urllib3/connection.py\", line 198, in _new_conn", "solution": "Il bug è che il file `urllib3` sta cercando di connettersi a un server che non esiste più.\n\n**Soluzione concisa:**\n\nAggiornare la libreria `urllib3` con l'ultima versione disponibile per evitare questo problema. Ad esempio:\n\n```bash\npip install --upgrade urllib3\n```\n\nQuesto comando aggiorna la libreria `urllib3` a una versione più recente, che probabilmente include le correzioni necessarie per risolvere il problema di connessione al server non esistente."}
{"timestamp": "2025-10-08T02:07:38.429496", "container": "proxy", "language": "generic", "error": "2025/09/25 23:21:07 [error] 27#27: *134 connect() failed (111: Connection refused) while connecting to upstream, client: 172.17.0.1, server: localhost, request: \"GET /v1 HTTP/1.1\", upstream: \"http://172.17.0.1:1234/v1\", host: \"peschiera3.ddns.net\", referrer: \"https://peschiera3.ddns.net/api\"", "solution": "Il bug è che il server non sta ascoltando su port 1234.\n\n**Soluzione concisa:** Assicurarsi di avviare il servizio web o l'applicazione correttamente e di avere un file di configurazione con la porta corretta. Ad esempio, per Nginx:\n\n```nginx\nhttp {\n    ...\n    upstream peschiera3 {\n        server localhost:1234;\n    }\n    ...\n}\n```\n\nNota che in questo caso il server è localhost, quindi il problema potrebbe essere che il file di configurazione non è stato caricato correttamente o che il servizio web/applicazione non sta ascoltando su port 1234."}
{"timestamp": "2025-10-08T02:07:39.097719", "container": "proxy", "language": "generic", "error": "2025/09/25 23:21:07 [error] 27#27: *138 connect() failed (111: Connection refused) while connecting to upstream, client: 172.17.0.1, server: localhost, request: \"GET /v2 HTTP/1.1\", upstream: \"http://172.17.0.1:4891/\", host: \"peschiera3.ddns.net\", referrer: \"https://peschiera3.ddns.net/api\"", "solution": "Il bug è che il client tenta di connettersi a `localhost` (127.0.0.1) anziché `172.17.0.1`, che sembra essere l'indirizzo IP del server.\n\n**Soluzione:** assicurarsi che il client utilizzi l'indirizzo IP corretto del server.\n\nEsempio di codice:\n```nginx\nserver {\n    listen 80;\n    server_name peschiera3.ddns.net;\n\n    location /v2 {\n        proxy_pass http://172.17.0.1:4891/;\n        proxy_set_header Host $host;\n        proxy_set_header X-Real-IP $remote_addr;\n    }\n}\n```\nNota che in questo esempio, `server_name` è impostato su `peschiera3.ddns.net`, e la `"}
{"timestamp": "2025-10-08T02:07:39.911956", "container": "proxy", "language": "generic", "error": "2025/09/25 23:21:09 [error] 25#25: *155 connect() failed (111: Connection refused) while connecting to upstream, client: 172.17.0.1, server: localhost, request: \"GET /rea HTTP/1.1\", upstream: \"http://172.17.0.1:8000/\", host: \"peschiera3.ddns.net\", referrer: \"https://peschiera3.ddns.net/api\"", "solution": "Il bug è che il server non sta ascoltando su porto 8000.\n\nLa soluzione è di assicurarsi che il servizio che ascolta su quel porto sia in esecuzione e funzioni correttamente. Ad esempio, se si utilizza un container Docker per eseguire l'applicazione, assicurarsi che il container sia in esecuzione e che la porta 8000 sia aperta.\n\nEsempio di codice (non errato):\n```python\nimport http.server\n\nclass MyServer(http.server.BaseHTTPRequestHandler):\n    def do_GET(self):\n        self.send_response(200)\n        self.end_headers()\n        self.wfile.write(b\"Hello, World!\")\n\nserver_address = ('', 8000)\nhttpd = http.server.HTTPServer(server_address, MyServer)\nhttpd.serve"}
{"timestamp": "2025-10-08T02:07:40.739086", "container": "privoxy", "language": "python", "error": "2025-08-21 09:18:16.458 7c3e34d33b38 Error: write to client failed: Invalid argument", "solution": "Il bug è che il problema \"Invalid argument\" potrebbe essere causato da un'opzione di configurazione non corretta nel file di configurazione del Privoxy.\n\n**Soluzione:** Verifica la configurazione dell'opzione `maxConnections` e assicurati che sia impostata su un valore positivo. Ad esempio:\n\n```bash\nmaxConnections = 1000\n```\n\nIn questo modo, il Privoxy verrà in grado di gestire fino a 1000 connessioni contemporanee con i clienti."}
{"timestamp": "2025-10-08T02:07:45.262896", "container": "gitea", "language": "python", "error": "2025/09/28 11:32:41 routers/common/db.go:36:InitDBEngine() [E] ORM engine initialization attempt #1/10 failed. Error: pq: the database system is starting up", "solution": "Il bug è che il codice tenta di inizializzare la connessione al database prima che esso sia stato effettivamente avviato.\n\n**Soluzione concisa:**\n\nInizializza la connessione al database dopo aver avviato il database, utilizzando una funzione asincrona per attendere l'avvio del database.\n\nEsempio di codice corretto:\n```go\nfunc init() {\n    go func() {\n        // Attendere l'avvio del database\n        time.Sleep(500 * time.Millisecond)\n        \n        // Inizializzare la connessione al database\n        db.InitDBEngine()\n    }()\n}\n```\nNota: il codice originale non è fornito, quindi questo esempio è solo una proposta di soluzione generica."}
{"timestamp": "2025-10-08T02:07:46.191104", "container": "gitea-db-1", "language": "generic", "error": "2025-09-28 09:32:41.137 UTC [28] FATAL:  the database system is starting up", "solution": "Il bug è che il messaggio di errore non fornisce informazioni dettagliate sul problema specifico.\n\n**Soluzione:** Aggiungere ulteriori log per comprendere meglio l'errore, ad esempio:\n\n```bash\ngitea-db-1] 2025-09-28 09:32:41.137 UTC [28] FATAL: unable to connect to database, check the configuration file for errors\n```\n\nIn questo modo, il messaggio di errore diventa più utile per identificare e risolvere il problema."}
{"timestamp": "2025-10-08T02:07:46.755594", "container": "dossier-backend", "language": "generic", "error": "\u001b[32m2025-09-27 03:12:45\u001b[0m | \u001b[31m\u001b[1mERROR   \u001b[0m | \u001b[31m\u001b[1m[FETCH] Errore fetch GNews: 'NoneType' object is not iterable\u001b[0m", "solution": "Il bug è che il codice cerca di iterare su un oggetto None, ovvero un valore nullo. Questo può accadere se la chiave \"GNews\" non esiste nel dizionario o nella struttura dati utilizzata.\n\n**Soluzione concisa:**\nVerifica che la chiave \"GNews\" sia presente e non nula prima di cercare di iterarla.\n\nEsempio di codice corretto:\n```python\nimport json\n\n# supponiamo di avere un dizionario con una chiave 'GNews'\ndizionario = {'GNews': 'some_value'}\n\nif 'GNews' in dizionario and dizionario['GNews'] is not None:\n    # il codice può procedere senza problemi\n    pass\nelse:\n    print(\"Chiave 'GNews' non trov"}
{"timestamp": "2025-10-08T02:07:47.550867", "container": "frontend", "language": "generic", "error": "2025/09/28 09:32:18 [error] 42#42: *1 connect() failed (111: Connection refused) while connecting to upstream, client: 172.21.0.1, server: 192.168.1.10, request: \"GET /api/agents HTTP/1.1\", upstream: \"http://172.21.0.3:8003/agents\", host: \"peschiera3.ddns.net\", referrer: \"https://peschiera3.ddns.net/dossier/\"", "solution": "Il bug è che il server non sta ascoltando su l'indirizzo IP specificato (`172.21.0.1`) e invece utilizza `192.168.1.10` per accettare le richieste.\n\n**Soluzione:** assicurarsi che il server sia configurato correttamente a utilizzare l'indirizzo IP giusto. Ad esempio, aggiungere la riga di configurazione `listen 172.21.0.1:80;` al file di configurazione del server (ad esempio, `/etc/nginx/nginx.conf`) per ascoltare su l'indirizzo IP specificato.\n\n**Esempio di codice non errato:**\n```nginx\nserver {\n    listen 172.21.0.1:80;\n    server_name peschiera3"}
{"timestamp": "2025-10-08T02:07:48.366082", "container": "couchdb1", "language": "generic", "error": "[error] 2025-09-26T00:34:02.116105Z couchdb@couchdb1 <0.467.0> -------- ** System running to use fully qualified hostnames **", "solution": "Il bug è che il codice non specifica la versione di CouchDB che sta utilizzando.\n\n**Soluzione:** Specificare la versione di CouchDB utilizzata, ad esempio:\n\n```bash\ncouchdb --version\n```\n\nIn questo modo si può verificare se la versione installata è la corretta e se non ci sono problemi con l'esecuzione del servizio."}
{"timestamp": "2025-10-08T02:07:48.791472", "container": "privoxy-updater", "language": "python", "error": "Traceback (most recent call last):", "solution": "Il bug è che il codice non fornisce informazioni sufficienti per identificare l'errore. \n\nLa soluzione potrebbe essere aggiungere le linee di debug per raccolta di dettagli più precisi:\n```python\nimport logging\n\nlogging.basicConfig(level=logging.DEBUG)\n\ntry:\n    # codice che richiede aggiornamento\nexcept Exception as e:\n    logging.error(f\"Errore durante l'aggiornamento: {str(e)}\")\n```\nIn questo modo, il codice fornisce informazioni più dettagliate sull'errore."}
{"timestamp": "2025-10-08T02:07:49.343880", "container": "privoxy-updater", "language": "python", "error": "  File \"/usr/local/lib/python3.11/site-packages/urllib3/connection.py\", line 198, in _new_conn", "solution": "Il bug è che il file `/usr/local/lib/python3.11/site-packages/urllib3/connection.py` non esiste più.\n\n**Soluzione:**\n\nAggiornare le dipendenze del progetto `privoxy-updater` per utilizzare la versione più recente di urllib3. Ad esempio, aggiungere la seguente riga nel file `requirements.txt`:\n```bash\nurllib3==2.0.35\n```\nQuesto assicurerà che il progetto utilizza una versione stabile e sicura di urllib3."}
{"timestamp": "2025-10-08T02:07:49.900565", "container": "proxy", "language": "generic", "error": "2025/09/25 23:21:07 [error] 27#27: *134 connect() failed (111: Connection refused) while connecting to upstream, client: 172.17.0.1, server: localhost, request: \"GET /v1 HTTP/1.1\", upstream: \"http://172.17.0.1:1234/v1\", host: \"peschiera3.ddns.net\", referrer: \"https://peschiera3.ddns.net/api\"", "solution": "Il bug è che il client (in questo caso, un'applicazione web) sta tentando di connettersi al server localhost tramite una porta specifica (1234), ma il server non sta ascoltando su quella porta.\n\n**Soluzione:** assicurarsi che il servizio che gestisce la porta 1234 sia in esecuzione e stia ascoltando sulla porta corretta.\n\nEsempio di codice per verificare se un servizio è in esecuzione:\n```bash\nsystemctl status <servizio>\n```\nIn questo caso, il comando dovrebbe restituire \"active (running)\" se il servizio è in esecuzione."}
{"timestamp": "2025-10-08T02:07:50.571077", "container": "proxy", "language": "generic", "error": "2025/09/25 23:21:07 [error] 27#27: *138 connect() failed (111: Connection refused) while connecting to upstream, client: 172.17.0.1, server: localhost, request: \"GET /v2 HTTP/1.1\", upstream: \"http://172.17.0.1:4891/\", host: \"peschiera3.ddns.net\", referrer: \"https://peschiera3.ddns.net/api\"", "solution": "Il bug è che il server non sta ascoltando su port 4891, ma il client cerca di connettersi a quel porto.\n\n**Soluzione:** assicurarsi che il servizio ascolti su un porto corretto e configurato correttamente. Ad esempio:\n\n```bash\n# Configura Nginx per ascoltare su port 80\nserver {\n    listen 80;\n    server_name peschiera3.ddns.net;\n\n    location /v2 {\n        proxy_pass http://172.17.0.1:4891/;\n        proxy_set_header Host $host;\n        proxy_set_header X-Real-IP $remote_addr;\n    }\n}\n```\n\nNota che in questo esempio, il servizio ascolta su port 80 e proxya le richieste a `http"}
{"timestamp": "2025-10-08T02:07:51.377163", "container": "proxy", "language": "generic", "error": "2025/09/25 23:21:09 [error] 25#25: *155 connect() failed (111: Connection refused) while connecting to upstream, client: 172.17.0.1, server: localhost, request: \"GET /rea HTTP/1.1\", upstream: \"http://172.17.0.1:8000/\", host: \"peschiera3.ddns.net\", referrer: \"https://peschiera3.ddns.net/api\"", "solution": "Il bug è che il server non sta ascoltando su l'indirizzo IP 172.17.0.1, ma piuttosto su `localhost`.\n\n**Soluzione:** Assicurarsi di utilizzare l'indirizzo IP corretto nel file di configurazione del servizio Nginx.\n\nEsempio di codice (non errato):\n```nginx\nhttp {\n    server {\n        listen 80;\n        server_name peschiera3.ddns.net;\n\n        location /rea {\n            proxy_pass http://172.17.0.1:8000/;\n            proxy_http_version 1.1;\n            proxy_set_header Upgrade $http_upgrade;\n            proxy_set_header Connection 'upgrade';\n            proxy_set_header Host $host;\n            proxy_cache_bypass $http_upgrade;\n        }\n    }\n}\n```"}
{"timestamp": "2025-10-08T02:07:52.165238", "container": "privoxy", "language": "python", "error": "2025-08-21 09:18:16.458 7c3e34d33b38 Error: write to client failed: Invalid argument", "solution": "Il bug è che il problema \"Invalid argument\" potrebbe essere causato da un'errata configurazione del protocollo HTTP o della connessione con il server.\n\n**Soluzione concisa:**\nVerifica la configurazione del protocollo HTTP e della connessione, assicurandoti che le impostazioni siano corrette e coerenti con le richieste di rete."}
{"timestamp": "2025-10-08T02:08:13.492543", "container": "gitea-db-1", "language": "generic", "error": "2025-09-28 09:32:41.137 UTC [28] FATAL:  the database system is starting up", "solution": "Il bug è che il messaggio di errore indica che il sistema di database sta iniziando, ma non fornisce informazioni specifiche sul problema.\n\nSoluzione: aggiungere log di debug per raccogliere informazioni più dettagliate sul problema. Ad esempio:\n\n```sql\n-- Aggiungi questo comando al file di configurazione del database\nSET GLOBAL log_error_format = '%t %p %u %q %m %e';\n```\n\nQuesto comando consente di visualizzare i dettagli del messaggio di errore, come l'ora, il livello di accesso, l'ID utente e la query che ha causato l'errore."}
{"timestamp": "2025-10-08T02:08:14.348733", "container": "frontend", "language": "generic", "error": "2025/09/28 09:32:18 [error] 42#42: *1 connect() failed (111: Connection refused) while connecting to upstream, client: 172.21.0.1, server: 192.168.1.10, request: \"GET /api/agents HTTP/1.1\", upstream: \"http://172.21.0.3:8003/agents\", host: \"peschiera3.ddns.net\", referrer: \"https://peschiera3.ddns.net/dossier/\"", "solution": "Il bug è che il server non sta ascoltando sulla porta 8003.\n\nSoluzione:\n- Verifica che il servizio di Apache o Nginx che esegue l'applicazione sia stato avviato correttamente e stia ascoltando sulla porta 8003.\n- Se necessario, aggiorna la configurazione del file di configurazione (ad esempio `httpd.conf` o `nginx.conf`) per specificare la porta 8003 come porta di ascolto.\n\nEsempio di codice non errato:\n```bash\n# Apache\n<VirtualHost *:80>\n    ServerName peschiera3.ddns.net\n    DocumentRoot /var/www/html\n\n    # Configura la porta 8003 per l'ascolto\n    ProxyPass /agents http://localhost:8003/"}
{"timestamp": "2025-10-08T02:08:15.165002", "container": "privoxy-updater", "language": "python", "error": "Traceback (most recent call last):", "solution": "Il bug è che il codice non fornisce informazioni sufficienti per identificare l'errore. \n\nSoluzione: aggiungere le linee di debug per raccogliere più informazioni sul problema.\n\nEsempio di codice corretto:\n```python\nimport logging\n\nlogging.basicConfig(level=logging.DEBUG)\n\ntry:\n    # codice da eseguire\nexcept Exception as e:\n    logging.error(f\"Errore: {str(e)}\")\n```\nIn questo modo, il codice fornisce informazioni più dettagliate sull'errore."}
{"timestamp": "2025-10-08T02:08:15.713866", "container": "privoxy-updater", "language": "python", "error": "  File \"/usr/local/lib/python3.11/site-packages/urllib3/connection.py\", line 198, in _new_conn", "solution": "Il bug sembra essere legato alla gestione delle connessioni HTTP. La soluzione potrebbe essere:\n\n*   Verificare che il pacchetto `urllib3` sia aggiornato a una versione recente.\n\nEcco un esempio di codice Python non errato per verificare la versione del pacchetto:\n```python\nimport urllib3\n\nversione = urllib3.__version__\nprint(f\"La versione del pacchetto urllib3 è: {versione}\")\n```\nQuesto codice verifica la versione del pacchetto `urllib3` e la stampa sullo schermo."}
{"timestamp": "2025-10-08T02:08:16.307726", "container": "gitea", "language": "python", "error": "2025/09/28 11:32:41 routers/common/db.go:36:InitDBEngine() [E] ORM engine initialization attempt #1/10 failed. Error: pq: the database system is starting up", "solution": "Il bug è che il codice non attende la fine dell'operazione di inizializzazione del database prima di tentare di utilizzarlo.\n\n**Soluzione concisa:**\n\nAggiungere un `select` su una query vuota per attendere la fine dell'operazione di inizializzazione:\n\n```go\nfunc InitDBEngine() {\n    // ...\n    defer func() {\n        _ = db.Ping()\n    }()\n    // ...\n}\n```\n\nIn questo modo, il codice attende che il database sia pronto prima di tentare di utilizzarlo."}
{"timestamp": "2025-10-08T02:08:16.867652", "container": "couchdb1", "language": "generic", "error": "[error] 2025-09-26T00:34:02.116105Z couchdb@couchdb1 <0.467.0> -------- ** System running to use fully qualified hostnames **", "solution": "Il bug è che il server CouchDB richiede un fully qualified hostname (FQDN) per funzionare correttamente.\n\n**Soluzione:** assicurarsi di utilizzare un FQDN valido nel file di configurazione del server CouchDB. Ad esempio:\n\n```bash\n# /etc/couchdb/couch.db\n{\n    \"couchdb\": {\n        \"host\": \"couchdb1.example.com\",\n        \"port\": 5984,\n        \"httpd_port\": 5985,\n        \"bind_address\": \"0.0.0.0\"\n    }\n}\n```\n\nIn questo esempio, `couchdb1.example.com` è un FQDN valido che il server CouchDB può utilizzare per identificarsi correttamente."}
{"timestamp": "2025-10-08T02:08:17.599313", "container": "dossier-backend", "language": "generic", "error": "\u001b[32m2025-09-27 03:12:45\u001b[0m | \u001b[31m\u001b[1mERROR   \u001b[0m | \u001b[31m\u001b[1m[FETCH] Errore fetch GNews: 'NoneType' object is not iterable\u001b[0m", "solution": "Il bug è che il codice cerca di iterare su un oggetto None, ovvero un valore non presente.\n\n**Soluzione concisa:** Verifica che la variabile `GNews` sia stata correttamente inizializzata prima dell'iterazione. Ad esempio:\n\n```python\n# Inizializzazione errata\nGNews = None\n\n# Iterazione su un oggetto None\nfor news in GNews:\n    print(news)\n```\n\n**Soluzione corretta:**\n```python\n# Inizializzazione corretta\nGNews = ['Articolo 1', 'Articolo 2', 'Articolo 3']\n\n# Iterazione su un oggetto presente\nfor news in GNews:\n    print(news)\n```\n\nIn questo esempio, la variabile `GNews` è stata cor"}
{"timestamp": "2025-10-08T02:08:18.409120", "container": "proxy", "language": "generic", "error": "2025/09/25 23:21:07 [error] 27#27: *134 connect() failed (111: Connection refused) while connecting to upstream, client: 172.17.0.1, server: localhost, request: \"GET /v1 HTTP/1.1\", upstream: \"http://172.17.0.1:1234/v1\", host: \"peschiera3.ddns.net\", referrer: \"https://peschiera3.ddns.net/api\"", "solution": "Il bug è che il server non sta ascoltando sul porto 1234.\n\nSoluzione:\n- Assicurarsi di avere un servizio o un'applicazione eseguibile sul porto 1234, ad esempio:\n\n```bash\npython -m http.server 1234\n```\n\nNota: il comando `http.server` è solo un esempio e potrebbe non essere adatto per tutti i casi."}
{"timestamp": "2025-10-08T02:08:18.842769", "container": "proxy", "language": "generic", "error": "2025/09/25 23:21:07 [error] 27#27: *138 connect() failed (111: Connection refused) while connecting to upstream, client: 172.17.0.1, server: localhost, request: \"GET /v2 HTTP/1.1\", upstream: \"http://172.17.0.1:4891/\", host: \"peschiera3.ddns.net\", referrer: \"https://peschiera3.ddns.net/api\"", "solution": "Il bug è che il server non sta ascoltando su port 4891.\n\nSoluzione:\n* Assicurarsi che il servizio di proxy stia eseguendo correttamente e che sia configurato per ascoltare su quel porto. Ad esempio, utilizzare un file di configurazione Apache come questo:\n\n```bash\n<VirtualHost *:80>\n    ServerName peschiera3.ddns.net\n\n    ProxyPass /v2 http://172.17.0.1:4891/\n    ProxyPassReverse /v2 http://172.17.0.1:4891/\n\n    ErrorLog ${APACHE_LOG_DIR}/error.log\n    CustomLog ${APACHE_LOG_DIR}/access.log combined\n</VirtualHost>\n```\n\nNota che questo è solo un esempio e potrebbe richiedere ul"}
{"timestamp": "2025-10-08T02:08:19.645663", "container": "proxy", "language": "generic", "error": "2025/09/25 23:21:09 [error] 25#25: *155 connect() failed (111: Connection refused) while connecting to upstream, client: 172.17.0.1, server: localhost, request: \"GET /rea HTTP/1.1\", upstream: \"http://172.17.0.1:8000/\", host: \"peschiera3.ddns.net\", referrer: \"https://peschiera3.ddns.net/api\"", "solution": "Il bug è che il server non sta ascoltando sulla porta 8000.\n\n**Soluzione concisa:** assicurarsi di avviare correttamente l'applicazione sul server e di configurare correttamente la porta di ascolto. Ad esempio, nel file `app.py`:\n\n```python\nimport http.server\n\nclass MyHandler(http.server.BaseHTTPRequestHandler):\n    def do_GET(self):\n        self.send_response(200)\n        self.end_headers()\n        self.wfile.write(b\"Hello World!\")\n\nserver = http.server.HTTPServer((\"localhost\", 8000), MyHandler)\nserver.serve_forever()\n```\n\nIn questo esempio, l'applicazione ascolta sulla porta 8000 e risponde con \"Hello World!\" a ogni richiesta GET."}
{"timestamp": "2025-10-08T02:08:20.401705", "container": "privoxy", "language": "python", "error": "2025-08-21 09:18:16.458 7c3e34d33b38 Error: write to client failed: Invalid argument", "solution": "Il bug è probabilmente legato alla gestione delle connessioni TCP. Il problema potrebbe essere che il server non ha trovato la chiave di autorizzazione corretta per accedere al contenuto richiesto.\n\n**Soluzione concisa:** Verifica che la chiave di autorizzazione sia stata impostata correttamente e che la configurazione del proxy Privoxy sia aggiornata per utilizzare la chiave corretta. \n\nEsempio di codice (non errato):\n```c\n// configura la chiave di autorizzazione\nconst char* authKey = \"your_auth_key_here\";\n```\nNota: Sostituisci `\"your_auth_key_here\"` con la tua chiave di autorizzazione reale."}
{"timestamp": "2025-10-08T02:32:13.331574", "container": "couchdb1", "language": "generic", "error": "[error] 2025-09-26T00:34:02.116105Z couchdb@couchdb1 <0.467.0> -------- ** System running to use fully qualified hostnames **", "solution": "Il bug è che il server CouchDB non sta utilizzando i nomi completi dei host in modo corretto.\n\n**Soluzione:** assicurarsi di configurare correttamente le proprietà `host` e `port` nel file di configurazione del server CouchDB. Ad esempio:\n\n```javascript\n{\n  \"include_docs\": true,\n  \" hosts\": [\"couchdb1:5985\"],\n  \"httpd\": {\n    \"bind_address\": \"127.0.0.1\"\n  }\n}\n```\n\nIn questo esempio, il server CouchDB ascolta su `localhost` e utilizza il nome completo del host (`couchdb1`) con il port `5985`."}
{"timestamp": "2025-10-08T02:32:15.350827", "container": "gitea", "language": "python", "error": "2025/09/28 11:32:41 routers/common/db.go:36:InitDBEngine() [E] ORM engine initialization attempt #1/10 failed. Error: pq: the database system is starting up", "solution": "Il bug è che il codice non attende la fine dell'avvio del database prima di tentare l'initializzazione dell'ORM engine.\n\n**Soluzione concisa:** Aggiungere un tempo di attesa prima di riconvertire all'errore, ad esempio:\n\n```go\nfunc InitDBEngine() {\n    // ...\n    defer func() {\n        if err := recover(); err != nil {\n            log.Printf(\"ORM engine initialization attempt failed: %v\", err)\n            return\n        }\n    }()\n    // ...\n}\n```\n\nIn questo modo, il codice attende che l'errore sia stato recuperato e poi riconverte all'errore se non è stato possibile."}
{"timestamp": "2025-10-08T02:32:16.036603", "container": "proxy", "language": "generic", "error": "2025/09/25 23:21:07 [error] 27#27: *134 connect() failed (111: Connection refused) while connecting to upstream, client: 172.17.0.1, server: localhost, request: \"GET /v1 HTTP/1.1\", upstream: \"http://172.17.0.1:1234/v1\", host: \"peschiera3.ddns.net\", referrer: \"https://peschiera3.ddns.net/api\"", "solution": "Il bug è che il client (in questo caso, un'applicazione di backend) stà tentando di connettersi al server localhost su porta 1234, ma il server non è ascoltante su questa porta.\n\n**Soluzione**: assicurarsi che il server sia configurato per ascoltare su la porta corretta. Ad esempio:\n\n```bash\n# Configura il server a ascoltare su porta 1234\nserver {\n    listen 1234;\n    # altre configurazioni...\n}\n```\n\nIn questo modo, quando il client tenta di connettersi al server localhost su porta 1234, il server sarà in grado di accoglierlo."}
{"timestamp": "2025-10-08T02:32:16.717067", "container": "proxy", "language": "generic", "error": "2025/09/25 23:21:07 [error] 27#27: *138 connect() failed (111: Connection refused) while connecting to upstream, client: 172.17.0.1, server: localhost, request: \"GET /v2 HTTP/1.1\", upstream: \"http://172.17.0.1:4891/\", host: \"peschiera3.ddns.net\", referrer: \"https://peschiera3.ddns.net/api\"", "solution": "Il bug è che il client tenta di connettersi al server localhost, ma il server non è disponibile a causa della porta 4891. La soluzione è quella di utilizzare la porta corretta per l'accesso al server.\n\nEsempio di codice:\n```bash\nhttp {\n    ...\n    upstream peschiera3 {\n        server localhost:8080; # utilizza la porta 8080 anziché 4891\n    }\n    ...\n}\n```\nNota che in questo esempio, la porta 8080 è solo un esempio e dovrebbe essere sostituita con la porta corretta per l'accesso al server."}
{"timestamp": "2025-10-08T02:32:17.398462", "container": "proxy", "language": "generic", "error": "2025/09/25 23:21:09 [error] 25#25: *155 connect() failed (111: Connection refused) while connecting to upstream, client: 172.17.0.1, server: localhost, request: \"GET /rea HTTP/1.1\", upstream: \"http://172.17.0.1:8000/\", host: \"peschiera3.ddns.net\", referrer: \"https://peschiera3.ddns.net/api\"", "solution": "Il bug è che il server non sta ascoltando su port 80 (il porto predefinito per HTTP).\n\n**Soluzione concisa:** Assicurarsi di avviare il servizio web sul porto corretto. Ad esempio, se stai usando Nginx, assicurati che la riga `server { listen 8000; }` sia presente nel file di configurazione.\n\nEsempio di codice (non errato):\n```nginx\nserver {\n    listen 80;\n    server_name peschiera3.ddns.net;\n\n    location /rea {\n        proxy_pass http://172.17.0.1:8000/;\n        proxy_set_header Host $host;\n        proxy_set_header X-Real-IP $remote_addr;\n    }\n}\n```"}
{"timestamp": "2025-10-08T02:32:18.169469", "container": "dossier-backend", "language": "generic", "error": "\u001b[32m2025-09-27 03:12:45\u001b[0m | \u001b[31m\u001b[1mERROR   \u001b[0m | \u001b[31m\u001b[1m[FETCH] Errore fetch GNews: 'NoneType' object is not iterable\u001b[0m", "solution": "Il bug è che il codice sta cercando di iterare su un oggetto `None`, ovvero un valore nullo.\n\nLa soluzione è controllare se l'oggetto è nullo prima di cercare di iterarlo. Ad esempio:\n\n```python\ngnews = fetch_gnews()  # supponiamo che fetch_gnews ritorna None\nif gnews is not None:\n    for item in gnews:\n        # codice qui\nelse:\n    print(\"Errore: non siamo riusciti a caricare i dati\")\n```\n\nIn questo esempio, controlliamo se `gnews` è nullo utilizzando il metodo `is not`, e solo se è nullo eseguiamo il codice all'interno del blocco `if`."}
{"timestamp": "2025-10-08T02:32:18.916496", "container": "gitea-db-1", "language": "generic", "error": "2025-09-28 09:32:41.137 UTC [28] FATAL:  the database system is starting up", "solution": "Il bug è che il messaggio di errore non fornisce informazioni dettagliate sul problema specifico.\n\n**Soluzione:** Aggiungere le opzioni `-v` o `--verbose` al comando per aumentare la visibilità dei log e poter identificare meglio l'errore.\n\nEsempio di codice non errato:\n```bash\ngitea db -v --verbose\n```\nQuesto comando esegue il comando `gitea db` con opzioni `-v` e `--verbose`, che consentono di visualizzare i log dettagliati e identificare meglio l'errore."}
{"timestamp": "2025-10-08T02:32:19.570941", "container": "frontend", "language": "generic", "error": "2025/09/28 09:32:18 [error] 42#42: *1 connect() failed (111: Connection refused) while connecting to upstream, client: 172.21.0.1, server: 192.168.1.10, request: \"GET /api/agents HTTP/1.1\", upstream: \"http://172.21.0.3:8003/agents\", host: \"peschiera3.ddns.net\", referrer: \"https://peschiera3.ddns.net/dossier/\"", "solution": "Il bug è che il server non sta ascoltando sulla porta 8003.\n\n**Soluzione:** assicurarsi di avere un servizio Nginx o Apache configurato per ascoltare sulla porta corretta. Ad esempio, in Nginx:\n\n```nginx\nhttp {\n    ...\n    upstream agents {\n        server localhost:8003;\n    }\n    ...\n}\n```\n\nNota che il valore \"localhost\" potrebbe non essere quello giusto, dipende dal sistema operativo e dalla configurazione del servizio."}
{"timestamp": "2025-10-08T02:32:20.106443", "container": "privoxy-updater", "language": "python", "error": "Traceback (most recent call last):", "solution": "Il bug è probabilmente legato alla mancanza di una dipendenza necessaria. \n\nAd esempio, il codice seguente potrebbe essere un esempio di codice corretto:\n```python\nimport subprocess\nfrom packaging import version\n\ndef update_privoxy():\n    try:\n        # Check if Privoxy is installed and up-to-date\n        output = subprocess.check_output(['privoxy', '--version'])\n        print(output.decode('utf-8'))\n        \n        # Update Privoxy\n        subprocess.check_call(['apt-get', 'update'])\n        subprocess.check_call(['apt-get', 'install', '-y', 'privoxy'])\n    except subprocess.CalledProcessError as e:\n        print(f\"Errore durante l'aggiornamento di Privoxy: {e}\")\n\nif __name__ == \"__main__\":\n    update"}
{"timestamp": "2025-10-08T02:32:20.897427", "container": "privoxy-updater", "language": "python", "error": "  File \"/usr/local/lib/python3.11/site-packages/urllib3/connection.py\", line 198, in _new_conn", "solution": "Il bug sembra essere una connessione fallita con il server proxy. \n\nLa soluzione potrebbe essere aggiungere un timeout per la connessione, in modo da evitare che l'applicazione si blocchi:\n\n```python\nimport urllib3\n\n# Impostare un timeout di 5 secondi per le connessioni\nurllib3.disable_warnings(urllib3.exceptions.InsecureRequestWarning)\nhttp = urllib3.PoolManager(timeout=5)\n```\n\nNota: è importante notare che il codice originale non è stato fornito, quindi questa soluzione è solo una ipotesi."}
{"timestamp": "2025-10-08T02:32:21.468300", "container": "privoxy", "language": "python", "error": "2025-08-21 09:18:16.458 7c3e34d33b38 Error: write to client failed: Invalid argument", "solution": "Il bug è probabilmente legato alla gestione delle connessioni TCP. Il problema potrebbe essere causato da un'errata configurazione della porta di ascolto o dalla mancata gestione delle connessioni in modo corretto.\n\nSoluzione:\nUtilizzare una libreria come `libev` per gestire le connessioni TCP degnamente, che fornisce una maggiore sicurezza e stabilità rispetto alla gestione manuali.\n\nEsempio di codice (non errato):\n```c\n#include <ev.h>\n\nint main() {\n    evhttp *server;\n    struct evhttp_request *req;\n\n    // Inizializzazione del server HTTP\n    server = evhttp_new();\n    if (!server) {\n        return 1;\n    }\n\n    // Configurazione della porta di as"}
{"timestamp": "2025-10-08T02:33:03.714426", "container": "gitea-db-1", "language": "generic", "error": "2025-09-28 09:32:41.137 UTC [28] FATAL:  the database system is starting up", "solution": "Il bug è che il log non fornisce informazioni utili per risolvere il problema.\n\nLa soluzione potrebbe essere di aumentare la livello di dettaglio del log, ad esempio impostando `log_level = DEBUG` nel file di configurazione del database. Questo avrebbe lo scopo di fornire una visione più completa dell'errore.\n\nEsempio di codice (in Java):\n```java\nimport org.gitea.db.GiteaDB;\nimport org.gitea.db.config.Config;\n\npublic class Main {\n    public static void main(String[] args) {\n        Config config = new Config();\n        config.setLogLevel(\"DEBUG\");\n        GiteaDB db = new GiteaDB(config);\n        // ...\n    }\n}\n```\nNota: l'esempio di codice è solo un esemp"}
{"timestamp": "2025-10-08T02:33:04.698502", "container": "dossier-backend", "language": "generic", "error": "\u001b[32m2025-09-27 03:12:45\u001b[0m | \u001b[31m\u001b[1mERROR   \u001b[0m | \u001b[31m\u001b[1m[FETCH] Errore fetch GNews: 'NoneType' object is not iterable\u001b[0m", "solution": "Il bug è che il codice non controlla se la variabile `GNews` è stata caricata correttamente prima di cercarla.\n\n**Soluzione:** Aggiungere una verifica per assicurarsi che `GNews` sia non null prima di cercare di iterarla.\n\nEsempio di codice corretto:\n```python\nimport logging\n\n# ... (codice precedente)\n\nif GNews is not None:\n    for news in GNews:\n        # codice per elaborare la notizia\nelse:\n    logging.error(\"Errore: non è stato possibile caricare le notizie\")\n```\nNota che questo esempio è solo un esempio di come potrebbe essere corretto il codice, e potrebbero esserci altre soluzioni a seconda del contesto specifico"}
{"timestamp": "2025-10-08T02:33:05.490578", "container": "gitea", "language": "python", "error": "2025/09/28 11:32:41 routers/common/db.go:36:InitDBEngine() [E] ORM engine initialization attempt #1/10 failed. Error: pq: the database system is starting up", "solution": "Il bug è che il codice tenta di inizializzare l'engine DB prima che il sistema di database sia completamente avviato.\n\n**Soluzione:** Utilizzare un meccanismo di ritardo per attendere che il sistema di database sia pronto, ad esempio utilizzando `net/http.DefaultClient` per inviare una richiesta al server di database dopo un certo periodo di tempo.\n\nEsempio di codice corretto:\n```go\nimport (\n\t\"context\"\n\t\"fmt\"\n\t\"time\"\n\n\t\"github.com/jackc/gotea/v3/db\"\n)\n\nfunc InitDBEngine(ctx context.Context) error {\n\tdefer func() {\n\t\tif r := recover(); r != nil {\n\t\t\treturn fmt.Errorf(\"recovered from panic: %v\", r)\n\t\t}\n\t}()\n\n\t// attendere 1 secondo prima di provare"}
{"timestamp": "2025-10-08T02:33:06.287989", "container": "frontend", "language": "generic", "error": "2025/09/28 09:32:18 [error] 42#42: *1 connect() failed (111: Connection refused) while connecting to upstream, client: 172.21.0.1, server: 192.168.1.10, request: \"GET /api/agents HTTP/1.1\", upstream: \"http://172.21.0.3:8003/agents\", host: \"peschiera3.ddns.net\", referrer: \"https://peschiera3.ddns.net/dossier/\"", "solution": "Il bug è che il server non sta ascoltando su l'indirizzo IP specificato (`http://172.21.0.3:8003/agents`) in quanto il file di configurazione del servizio Nginx non contiene una riga per ascoltare su quel indirizzo.\n\n**Esempio di codice (Nginx) corretto:**\n```nginx\nserver {\n    listen 80;\n    server_name peschiera3.ddns.net;\n\n    location /api/agents {\n        proxy_pass http://172.21.0.3:8003/agents;\n        proxy_http_version 1.1;\n        proxy_set_header Upgrade $http_upgrade;\n        proxy_set_header Connection 'upgrade';\n        proxy_set_header Host $host;\n        proxy_cache_bypass $http_upgrade;\n    }\n}\n```\nNota che in"}
{"timestamp": "2025-10-08T02:33:07.113283", "container": "proxy", "language": "generic", "error": "2025/09/25 23:21:07 [error] 27#27: *134 connect() failed (111: Connection refused) while connecting to upstream, client: 172.17.0.1, server: localhost, request: \"GET /v1 HTTP/1.1\", upstream: \"http://172.17.0.1:1234/v1\", host: \"peschiera3.ddns.net\", referrer: \"https://peschiera3.ddns.net/api\"", "solution": "Il bug è che il server non sta ascoltando su l'indirizzo IP specificato (`172.17.0.1`) e invece utilizza l'indirizzo `localhost` (che in realtà non esiste se il server si avvia con un indirizzo IP diverso).\n\n**Soluzione**: assicurarsi che il server sia configurato per ascoltare su l'indirizzo IP corretto.\n\nEsempio di codice non errato:\n```bash\nnginx {\n    upstream peschiera3 {\n        server 172.17.0.1:1234;\n    }\n\n    server {\n        listen 80;\n        location /v1 {\n            proxy_pass http://peschiera3;\n            proxy_set_header Host $host;\n            proxy_set_header X-Real-IP $remote_addr;\n        }"}
{"timestamp": "2025-10-08T02:33:07.930498", "container": "proxy", "language": "generic", "error": "2025/09/25 23:21:07 [error] 27#27: *138 connect() failed (111: Connection refused) while connecting to upstream, client: 172.17.0.1, server: localhost, request: \"GET /v2 HTTP/1.1\", upstream: \"http://172.17.0.1:4891/\", host: \"peschiera3.ddns.net\", referrer: \"https://peschiera3.ddns.net/api\"", "solution": "Il bug è che il server non sta ascoltando su porta 4891.\n\n**Soluzione concisa:** assicurarsi di avviare il servizio web o l'applicazione corrispondente su quella porta. Ad esempio, se si utilizza Node.js e Express, assicurarsi di aver creato un server con `app.listen(4891);`."}
{"timestamp": "2025-10-08T02:33:08.307937", "container": "proxy", "language": "generic", "error": "2025/09/25 23:21:09 [error] 25#25: *155 connect() failed (111: Connection refused) while connecting to upstream, client: 172.17.0.1, server: localhost, request: \"GET /rea HTTP/1.1\", upstream: \"http://172.17.0.1:8000/\", host: \"peschiera3.ddns.net\", referrer: \"https://peschiera3.ddns.net/api\"", "solution": "Il bug è che il server non sta ascoltando su port 8000.\n\nLa soluzione è quella di assicurarsi che il servizio che ascolta su quel port sia stato avviato e stia correttamente ascoltando su quell'indirizzo. Ad esempio, se si utilizza Python con `http.server`, bisogna assicurarsi che il comando `python -m http.server 8000` sia stato eseguito correttamente.\n\nEsempio di codice non errato:\n```python\nimport http.server\n\ndef run_server():\n    with http.server.HTTPServer(('localhost', 8000), http.server.SimpleHTTPRequestHandler) as server:\n        print(\"Servizio in esecuzione su localhost:8000\")\n        server.serve_forever()\n\nrun_server()\n```\nNota che questo"}
{"timestamp": "2025-10-08T02:33:09.140613", "container": "couchdb1", "language": "generic", "error": "[error] 2025-09-26T00:34:02.116105Z couchdb@couchdb1 <0.467.0> -------- ** System running to use fully qualified hostnames **", "solution": "Il bug è che il comando CouchDB richiede un nome di utente e una password per accedere al database, ma in questo caso non sono forniti.\n\n**Soluzione:** Aggiungere le credenziali di accesso al comando CouchDB, ad esempio:\n\n```bash\ncouchdb -u \"username\":password -d database_name\n```\n\nIn questo modo, il comando verrà eseguito con le credenziali specificate."}
{"timestamp": "2025-10-08T02:33:09.583446", "container": "privoxy-updater", "language": "python", "error": "Traceback (most recent call last):", "solution": "Il bug è probabilmente legato alla mancanza di una dipendenza necessaria per il modulo Privoxy-Updater. \n\nSoluzione: aggiungere la dipendenza `setuptools` e `wheel` al file `setup.py`.\n\nEsempio di codice corretto:\n```python\nfrom setuptools import setup, find_packages\n\nsetup(\n    name='privoxy-updater',\n    packages=find_packages(),\n    install_requires=['setuptools', 'wheel']\n)\n```\nNota: il codice completo del file `setup.py` dovrebbe essere consultato per una soluzione completa."}
{"timestamp": "2025-10-08T02:33:10.137463", "container": "privoxy-updater", "language": "python", "error": "  File \"/usr/local/lib/python3.11/site-packages/urllib3/connection.py\", line 198, in _new_conn", "solution": "Il bug è che il file `urllib3` sta cercando una connessione con un'URL non valida.\n\n**Soluzione:**\n\nVerifica che l'URL utilizzato nel codice sia corretto e punta al server desiderato. Ad esempio, se si cerca aggiornare Privoxy, assicurati di utilizzare l'URL del repository Git corretto:\n```python\nimport requests\n\nurl = \"https://github.com/Privoxy/Privoxy-Updater.git\"\n```\nAssicurati che `requests` sia installato e configurato correttamente."}
{"timestamp": "2025-10-08T02:33:10.726583", "container": "privoxy", "language": "python", "error": "2025-08-21 09:18:16.458 7c3e34d33b38 Error: write to client failed: Invalid argument", "solution": "Il bug è che il problema \"Invalid argument\" potrebbe essere causato da un'opzione o un parametro non configurati correttamente.\n\n**Soluzione concisa:** Verifica se l'opzione o il parametro richiesto è stato impostato correttamente nella configurazione del privoxy, ad esempio:\n\n```c\n# Configurazione di privoxy per evitare la connessione a un server specifico\nset max-connections 10\nset disable-hosts \"192.168.1.100\"\n```\n\nIn questo esempio, il problema potrebbe essere risolto impostando correttamente l'opzione `disable-hosts` con il valore del host che non deve essere raggiunto."}
{"timestamp": "2025-10-08T02:35:37.524656", "container": "gitea-db-1", "language": "generic", "error": "2025-09-28 09:32:41.137 UTC [28] FATAL:  the database system is starting up", "solution": "Il bug potrebbe essere legato alla mancata configurazione corretta del file di configurazione per la base di dati PostgreSQL, che è utilizzata da Gitea.\n\n**Soluzione proposta:** assicurarsi di aver impostato il file `gitea.ini` con le seguenti righe:\n\n```ini\n[database]\nhost = localhost\nport = 5432\nuser = username\npassword = password\nname = nome_database\n```\n\nIn questo esempio, sostituire \"localhost\", \"username\", \"password\" e \"nome_database\" con i valori corretti per la tua base di dati PostgreSQL."}
{"timestamp": "2025-10-08T02:35:38.331607", "container": "frontend", "language": "generic", "error": "2025/09/28 09:32:18 [error] 42#42: *1 connect() failed (111: Connection refused) while connecting to upstream, client: 172.21.0.1, server: 192.168.1.10, request: \"GET /api/agents HTTP/1.1\", upstream: \"http://172.21.0.3:8003/agents\", host: \"peschiera3.ddns.net\", referrer: \"https://peschiera3.ddns.net/dossier/\"", "solution": "Il bug è che il server non sta ascoltando sulla porta 8003.\n\nSoluzione concisa:\nVerifica che il servizio Nginx o l'applicazione che utilizza la porta 8003 sia in esecuzione e stia ascoltando correttamente."}
{"timestamp": "2025-10-08T02:35:38.631108", "container": "gitea", "language": "python", "error": "2025/09/28 11:32:41 routers/common/db.go:36:InitDBEngine() [E] ORM engine initialization attempt #1/10 failed. Error: pq: the database system is starting up", "solution": "Il bug è che il codice non attende che la base di dati sia completamente avviata prima di iniziare l'initializzazione dell'ORM engine.\n\n**Soluzione concisa:** Utilizzare un meccanismo di ritardo o una funzione di attesa per garantire che la base di dati sia pronta prima di procedere con l'initializzazione. Ad esempio:\n\n```go\nfunc InitDBEngine() {\n    // Attendi 2 secondi per permettere al database di iniziare\n    time.Sleep(2 * time.Second)\n    \n    // Procedi con l'initializzazione dell'ORM engine\n}\n```\n\nNota: la soluzione proposta è solo un esempio e potrebbe richiedere adattamenti in base alle specifiche esigenze del progetto."}
{"timestamp": "2025-10-08T02:35:39.393697", "container": "couchdb1", "language": "generic", "error": "[error] 2025-09-26T00:34:02.116105Z couchdb@couchdb1 <0.467.0> -------- ** System running to use fully qualified hostnames **", "solution": "Il bug è che il sistema non utilizza i nomi completi dei host (FQDN) per le connessioni.\n\n**Soluzione:** Configurare la proprietà `hosts` nel file di configurazione del CouchDB, ad esempio:\n\n```bash\n[local]\nhosts = \"localhost:5985\"\n```\n\nIn questo modo, il sistema utilizzerà il nome completo del host (`localhost`) per le connessioni."}
{"timestamp": "2025-10-08T02:35:39.814218", "container": "dossier-backend", "language": "generic", "error": "\u001b[32m2025-09-27 03:12:45\u001b[0m | \u001b[31m\u001b[1mERROR   \u001b[0m | \u001b[31m\u001b[1m[FETCH] Errore fetch GNews: 'NoneType' object is not iterable\u001b[0m", "solution": "Il bug è che il codice cerca di iterare su un oggetto None, ovvero un valore nullo. Questo potrebbe accadere se la query di fetch non ritorna alcun risultato.\n\nSoluzione:\nVerifica che la query di fetch sia corretta e che non ritorni sempre None. Ad esempio:\n\n```python\n# Codice errato\ngnews = GNews.query.filter_by(id=1).first()\nif gnews is not None:\n    # Processa i dati\nelse:\n    print(\"Non si è trovata alcuna notizia\")\n```\n\nIn questo esempio, il codice controlla se `gnews` non è None prima di cercare di iterarlo. Se `gnews` è None, il codice stampa un messaggio di errore; altrimenti, proced"}
{"timestamp": "2025-10-08T02:35:40.621228", "container": "proxy", "language": "generic", "error": "2025/09/25 23:21:07 [error] 27#27: *134 connect() failed (111: Connection refused) while connecting to upstream, client: 172.17.0.1, server: localhost, request: \"GET /v1 HTTP/1.1\", upstream: \"http://172.17.0.1:1234/v1\", host: \"peschiera3.ddns.net\", referrer: \"https://peschiera3.ddns.net/api\"", "solution": "Il bug è che il server non sta ascoltando su porta 1234.\n\n**Soluzione concisa:** Assicurarsi di avviare correttamente l'applicazione o servizio che si suppone sia esposto sulla porta 1234. Ad esempio, se si utilizza un container Docker, assicurarsi di averlo avviato correttamente:\n\n```bash\ndocker run -p 1234:1234 <immagine dell'app>\n```\n\nNota: il codice non è necessario per risolvere il problema, ma è stato incluso come esempio."}
{"timestamp": "2025-10-08T02:35:41.212389", "container": "proxy", "language": "generic", "error": "2025/09/25 23:21:07 [error] 27#27: *138 connect() failed (111: Connection refused) while connecting to upstream, client: 172.17.0.1, server: localhost, request: \"GET /v2 HTTP/1.1\", upstream: \"http://172.17.0.1:4891/\", host: \"peschiera3.ddns.net\", referrer: \"https://peschiera3.ddns.net/api\"", "solution": "Il bug è che il server non sta ascoltando su port 4891.\n\n**Soluzione concisa:** assicurarsi di avviare correttamente l'applicazione o servizio ascoltante su quel porto. Ad esempio, nel caso di un'app Node.js:\n\n```javascript\nconst http = require('http');\n\nconst server = http.createServer((req, res) => {\n  // gestione richieste e risposte\n});\n\nserver.listen(4891, () => {\n  console.log('Servizio ascoltante avviato su port 4891');\n});\n```\n\nNota che la soluzione dipende dal contesto specifico in cui si trova l'applicazione."}
{"timestamp": "2025-10-08T02:35:41.902951", "container": "proxy", "language": "generic", "error": "2025/09/25 23:21:09 [error] 25#25: *155 connect() failed (111: Connection refused) while connecting to upstream, client: 172.17.0.1, server: localhost, request: \"GET /rea HTTP/1.1\", upstream: \"http://172.17.0.1:8000/\", host: \"peschiera3.ddns.net\", referrer: \"https://peschiera3.ddns.net/api\"", "solution": "Il bug è che il server non sta ascoltando su port 8000.\n\n**Soluzione concisa:** Assicurarsi di eseguire l'applicazione con l'opzione `-p` per specificare il port di ascolto, ad esempio:\n```bash\npython app.py -p 8000\n```\nIn questo modo, il server ascolterà su port 8000 e non si verificherà un errore di connessione."}
{"timestamp": "2025-10-08T02:35:42.402030", "container": "privoxy-updater", "language": "python", "error": "Traceback (most recent call last):", "solution": "Il bug sembra essere una eccezione non gestita. La soluzione potrebbe essere aggiungere un try-except per gestire l'eccezione.\n\nEsempio di codice corretto:\n```python\ntry:\n    # codice eseguibile\nexcept Exception as e:\n    print(f\"Eccezione rilevata: {e}\")\n```\nIn questo modo, il programma non si fermerà in caso di eccezione ma continuerà a eseguire il codice dopo aver gestito l'errore."}
{"timestamp": "2025-10-08T02:35:42.925166", "container": "privoxy-updater", "language": "python", "error": "  File \"/usr/local/lib/python3.11/site-packages/urllib3/connection.py\", line 198, in _new_conn", "solution": "Il bug è che il file `urllib3.connection.py` non esiste nel pacchetto `privoxy-updater`. Questo file sembra essere stato sostituito da un altro file con lo stesso nome.\n\nLa soluzione potrebbe essere quella di controllare la versione del pacchetto `urllib3` e aggiornarla a una versione più recente, che potrebbe correggere il problema. Ad esempio:\n\n```bash\nsudo apt-get update && sudo apt-get install -y python3-urllib3\n```\n\nNota: l'esempio di codice non errato non è necessario in questo caso poiché si tratta di un problema con la versione del pacchetto."}
{"timestamp": "2025-10-08T02:35:43.622992", "container": "privoxy", "language": "python", "error": "2025-08-21 09:18:16.458 7c3e34d33b38 Error: write to client failed: Invalid argument", "solution": "Il bug è che il problema \"Invalid argument\" potrebbe essere causato da un'opzione di configurazione errata.\n\n**Soluzione:** Verifica le opzioni di configurazione del Privoxy e assicurati che l'opzione `max-connections` sia impostata su un valore positivo. Ad esempio:\n\n```bash\nmax-connections = 1000\n```\n\nQuesto aumenterà il numero massimo di connessioni che può gestire il Privoxy, evitando così l'errore \"Invalid argument\"."}
{"timestamp": "2025-10-08T02:49:17.957471", "container": "gitea", "language": "python", "error": "2025/09/28 11:32:41 routers/common/db.go:36:InitDBEngine() [E] ORM engine initialization attempt #1/10 failed. Error: pq: the database system is starting up", "solution": "Il bug è che il codice tenta di inizializzare l'engine DB prima che il sistema di database sia pronto.\n\nSoluzione:\nUtilizza un meccanismo di ritardo per attendere che il sistema di database sia pronto prima di iniziare l'inizializzazione dell'engine DB. Ad esempio, si può utilizzare la funzione `time.Sleep()` con un tempo di attesa sufficiente per permettere al sistema di database di avviarsi.\n\nEsempio di codice corretto:\n```go\nfunc InitDBEngine() {\n    time.Sleep(2 * time.Second) // attendere 2 secondi prima di iniziare l'inizializzazione dell'engine DB\n    // code che inizia l'inizializzazione dell'engine DB\n}\n```\nNota: il valore di `time.Second"}
{"timestamp": "2025-10-08T02:49:20.116033", "container": "proxy", "language": "generic", "error": "2025/09/25 23:21:07 [error] 27#27: *134 connect() failed (111: Connection refused) while connecting to upstream, client: 172.17.0.1, server: localhost, request: \"GET /v1 HTTP/1.1\", upstream: \"http://172.17.0.1:1234/v1\", host: \"peschiera3.ddns.net\", referrer: \"https://peschiera3.ddns.net/api\"", "solution": "Il bug è che il server non sta ascoltando sulla porta 1234.\n\n**Soluzione concisa:** Assicurarsi di aver avviato correttamente l'applicazione o il servizio che utilizza la porta 1234. Ad esempio, se si tratta di un'app Node.js, assicurarsi di aver utilizzato `app.listen(1234)`.\n\n**Esempio di codice non errato:**\n```javascript\nconst express = require('express');\nconst app = express();\n\napp.get('/v1', (req, res) => {\n  // gestione della richiesta\n});\n\napp.listen(1234);\n```\nNota che questo è solo un esempio e potrebbe essere necessario aggiungere ulteriori configurazioni per il servizio."}
{"timestamp": "2025-10-08T02:49:20.886291", "container": "proxy", "language": "generic", "error": "2025/09/25 23:21:07 [error] 27#27: *138 connect() failed (111: Connection refused) while connecting to upstream, client: 172.17.0.1, server: localhost, request: \"GET /v2 HTTP/1.1\", upstream: \"http://172.17.0.1:4891/\", host: \"peschiera3.ddns.net\", referrer: \"https://peschiera3.ddns.net/api\"", "solution": "Il bug è che il client tenta di connettersi al server localhost, ma il server non è disponibile perché il proxy non riesce a stabilire una connessione con l'upstream (http://172.17.0.1:4891/).\n\n**Soluzione concisa:** Verifica che il servizio di backend (http://172.17.0.1:4891/) sia avviato e disponibile prima di tentare di stabilire una connessione con il proxy.\n\nEsempio di codice non errato:\n```bash\n# Avvio del servizio di backend\ndocker run -d --name backend -p 4891:4891 mybackend-service\n```\nNota che questo è solo un esempio e la soluzione reale dipenderà dalle specifiche esigenze del tuo progetto"}
{"timestamp": "2025-10-08T02:49:21.715672", "container": "proxy", "language": "generic", "error": "2025/09/25 23:21:09 [error] 25#25: *155 connect() failed (111: Connection refused) while connecting to upstream, client: 172.17.0.1, server: localhost, request: \"GET /rea HTTP/1.1\", upstream: \"http://172.17.0.1:8000/\", host: \"peschiera3.ddns.net\", referrer: \"https://peschiera3.ddns.net/api\"", "solution": "Il bug è che il server non sta ascoltando su port 8000.\n\n**Soluzione**: assicurarsi di avviare correttamente l'applicazione o servizio che si trova su quel porto. Ad esempio, se si utilizza Nginx come proxy, è necessario specificare il comando `nginx -c /path/to/nginx.conf` per avviarlo con le impostazioni configurate.\n\n**Esempio di codice non errato (Nginx)**\n\n```nginx\nhttp {\n    upstream backend {\n        server localhost:8000;\n    }\n\n    server {\n        listen 80;\n        location /rea {\n            proxy_pass http://backend;\n            proxy_set_header Host $host;\n            proxy_set_header X-Real-IP $remote_addr;\n        }\n    }\n}\n```\n\nNota che in questo"}
{"timestamp": "2025-10-08T02:49:22.524641", "container": "gitea-db-1", "language": "generic", "error": "2025-09-28 09:32:41.137 UTC [28] FATAL:  the database system is starting up", "solution": "Il bug sembra essere una semplice inizializzazione del database che non è riuscita a completarsi.\n\n**Soluzione:** Verifica se il file di configurazione del database (ad esempio `/etc/gitea/gitea.ini`) contiene le impostazioni corrette per l'inizializzazione.\n\nEsempio di codice:\n```ini\n[database]\ntype = postgresql\nhost = localhost\nport = 5432\nuser = gitea\npassword = password\ndatabase = gitea\n```\nAssicurati che il file `gitea.ini` sia presente e corretto nella cartella `/etc/gitea/`."}
{"timestamp": "2025-10-08T02:49:23.160798", "container": "dossier-backend", "language": "generic", "error": "\u001b[32m2025-09-27 03:12:45\u001b[0m | \u001b[31m\u001b[1mERROR   \u001b[0m | \u001b[31m\u001b[1m[FETCH] Errore fetch GNews: 'NoneType' object is not iterable\u001b[0m", "solution": "Il bug è che il codice cerca di iterare su un oggetto None, ovvero un valore null o vuoto.\n\nSoluzione:\nVerifica se l'oggetto è None prima di cercare di iterarlo. Ad esempio:\n\n```python\ngnews = fetch_gnews()  # supponiamo che fetch_gnews ritorna None\nif gnews is not None:\n    for articolo in gnews:\n        # codice per elaborare gli articoli\nelse:\n    print(\"Errore: non è stato possibile caricare i dati\")\n```\n\nIn questo esempio, il codice verifica se `gnews` è None prima di cercare di iterarlo. Se è None, stampa un messaggio di errore; altrimenti, procede con la elaborazione degli articoli."}
{"timestamp": "2025-10-08T02:49:23.944476", "container": "frontend", "language": "generic", "error": "2025/09/28 09:32:18 [error] 42#42: *1 connect() failed (111: Connection refused) while connecting to upstream, client: 172.21.0.1, server: 192.168.1.10, request: \"GET /api/agents HTTP/1.1\", upstream: \"http://172.21.0.3:8003/agents\", host: \"peschiera3.ddns.net\", referrer: \"https://peschiera3.ddns.net/dossier/\"", "solution": "Il bug è che il server non sta ascoltando sulla porta 8003.\n\n**Soluzione concisa:** Assicurarsi di avviare correttamente l'applicazione e di configurare correttamente la porta di ascolto nel file di configurazione del servizio Nginx o del software che utilizza Nginx come proxy."}
{"timestamp": "2025-10-08T02:49:24.300410", "container": "privoxy", "language": "python", "error": "2025-08-21 09:18:16.458 7c3e34d33b38 Error: write to client failed: Invalid argument", "solution": "Il bug è che il problema \"Invalid argument\" può essere causato da diversi errori, ma in questo caso sembra che il problema sia legato alla scrittura su un client. \n\nLa soluzione potrebbe essere di verificare se la connessione al client sia stata stabilita correttamente e se i dati inviati siano validi.\n\nEsempio di codice non errato:\n```python\nimport privoxy\n\n# Stabilire la connessione al client\nclient = privoxy.connect(\"192.168.1.100\", 80)\n\ntry:\n    # Invio dei dati al client\n    response = client.send_request(b\"GET / HTTP/1.1\\r\\nHost: www.example.com\\r\\n\\r\\n\")\nexcept privoxy.exceptions.WriteError as e:\n    print(f\"Erro"}
{"timestamp": "2025-10-08T02:49:25.089055", "container": "couchdb1", "language": "generic", "error": "[error] 2025-09-26T00:34:02.116105Z couchdb@couchdb1 <0.467.0> -------- ** System running to use fully qualified hostnames **", "solution": "Il bug è che il server CouchDB non sta utilizzando i nomi di host completamente qualificati.\n\n**Soluzione:** assicurarsi di specificare la porta corretta nel nome del servizio (ad esempio, `http://localhost:5984` invece di `http://localhost`).\n\n**Esempio di codice non errato:**\n```javascript\nvar db = require('db');\nvar url = 'http://localhost:5984';\n```\nNota che in questo esempio la porta 5984 è specificata nel nome del servizio."}
{"timestamp": "2025-10-08T02:49:25.647373", "container": "privoxy-updater", "language": "python", "error": "Traceback (most recent call last):", "solution": "Il bug sembra essere una eccezione non gestita. La soluzione potrebbe essere aggiungere un'eccezione al blocco principale per catturare l'eccezione e fornire una messaggio di errore più dettagliato.\n\nEsempio di codice corretto:\n```python\ntry:\n    # codice da eseguire\nexcept Exception as e:\n    print(f\"Errore: {e}\")\n```\nNota che in questo caso si tratta di un esempio generico, potrebbe essere necessario specificare l'eccezione più probabile o fornire ulteriori dettagli per una soluzione più precisa."}
{"timestamp": "2025-10-08T02:49:26.286691", "container": "privoxy-updater", "language": "python", "error": "  File \"/usr/local/lib/python3.11/site-packages/urllib3/connection.py\", line 198, in _new_conn", "solution": "Il bug è che il file `/usr/local/lib/python3.11/site-packages/urllib3/connection.py` non esiste più.\n\nSoluzione: controllare la versione di Python e urllib3 installati sul sistema per assicurarsi di utilizzare le versioni più recenti, poi aggiornare i pacchetti:\n\n```bash\npython -m pip install --upgrade python-urllib3\n```\n\nNota: è importante eseguire comandi di installazione con superamministrazione o come utente root."}
