{"timestamp": "2025-10-05T03:25:09.170222", "container": "gitea-db-1", "language": "generic", "error": "2025-09-28 09:32:41.137 UTC [28] FATAL:  the database system is starting up", "solution": "Errore AI: Error code: 429 - {'error': {'code': None, 'message': 'Rate limit exceeded', 'param': None, 'type': 'rate_limit_exceeded'}}"}
{"timestamp": "2025-10-05T03:25:11.968418", "container": "dossier-backend", "language": "generic", "error": "\u001b[32m2025-09-27 03:12:45\u001b[0m | \u001b[31m\u001b[1mERROR   \u001b[0m | \u001b[31m\u001b[1m[FETCH] Errore fetch GNews: 'NoneType' object is not iterable\u001b[0m", "solution": "Errore AI: Error code: 429 - {'error': {'code': None, 'message': 'Rate limit exceeded', 'param': None, 'type': 'rate_limit_exceeded'}}"}
{"timestamp": "2025-10-05T03:25:14.074226", "container": "gitea", "language": "python", "error": "2025/09/28 11:32:41 routers/common/db.go:36:InitDBEngine() [E] ORM engine initialization attempt #1/10 failed. Error: pq: the database system is starting up", "solution": "Errore AI: Error code: 429 - {'error': {'code': None, 'message': 'Rate limit exceeded', 'param': None, 'type': 'rate_limit_exceeded'}}"}
{"timestamp": "2025-10-05T03:25:16.226996", "container": "privoxy-updater", "language": "python", "error": "Traceback (most recent call last):", "solution": "Errore AI: Error code: 429 - {'error': {'code': None, 'message': 'Rate limit exceeded', 'param': None, 'type': 'rate_limit_exceeded'}}"}
{"timestamp": "2025-10-05T03:25:18.364490", "container": "privoxy-updater", "language": "python", "error": "  File \"/usr/local/lib/python3.11/site-packages/urllib3/connection.py\", line 198, in _new_conn", "solution": "Errore AI: Error code: 429 - {'error': {'code': None, 'message': 'Rate limit exceeded', 'param': None, 'type': 'rate_limit_exceeded'}}"}
{"timestamp": "2025-10-05T03:25:20.496245", "container": "couchdb1", "language": "generic", "error": "[error] 2025-09-26T00:34:02.116105Z couchdb@couchdb1 <0.467.0> -------- ** System running to use fully qualified hostnames **", "solution": "Errore AI: Error code: 429 - {'error': {'code': None, 'message': 'Rate limit exceeded', 'param': None, 'type': 'rate_limit_exceeded'}}"}
{"timestamp": "2025-10-05T03:25:22.714254", "container": "frontend", "language": "generic", "error": "2025/09/28 09:32:18 [error] 42#42: *1 connect() failed (111: Connection refused) while connecting to upstream, client: 172.21.0.1, server: 192.168.1.10, request: \"GET /api/agents HTTP/1.1\", upstream: \"http://172.21.0.3:8003/agents\", host: \"peschiera3.ddns.net\", referrer: \"https://peschiera3.ddns.net/dossier/\"", "solution": "Errore AI: Error code: 429 - {'error': {'code': None, 'message': 'Rate limit exceeded', 'param': None, 'type': 'rate_limit_exceeded'}}"}
{"timestamp": "2025-10-05T03:25:24.960617", "container": "proxy", "language": "generic", "error": "2025/09/25 23:21:07 [error] 27#27: *134 connect() failed (111: Connection refused) while connecting to upstream, client: 172.17.0.1, server: localhost, request: \"GET /v1 HTTP/1.1\", upstream: \"http://172.17.0.1:1234/v1\", host: \"peschiera3.ddns.net\", referrer: \"https://peschiera3.ddns.net/api\"", "solution": "Errore AI: Error code: 429 - {'error': {'code': None, 'message': 'Rate limit exceeded', 'param': None, 'type': 'rate_limit_exceeded'}}"}
{"timestamp": "2025-10-05T03:25:27.276466", "container": "proxy", "language": "generic", "error": "2025/09/25 23:21:07 [error] 27#27: *138 connect() failed (111: Connection refused) while connecting to upstream, client: 172.17.0.1, server: localhost, request: \"GET /v2 HTTP/1.1\", upstream: \"http://172.17.0.1:4891/\", host: \"peschiera3.ddns.net\", referrer: \"https://peschiera3.ddns.net/api\"", "solution": "Errore AI: Error code: 429 - {'error': {'code': None, 'message': 'Rate limit exceeded', 'param': None, 'type': 'rate_limit_exceeded'}}"}
{"timestamp": "2025-10-05T03:25:29.338570", "container": "proxy", "language": "generic", "error": "2025/09/25 23:21:09 [error] 25#25: *155 connect() failed (111: Connection refused) while connecting to upstream, client: 172.17.0.1, server: localhost, request: \"GET /rea HTTP/1.1\", upstream: \"http://172.17.0.1:8000/\", host: \"peschiera3.ddns.net\", referrer: \"https://peschiera3.ddns.net/api\"", "solution": "Errore AI: Error code: 429 - {'error': {'code': None, 'message': 'Rate limit exceeded', 'param': None, 'type': 'rate_limit_exceeded'}}"}
{"timestamp": "2025-10-05T03:25:31.477993", "container": "privoxy", "language": "python", "error": "2025-08-21 09:18:16.458 7c3e34d33b38 Error: write to client failed: Invalid argument", "solution": "Errore AI: Error code: 429 - {'error': {'code': None, 'message': 'Rate limit exceeded', 'param': None, 'type': 'rate_limit_exceeded'}}"}
{"timestamp": "2025-10-05T03:28:46.493223", "container": "couchdb1", "language": "generic", "error": "[error] 2025-09-26T00:34:02.116105Z couchdb@couchdb1 <0.467.0> -------- ** System running to use fully qualified hostnames **", "solution": "Il bug è che il server CouchDB richiede un'indirizzo IP completo (FQDN) per connettersi, invece di utilizzare solo il nome del dominio.\n\n**Soluzione:** Assicurarsi di utilizzare l'indirizzo IP completo quando si cerca di connettersi al server CouchDB. Ad esempio:\n\n```bash\ncurl -X GET http://192.168.1.100:5984/_utils/\n```\n\nInvece di:\n```bash\ncurl -X GET http://dominio.com/5984/_utils/\n```\nNota che il dominio non è sufficiente per connettersi al server CouchDB."}
{"timestamp": "2025-10-05T03:28:47.332559", "container": "gitea-db-1", "language": "generic", "error": "2025-09-28 09:32:41.137 UTC [28] FATAL:  the database system is starting up", "solution": "Il bug è che il messaggio di errore non fornisce informazioni specifiche sul problema.\n\nLa soluzione potrebbe essere una configurazione più dettagliata del database, ad esempio:\n\n```bash\ngitea db init --config=gitea.ini\n```\n\nQuesto comando inizia il database con le impostazioni specificate nel file `gitea.ini`."}
{"timestamp": "2025-10-05T03:28:47.716737", "container": "gitea", "language": "python", "error": "2025/09/28 11:32:41 routers/common/db.go:36:InitDBEngine() [E] ORM engine initialization attempt #1/10 failed. Error: pq: the database system is starting up", "solution": "Il bug è che il codice non attende la fine dell'avvio del database prima di tentare l'initializzazione dell'ORM engine.\n\n**Soluzione concisa:** Aggiungere un tempo di attesa prima di riconvertire all'initializzazione.\n\nEsempio di codice corretto:\n```go\nfunc InitDBEngine() {\n    defer func() {\n        // attendi 2 secondi per garantire che il database sia pronto\n        time.Sleep(2 * time.Second)\n        // riconverte l'initializzazione dell'ORM engine\n        if err := db.Init(); err != nil {\n            log.Println(err)\n        }\n    }()\n}\n```"}
{"timestamp": "2025-10-05T03:28:48.358945", "container": "frontend", "language": "generic", "error": "2025/09/28 09:32:18 [error] 42#42: *1 connect() failed (111: Connection refused) while connecting to upstream, client: 172.21.0.1, server: 192.168.1.10, request: \"GET /api/agents HTTP/1.1\", upstream: \"http://172.21.0.3:8003/agents\", host: \"peschiera3.ddns.net\", referrer: \"https://peschiera3.ddns.net/dossier/\"", "solution": "Il bug è che il server non sta ascoltando sulla porta 8003.\n\nSoluzione:\n- Assicurarsi di aver avviato correttamente l'applicazione su quella porta."}
{"timestamp": "2025-10-05T03:28:48.587498", "container": "proxy", "language": "generic", "error": "2025/09/25 23:21:07 [error] 27#27: *134 connect() failed (111: Connection refused) while connecting to upstream, client: 172.17.0.1, server: localhost, request: \"GET /v1 HTTP/1.1\", upstream: \"http://172.17.0.1:1234/v1\", host: \"peschiera3.ddns.net\", referrer: \"https://peschiera3.ddns.net/api\"", "solution": "Il bug è che il server non sta ascoltando sulla porta 1234.\n\nSoluzione: assicurarsi di aver avviato correttamente l'applicazione o il servizio che utilizza quella porta. Ad esempio, se si tratta di un'applicazione scritta in Python con Flask, assicurarsi di aver utilizzato la funzione `flask.run()` con l'opzione `host='0.0.0.0'` e `port=1234`.\n\nEsempio di codice non errato:\n```python\nfrom flask import Flask\n\napp = Flask(__name__)\n\n@app.route('/v1')\ndef v1():\n    return 'OK'\n\nif __name__ == '__main__':\n    app.run(host='0.0.0.0', port=1234)\n```\nNota:"}
{"timestamp": "2025-10-05T03:28:49.392686", "container": "proxy", "language": "generic", "error": "2025/09/25 23:21:07 [error] 27#27: *138 connect() failed (111: Connection refused) while connecting to upstream, client: 172.17.0.1, server: localhost, request: \"GET /v2 HTTP/1.1\", upstream: \"http://172.17.0.1:4891/\", host: \"peschiera3.ddns.net\", referrer: \"https://peschiera3.ddns.net/api\"", "solution": "Il bug è che il server non sta ascoltando su port 4891.\n\n**Soluzione:** assicurarsi di eseguire il servizio web correttamente e di utilizzare il comando `nginx -s reload` per rilanciare la configurazione del servizio. Ad esempio, se si utilizza Nginx, è necessario eseguire:\n\n```bash\nsudo nginx -s reload\n```\n\noppure, se si utilizza un servizio web come Apache, è necessario eseguire:\n\n```bash\nsudo service apache2 restart\n```\no\n\n```bash\nsudo systemctl restart apache2\n```\n\nNota: la soluzione dipende dal sistema operativo e dalla configurazione specifica del servizio web."}
{"timestamp": "2025-10-05T03:28:50.104730", "container": "proxy", "language": "generic", "error": "2025/09/25 23:21:09 [error] 25#25: *155 connect() failed (111: Connection refused) while connecting to upstream, client: 172.17.0.1, server: localhost, request: \"GET /rea HTTP/1.1\", upstream: \"http://172.17.0.1:8000/\", host: \"peschiera3.ddns.net\", referrer: \"https://peschiera3.ddns.net/api\"", "solution": "Il bug è che il server non sta ascoltando sulla porta 8000.\n\n**Soluzione concisa:** Assicurarsi di eseguire il servizio web (ad esempio, `python -m http.server` o `gunicorn myapp:app`) prima di tentare una connessione.\n\n**Esempio di codice non errato:**\n```bash\n# eseguire un server HTTP\npython -m http.server 8000\n```\nNota che il codice non è specifico a nessuna lingua, ma piuttosto una semplice istruzione per eseguire un server HTTP."}
{"timestamp": "2025-10-05T03:28:50.721194", "container": "dossier-backend", "language": "generic", "error": "\u001b[32m2025-09-27 03:12:45\u001b[0m | \u001b[31m\u001b[1mERROR   \u001b[0m | \u001b[31m\u001b[1m[FETCH] Errore fetch GNews: 'NoneType' object is not iterable\u001b[0m", "solution": "Il bug è che il codice cerca di iterare su un oggetto None, che non può essere trattato come una sequenza.\n\nSoluzione:\nVerifica se l'oggetto è None prima di cercare di iterarlo. Ad esempio:\n\n```python\ngnews = fetch_gnews()  # supponiamo che fetch_gnews ritorna None\nif gnews is not None:\n    for item in gnews:\n        # trattamento dell'item\nelse:\n    print(\"Errore: non si è riusciti a caricare i dati\")\n```"}
{"timestamp": "2025-10-05T03:28:51.281727", "container": "privoxy-updater", "language": "python", "error": "Traceback (most recent call last):", "solution": "Il bug è probabilmente legato alla mancanza di una dipendenza necessaria per il modulo Privoxy-Updater. \n\nLa soluzione potrebbe essere aggiungere la dipendenza `python-privoxy` al file `setup.py`:\n\n```bash\nfrom setuptools import setup, find_packages\n\nsetup(\n    name='privoxy-updater',\n    version='1.0',\n    packages=find_packages(),\n    install_requires=['python-privoxy']\n)\n```\n\nNota che la soluzione potrebbe variare in base alle specifiche esigenze del progetto."}
{"timestamp": "2025-10-05T03:28:51.815554", "container": "privoxy-updater", "language": "python", "error": "  File \"/usr/local/lib/python3.11/site-packages/urllib3/connection.py\", line 198, in _new_conn", "solution": "Il bug sembra essere legato alla gestione delle connessioni HTTP. La causa potrebbe essere un problema di sicurezza o di configurazione.\n\n**Soluzione concisa:**\n\nAggiornare Privoxy-Updater a una versione recente per garantire la presenza di patch di sicurezza e miglioramenti di prestazioni.\n\nEsempio di codice (non errato):\n```python\nimport subprocess\n\n# Aggiorna Privoxy-Updater\nsubprocess.run(['apt-get', 'update'], check=True)\nsubprocess.run(['apt-get', '-y', 'upgrade', '--auto-remove', 'privoxy-updater'], check=True)\n```\nNota: Questo esempio utilizza `apt-get` per gestire le versioni di Privoxy-Updater su un sistema Linux. La soluzione potrebbe vari"}
{"timestamp": "2025-10-05T03:28:52.602773", "container": "privoxy", "language": "python", "error": "2025-08-21 09:18:16.458 7c3e34d33b38 Error: write to client failed: Invalid argument", "solution": "Il bug è che il parametro `Invalid argument` non è un valore valido per l'errore `write to client failed`.\n\nLa soluzione potrebbe essere di controllare se il problema si verifica quando si tenta di scrivere dati al client, e se la causa dell'errore è legata a una configurazione o a un problema specifico.\n\nEsempio di codice per debug:\n```python\nimport logging\n\nlogging.basicConfig(level=logging.ERROR)\n\ntry:\n    # codice che scrive dati al client\n    with open('file.txt', 'wb') as f:\n        f.write(b'informazioni')\nexcept Exception as e:\n    logging.error(f\"Errore durante la scrittura al client: {e}\")\n```\nIn questo esempio, il codice cerca di scrivere un file al client, ma se si verifica"}
{"timestamp": "2025-10-05T03:32:21.004918", "container": "frontend", "language": "generic", "error": "2025/09/28 09:32:18 [error] 42#42: *1 connect() failed (111: Connection refused) while connecting to upstream, client: 172.21.0.1, server: 192.168.1.10, request: \"GET /api/agents HTTP/1.1\", upstream: \"http://172.21.0.3:8003/agents\", host: \"peschiera3.ddns.net\", referrer: \"https://peschiera3.ddns.net/dossier/\"", "solution": "Il bug è che il server non sta ascoltando su l'indirizzo IP specificato (`172.21.0.1`) in lugar di `192.168.1.10`.\n\nSoluzione:\n- Assicurarsi che il servizio Nginx stia eseguendo correttamente e che sia configurato per ascoltare su l'indirizzo IP corretto.\n\nEsempio di codice non errato (Nginx configuration):\n```nginx\nserver {\n    listen 80;\n    server_name peschiera3.ddns.net;\n\n    location /api/agents {\n        proxy_pass http://172.21.0.3:8003/agents;\n        proxy_http_version 1.1;\n        proxy_set_header Upgrade $http_upgrade;\n        proxy_set_header Connection 'upgrade';\n        proxy_set_header Host $"}
